<sdf version="1.6">
    <model name="robot">
      <static>0</static>
      <link name="base_link">
        <pose frame="">0 0 0 0 -0 0</pose>
        <inertial>
          <pose frame="">-0.004491 0 0.053793 0 -0 0</pose>
          <mass>48.2</mass>
          <inertia>
            <ixx>0.868958</ixx>
            <ixy>0</ixy>
            <ixz>0.0568058</ixz>
            <iyy>1.66703</iyy>
            <iyz>0</iyz>
            <izz>1.06874</izz>
          </inertia>
        </inertial>
        <collision name="base_link_collision">
          <pose frame="">0 0 0 0 -0 0</pose>
          <geometry>
            <box>
              <size>0.52 0.18 0.118</size>
            </box>
          </geometry>
          <surface>
            <contact>
              <ode>
                <kp>1e+06</kp>
                <kd>100</kd>
                <max_vel>1</max_vel>
                <min_depth>0.001</min_depth>
              </ode>
            </contact>
            <friction>
              <ode>
                <mu>0</mu>
                <mu2>0</mu2>
              </ode>
              <torsional>
                <ode/>
              </torsional>
            </friction>
            <bounce/>
          </surface>
          <max_contacts>10</max_contacts>
        </collision>
        <collision name="base_link_collision_1">
          <pose frame="">0.218 0.155 -0.006 1.5708 -0 0</pose>
          <geometry>
            <cylinder>
              <length>0.1</length>
              <radius>0.09</radius>
            </cylinder>
          </geometry>
          <surface>
            <contact>
              <ode>
                <kp>1e+06</kp>
                <kd>100</kd>
                <max_vel>1</max_vel>
                <min_depth>0.001</min_depth>
              </ode>
            </contact>
            <friction>
              <ode>
                <mu>0</mu>
                <mu2>0</mu2>
              </ode>
              <torsional>
                <ode/>
              </torsional>
            </friction>
            <bounce/>
          </surface>
          <max_contacts>10</max_contacts>
        </collision>
        <collision name="base_link_collision_2">
          <pose frame="">-0.218 0.155 -0.006 1.5708 -0 0</pose>
          <geometry>
            <cylinder>
              <length>0.1</length>
              <radius>0.09</radius>
            </cylinder>
          </geometry>
          <surface>
            <contact>
              <ode>
                <kp>1e+06</kp>
                <kd>100</kd>
                <max_vel>1</max_vel>
                <min_depth>0.001</min_depth>
              </ode>
            </contact>
            <friction>
              <ode>
                <mu>0</mu>
                <mu2>0</mu2>
              </ode>
              <torsional>
                <ode/>
              </torsional>
            </friction>
            <bounce/>
          </surface>
          <max_contacts>10</max_contacts>
        </collision>
        <collision name="base_link_collision_3">
          <pose frame="">0 0.155 -0.006 0 -0 0</pose>
          <geometry>
            <box>
              <size>0.43 0.1 0.18</size>
            </box>
          </geometry>
          <surface>
            <contact>
              <ode>
                <kp>1e+06</kp>
                <kd>100</kd>
                <max_vel>1</max_vel>
                <min_depth>0.001</min_depth>
              </ode>
            </contact>
            <friction>
              <ode>
                <mu>0</mu>
                <mu2>0</mu2>
              </ode>
              <torsional>
                <ode/>
              </torsional>
            </friction>
            <bounce/>
          </surface>
          <max_contacts>10</max_contacts>
        </collision>
        <collision name="base_link_collision_4">
          <pose frame="">0.218 -0.155 -0.006 1.5708 -0 0</pose>
          <geometry>
            <cylinder>
              <length>0.1</length>
              <radius>0.09</radius>
            </cylinder>
          </geometry>
          <surface>
            <contact>
              <ode>
                <kp>1e+06</kp>
                <kd>100</kd>
                <max_vel>1</max_vel>
                <min_depth>0.001</min_depth>
              </ode>
            </contact>
            <friction>
              <ode>
                <mu>0</mu>
                <mu2>0</mu2>
              </ode>
              <torsional>
                <ode/>
              </torsional>
            </friction>
            <bounce/>
          </surface>
          <max_contacts>10</max_contacts>
        </collision>
        <collision name="base_link_collision_5">
          <pose frame="">-0.218 -0.155 -0.006 1.5708 -0 0</pose>
          <geometry>
            <cylinder>
              <length>0.1</length>
              <radius>0.09</radius>
            </cylinder>
          </geometry>
          <surface>
            <contact>
              <ode>
                <kp>1e+06</kp>
                <kd>100</kd>
                <max_vel>1</max_vel>
                <min_depth>0.001</min_depth>
              </ode>
            </contact>
            <friction>
              <ode>
                <mu>0</mu>
                <mu2>0</mu2>
              </ode>
              <torsional>
                <ode/>
              </torsional>
            </friction>
            <bounce/>
          </surface>
          <max_contacts>10</max_contacts>
        </collision>
        <collision name="base_link_collision_6">
          <pose frame="">0 -0.155 -0.006 0 -0 0</pose>
          <geometry>
            <box>
              <size>0.43 0.1 0.18</size>
            </box>
          </geometry>
          <surface>
            <contact>
              <ode>
                <kp>1e+06</kp>
                <kd>100</kd>
                <max_vel>1</max_vel>
                <min_depth>0.001</min_depth>
              </ode>
            </contact>
            <friction>
              <ode>
                <mu>0</mu>
                <mu2>0</mu2>
              </ode>
              <torsional>
                <ode/>
              </torsional>
            </friction>
            <bounce/>
          </surface>
          <max_contacts>10</max_contacts>
        </collision>
        <collision name="base_link_fixed_joint_lump__pelvis_collision_7">
          <pose frame="">-0.01 0 0.325 0 -0 0</pose>
          <geometry>
            <box>
              <size>0.23 0.23 0.24</size>
            </box>
          </geometry>
          <max_contacts>10</max_contacts>
          <surface>
            <contact>
              <ode/>
            </contact>
            <bounce/>
            <friction>
              <torsional>
                <ode/>
              </torsional>
              <ode/>
            </friction>
          </surface>
        </collision>
        <visual name="base_link_visual">
          <pose frame="">0 0 0 0 -0 0</pose>
          <geometry>
            <box>
              <size>0.52 0.18 0.118</size>
            </box>
          </geometry>
          <material>
            <script>
              <uri>__default__</uri>
              <name>__default__</name>
            </script>
          </material>
        </visual>
        <visual name="base_link_visual_1">
          <pose frame="">0.218 0.155 -0.006 1.5708 -0 0</pose>
          <geometry>
            <cylinder>
              <length>0.1</length>
              <radius>0.09</radius>
            </cylinder>
          </geometry>
          <material>
            <script>
              <uri>__default__</uri>
              <name>__default__</name>
            </script>
          </material>
        </visual>
        <visual name="base_link_visual_2">
          <pose frame="">-0.218 0.155 -0.006 1.5708 -0 0</pose>
          <geometry>
            <cylinder>
              <length>0.1</length>
              <radius>0.09</radius>
            </cylinder>
          </geometry>
          <material>
            <script>
              <uri>__default__</uri>
              <name>__default__</name>
            </script>
          </material>
        </visual>
        <visual name="base_link_visual_3">
          <pose frame="">0 0.155 -0.006 0 -0 0</pose>
          <geometry>
            <box>
              <size>0.43 0.1 0.18</size>
            </box>
          </geometry>
          <material>
            <script>
              <uri>__default__</uri>
              <name>__default__</name>
            </script>
          </material>
        </visual>
        <visual name="base_link_visual_4">
          <pose frame="">0.218 -0.155 -0.006 1.5708 -0 0</pose>
          <geometry>
            <cylinder>
              <length>0.1</length>
              <radius>0.09</radius>
            </cylinder>
          </geometry>
          <material>
            <script>
              <uri>__default__</uri>
              <name>__default__</name>
            </script>
          </material>
        </visual>
        <visual name="base_link_visual_5">
          <pose frame="">-0.218 -0.155 -0.006 1.5708 -0 0</pose>
          <geometry>
            <cylinder>
              <length>0.1</length>
              <radius>0.09</radius>
            </cylinder>
          </geometry>
          <material>
            <script>
              <uri>__default__</uri>
              <name>__default__</name>
            </script>
          </material>
        </visual>
        <visual name="base_link_visual_6">
          <pose frame="">0 -0.155 -0.006 0 -0 0</pose>
          <geometry>
            <box>
              <size>0.43 0.1 0.18</size>
            </box>
          </geometry>
          <material>
            <script>
              <uri>__default__</uri>
              <name>__default__</name>
            </script>
          </material>
        </visual>
        <visual name="base_link_fixed_joint_lump__pelvis_visual_7">
          <pose frame="">0 0 0.3 1.5708 -0 1.5708</pose>
          <geometry>
            <mesh>
              <scale>0.001 0.001 0.001</scale>
              <uri>model://centaur/meshes/pelvis.stl</uri>
            </mesh>
          </geometry>
        </visual>
        <gravity>1</gravity>
        <velocity_decay/>
        <self_collide>0</self_collide>
        <kinematic>0</kinematic>
      </link>
      <link name="waist">
        <pose frame="">0 0 0.437 0 -0 0</pose>
        <inertial>
          <pose frame="">0 0 0 0 -0 0</pose>
          <mass>0.8</mass>
          <inertia>
            <ixx>0.0012</ixx>
            <ixy>0</ixy>
            <ixz>0</ixz>
            <iyy>0.00048</iyy>
            <iyz>0</iyz>
            <izz>0.0012</izz>
          </inertia>
        </inertial>
        <collision name="waist_collision">
          <pose frame="">0.024 0 0 0 -0 0</pose>
          <geometry>
            <box>
              <size>0.03 0.08 0.03</size>
            </box>
          </geometry>
          <max_contacts>10</max_contacts>
          <surface>
            <contact>
              <ode/>
            </contact>
            <bounce/>
            <friction>
              <torsional>
                <ode/>
              </torsional>
              <ode/>
            </friction>
          </surface>
        </collision>
        <visual name="waist_visual">
          <pose frame="">0 0 -0.039 1.5708 -0 1.5708</pose>
          <geometry>
            <mesh>
              <scale>0.001 0.001 0.001</scale>
              <uri>model://centaur/meshes/waist.stl</uri>
            </mesh>
          </geometry>
        </visual>
        <self_collide>0</self_collide>
        <kinematic>0</kinematic>
      </link>
      <joint name="waist_pan" type="revolute">
        <child>waist</child>
        <parent>base_link</parent>
        <axis>
          <xyz>0 0 1</xyz>
          <limit>
            <lower>-1.8</lower>
            <upper>1.3</upper>
            <effort>210.142</effort>
            <velocity>2.5</velocity>
          </limit>
          <dynamics>
            <damping>0.1</damping>
            <friction>0</friction>
            <spring_reference>0</spring_reference>
            <spring_stiffness>0</spring_stiffness>
          </dynamics>
          <use_parent_model_frame>1</use_parent_model_frame>
        </axis>
        <physics>
          <ode>
            <implicit_spring_damper>1</implicit_spring_damper>
            <cfm_damping>1</cfm_damping>
            <limit>
              <cfm>0</cfm>
              <erp>0.2</erp>
            </limit>
          </ode>
        </physics>
      </joint>
      <link name="utorso">
        <pose frame="">0 0 0.437 0 -0 0</pose>
        <inertial>
          <pose frame="">-0.0264 0 0.155 0 -0 0</pose>
          <mass>10.91</mass>
          <inertia>
            <ixx>0.118192</ixx>
            <ixy>0</ixy>
            <ixz>0</ixz>
            <iyy>0.0931896</iyy>
            <iyz>0</iyz>
            <izz>0.138648</izz>
          </inertia>
        </inertial>
        <collision name="utorso_collision">
          <pose frame="">-0.075 0 0.11 0 -0 0</pose>
          <geometry>
            <box>
              <size>0.24 0.31 0.24</size>
            </box>
          </geometry>
          <max_contacts>10</max_contacts>
          <surface>
            <contact>
              <ode/>
            </contact>
            <bounce/>
            <friction>
              <torsional>
                <ode/>
              </torsional>
              <ode/>
            </friction>
          </surface>
        </collision>
        <collision name="utorso_collision_1">
          <pose frame="">0.1 0.13 0.12 0 -0 0</pose>
          <geometry>
            <cylinder>
              <length>0.23</length>
              <radius>0.04</radius>
            </cylinder>
          </geometry>
          <max_contacts>10</max_contacts>
          <surface>
            <contact>
              <ode/>
            </contact>
            <bounce/>
            <friction>
              <torsional>
                <ode/>
              </torsional>
              <ode/>
            </friction>
          </surface>
        </collision>
        <collision name="utorso_collision_2">
          <pose frame="">0.1 -0.13 0.12 0 -0 0</pose>
          <geometry>
            <cylinder>
              <length>0.23</length>
              <radius>0.04</radius>
            </cylinder>
          </geometry>
          <max_contacts>10</max_contacts>
          <surface>
            <contact>
              <ode/>
            </contact>
            <bounce/>
            <friction>
              <torsional>
                <ode/>
              </torsional>
              <ode/>
            </friction>
          </surface>
        </collision>
        <visual name="utorso_visual">
          <pose frame="">-0 0 0.159 1.5708 -0 1.5708</pose>
          <geometry>
            <mesh>
              <scale>0.001 0.001 0.001</scale>
              <uri>model://centaur/meshes/chest.stl</uri>
            </mesh>
          </geometry>
        </visual>
        <self_collide>0</self_collide>
        <kinematic>0</kinematic>
      </link>
      <joint name="waist_tilt" type="revolute">
        <child>utorso</child>
        <parent>waist</parent>
        <axis>
          <xyz>0 1 0</xyz>
          <limit>
            <lower>-0.05</lower>
            <upper>1.07</upper>
            <effort>390.131</effort>
            <velocity>2.5</velocity>
          </limit>
          <dynamics>
            <damping>0.1</damping>
            <friction>0</friction>
            <spring_reference>0</spring_reference>
            <spring_stiffness>0</spring_stiffness>
          </dynamics>
          <use_parent_model_frame>1</use_parent_model_frame>
        </axis>
        <physics>
          <ode>
            <implicit_spring_damper>1</implicit_spring_damper>
            <cfm_damping>1</cfm_damping>
            <limit>
              <cfm>0</cfm>
              <erp>0.2</erp>
            </limit>
          </ode>
        </physics>
      </joint>
      <link name="neck_link">
        <pose frame="">0 0 0.757 0 -0 0</pose>
        <inertial>
          <pose frame="">0 0 0 0 -0 0</pose>
          <mass>0.1</mass>
          <inertia>
            <ixx>9e-06</ixx>
            <ixy>0</ixy>
            <ixz>0</ixz>
            <iyy>9e-06</iyy>
            <iyz>0</iyz>
            <izz>9e-06</izz>
          </inertia>
        </inertial>
        <collision name="neck_link_collision">
          <pose frame="">0 0 -0.05 0 -0 0</pose>
          <geometry>
            <box>
              <size>0.045 0.045 0.15</size>
            </box>
          </geometry>
          <max_contacts>10</max_contacts>
          <surface>
            <contact>
              <ode/>
            </contact>
            <bounce/>
            <friction>
              <torsional>
                <ode/>
              </torsional>
              <ode/>
            </friction>
          </surface>
        </collision>
        <visual name="neck_link_visual">
          <pose frame="">0 0 -0.111 1.5708 0 -1.5708</pose>
          <geometry>
            <mesh>
              <scale>0.001 0.001 0.001</scale>
              <uri>model://centaur/meshes/neck.stl</uri>
            </mesh>
          </geometry>
        </visual>
        <self_collide>0</self_collide>
        <kinematic>0</kinematic>
      </link>
      <joint name="head_pan" type="revolute">
        <child>neck_link</child>
        <parent>utorso</parent>
        <axis>
          <xyz>0 0 1</xyz>
          <limit>
            <lower>-1.5708</lower>
            <upper>2.45</upper>
            <effort>50.596</effort>
            <velocity>1.4</velocity>
          </limit>
          <dynamics>
            <damping>0.1</damping>
            <friction>0</friction>
            <spring_reference>0</spring_reference>
            <spring_stiffness>0</spring_stiffness>
          </dynamics>
          <use_parent_model_frame>1</use_parent_model_frame>
        </axis>
        <physics>
          <ode>
            <implicit_spring_damper>1</implicit_spring_damper>
            <cfm_damping>1</cfm_damping>
            <limit>
              <cfm>0</cfm>
              <erp>0.2</erp>
            </limit>
          </ode>
        </physics>
      </joint>
      <link name="head_link">
        <audio_sink/>
        <pose frame="">0 0 0.757 0 -0 0</pose>
        <inertial>
          <pose frame="">0.013 0 0.046 0 -0 0</pose>
          <mass>1</mass>
          <inertia>
            <ixx>0.0115448</ixx>
            <ixy>0</ixy>
            <ixz>-0.002292</ixz>
            <iyy>0.0104708</iyy>
            <iyz>0</iyz>
            <izz>0.00386683</izz>
          </inertia>
        </inertial>
        <collision name="head_link_fixed_joint_lump__collision_collision">
          <pose frame="">0 0 -0.006 1.5708 -0 1.5708</pose>
          <geometry>
            <mesh>
              <scale>0.001 0.001 0.001</scale>
              <uri>model://centaur/meshes/multisensor_head_collision.stl</uri>
            </mesh>
          </geometry>
          <max_contacts>10</max_contacts>
          <surface>
            <contact>
              <ode/>
            </contact>
            <bounce/>
            <friction>
              <torsional>
                <ode/>
              </torsional>
              <ode/>
            </friction>
          </surface>
        </collision>
        <collision name="head_link_fixed_joint_lump__head_cam_link_collision_1">
          <pose frame="">0.065 0 0.23 0 -0 0</pose>
          <geometry>
            <mesh>
              <scale>1 1 1</scale>
              <uri>model://centaur/meshes/asus_camera_simple.dae</uri>
            </mesh>
          </geometry>
          <max_contacts>10</max_contacts>
          <surface>
            <contact>
              <ode/>
            </contact>
            <bounce/>
            <friction>
              <torsional>
                <ode/>
              </torsional>
              <ode/>
            </friction>
          </surface>
        </collision>
        <visual name="head_link_visual">
          <pose frame="">0 0 -0.006 1.5708 -0 1.5708</pose>
          <geometry>
            <mesh>
              <scale>0.001 0.001 0.001</scale>
              <uri>model://centaur/meshes/multisensor_head.stl</uri>
            </mesh>
          </geometry>
        </visual>
        <visual name="head_link_fixed_joint_lump__head_cam_link_visual_1">
          <pose frame="">0.065 0 0.23 0 -0 0</pose>
          <geometry>
            <mesh>
              <scale>1 1 1</scale>
              <uri>model://centaur/meshes/asus_camera_simple.dae</uri>
            </mesh>
          </geometry>
        </visual>
        <gravity>1</gravity>
        <velocity_decay/>
        <sensor name="head_cam" type="depth">
          <update_rate>20</update_rate>
          <camera name="head_cam">
            <horizontal_fov>1.09607</horizontal_fov>
            <image>
              <format>R8G8B8</format>
              <width>640</width>
              <height>480</height>
            </image>
            <clip>
              <near>0.5</near>
              <far>9</far>
            </clip>
          </camera>
          <plugin name="head_cam_camera_controller" filename="libgazebo_ros_openni_kinect.so">
            <cameraName>head_cam</cameraName>
            <imageTopicName>head_cam_ni/rgb/image_raw</imageTopicName>
            <cameraInfoTopicName>head_cam_ni/rgb/camera_info</cameraInfoTopicName>
            <depthImageTopicName>head_cam_ni/depth/image_raw</depthImageTopicName>
            <depthImageCameraInfoTopicName>head_cam_ni/depth/camera_info</depthImageCameraInfoTopicName>
            <pointCloudTopicName>head_cam_ni/depth/points</pointCloudTopicName>
            <frameName>head_cam_depth_optical_frame</frameName>
          </plugin>
          <pose frame="">0.065 0.049 0.23 0 -0 0</pose>
        </sensor>
        <self_collide>0</self_collide>
        <kinematic>0</kinematic>
      </link>
      <joint name="head_tilt" type="revolute">
        <child>head_link</child>
        <parent>neck_link</parent>
        <axis>
          <xyz>0 1 0</xyz>
          <limit>
            <lower>-1.32</lower>
            <upper>0.79</upper>
            <effort>50.596</effort>
            <velocity>1.4</velocity>
          </limit>
          <dynamics>
            <damping>0.1</damping>
            <friction>0</friction>
            <spring_reference>0</spring_reference>
            <spring_stiffness>0</spring_stiffness>
          </dynamics>
          <use_parent_model_frame>1</use_parent_model_frame>
        </axis>
        <physics>
          <ode>
            <implicit_spring_damper>1</implicit_spring_damper>
            <cfm_damping>1</cfm_damping>
            <limit>
              <cfm>0</cfm>
              <erp>0.2</erp>
            </limit>
          </ode>
        </physics>
      </joint>
      <link name="head_lidar_mount_link">
        <pose frame="">0.061 0 0.891 0 -0 0</pose>
        <inertial>
          <pose frame="">0 0.000236 0.009338 0 -0 0</pose>
          <mass>0.37</mass>
          <inertia>
            <ixx>0.000284112</ixx>
            <ixy>1.62368e-10</ixy>
            <ixz>-2.14448e-06</ixz>
            <iyy>0.000284149</iyy>
            <iyz>-2.94389e-07</iyz>
            <izz>0.000171053</izz>
          </inertia>
        </inertial>
        <collision name="head_lidar_mount_link_fixed_joint_lump__head_link_hokuyo_laser_frame_collision">
          <pose frame="">-0.000244 0.000324 0.001299 0 0.021197 -0.003571</pose>
          <geometry>
            <box>
              <size>0.058 0.058 0.087</size>
            </box>
          </geometry>
          <surface>
            <contact>
              <ode/>
            </contact>
            <friction>
              <ode/>
              <torsional>
                <ode/>
              </torsional>
            </friction>
            <bounce/>
          </surface>
          <max_contacts>10</max_contacts>
        </collision>
        <visual name="head_lidar_mount_link_fixed_joint_lump__head_link_hokuyo_laser_frame_visual">
          <pose frame="">0 0.000323 0.012797 0 0.021197 -0.003571</pose>
          <geometry>
            <mesh>
              <scale>1 1 1</scale>
              <uri>model://centaur/meshes/hokuyo_utm_30lx.dae</uri>
            </mesh>
          </geometry>
          <material>
            <script>
              <uri>__default__</uri>
              <name>__default__</name>
            </script>
          </material>
        </visual>
        <gravity>1</gravity>
        <velocity_decay/>
        <sensor name="head_link_hokuyo_laser" type="ray">
          <always_on>1</always_on>
          <update_rate>40</update_rate>
          <visualize>0</visualize>
          <ray>
            <scan>
              <horizontal>
                <samples>1040</samples>
                <resolution>1</resolution>
                <min_angle>2.26893</min_angle>
                <max_angle>-2.26893</max_angle>
              </horizontal>
              <vertical>
                <samples>1</samples>
                <min_angle>0</min_angle>
                <max_angle>0</max_angle>
              </vertical>
            </scan>
            <range>
              <min>0.2</min>
              <max>30</max>
              <resolution>0.01</resolution>
            </range>
            <noise>
              <type>gaussian</type>
              <mean>0</mean>
              <stddev>0.004</stddev>
            </noise>
          </ray>
          <plugin name="gazebo_ros_head_link_hokuyo_laser_controller" filename="libgazebo_ros_laser.so">
            <topicName>head_lidar/scan</topicName>
            <frameName>head_link_hokuyo_laser_frame</frameName>
          </plugin>
          <pose frame="">0 0.000323 0.012797 0 0.021197 -0.003571</pose>
        </sensor>
        <self_collide>0</self_collide>
        <kinematic>0</kinematic>
      </link>
      <joint name="head_lidar_spinning_joint" type="revolute">
        <child>head_lidar_mount_link</child>
        <parent>head_link</parent>
        <axis>
          <xyz>1 0 0</xyz>
          <limit>
            <lower>-1e+16</lower>
            <upper>1e+16</upper>
          </limit>
          <dynamics>
            <spring_reference>0</spring_reference>
            <spring_stiffness>0</spring_stiffness>
          </dynamics>
          <use_parent_model_frame>1</use_parent_model_frame>
        </axis>
        <physics>
          <ode>
            <implicit_spring_damper>1</implicit_spring_damper>
            <cfm_damping>1</cfm_damping>
            <limit>
              <cfm>0</cfm>
              <erp>0.2</erp>
            </limit>
          </ode>
        </physics>
      </joint>
      <link name="l_arm_shoulder_pitch">
        <pose frame="">0 0.234 0.602 0 -0 0</pose>
        <inertial>
          <pose frame="">0 0 -0 0 -0 0</pose>
          <mass>0.3</mass>
          <inertia>
            <ixx>0.00018</ixx>
            <ixy>0</ixy>
            <ixz>0</ixz>
            <iyy>0.00045</iyy>
            <iyz>0</iyz>
            <izz>0.00045</izz>
          </inertia>
        </inertial>
        <collision name="l_arm_shoulder_pitch_collision">
          <pose frame="">0 -0.01 0 0 -0 0</pose>
          <geometry>
            <box>
              <size>0.16 0.085 0.06</size>
            </box>
          </geometry>
          <max_contacts>10</max_contacts>
          <surface>
            <contact>
              <ode/>
            </contact>
            <bounce/>
            <friction>
              <torsional>
                <ode/>
              </torsional>
              <ode/>
            </friction>
          </surface>
        </collision>
        <visual name="l_arm_shoulder_pitch_visual">
          <pose frame="">0 -0.051 0 3e-06 1.57079 3.14159</pose>
          <geometry>
            <mesh>
              <scale>0.001 0.001 0.001</scale>
              <uri>model://centaur/meshes/shoulder_pitch_left.stl</uri>
            </mesh>
          </geometry>
        </visual>
        <self_collide>0</self_collide>
        <kinematic>0</kinematic>
      </link>
      <joint name="l_shoulder_pitch" type="revolute">
        <child>l_arm_shoulder_pitch</child>
        <parent>utorso</parent>
        <axis>
          <xyz>0 1 0</xyz>
          <limit>
            <lower>-3.14159</lower>
            <upper>2.3</upper>
            <effort>390.131</effort>
            <velocity>2.5</velocity>
          </limit>
          <dynamics>
            <damping>0.1</damping>
            <friction>0</friction>
            <spring_reference>0</spring_reference>
            <spring_stiffness>0</spring_stiffness>
          </dynamics>
          <use_parent_model_frame>1</use_parent_model_frame>
        </axis>
        <physics>
          <ode>
            <implicit_spring_damper>1</implicit_spring_damper>
            <cfm_damping>1</cfm_damping>
            <limit>
              <cfm>0</cfm>
              <erp>0.2</erp>
            </limit>
          </ode>
        </physics>
      </joint>
      <link name="l_arm_shoulder_roll">
        <pose frame="">0 0.234 0.602 0 -0 0</pose>
        <inertial>
          <pose frame="">0 0 -0 0 -0 0</pose>
          <mass>0.6</mass>
          <inertia>
            <ixx>0.00036</ixx>
            <ixy>0</ixy>
            <ixz>0</ixz>
            <iyy>0.0009</iyy>
            <iyz>0</iyz>
            <izz>0.0009</izz>
          </inertia>
        </inertial>
        <collision name="l_arm_shoulder_roll_collision">
          <pose frame="">0 0 0 0 -0 0</pose>
          <geometry>
            <box>
              <size>0.16 0.06 0.06</size>
            </box>
          </geometry>
          <max_contacts>10</max_contacts>
          <surface>
            <contact>
              <ode/>
            </contact>
            <bounce/>
            <friction>
              <torsional>
                <ode/>
              </torsional>
              <ode/>
            </friction>
          </surface>
        </collision>
        <visual name="l_arm_shoulder_roll_visual">
          <pose frame="">0.024 0 0 1.5708 0 -1.5708</pose>
          <geometry>
            <mesh>
              <scale>0.001 0.001 0.001</scale>
              <uri>model://centaur/meshes/shoulder_roll_left.stl</uri>
            </mesh>
          </geometry>
        </visual>
        <self_collide>0</self_collide>
        <kinematic>0</kinematic>
      </link>
      <joint name="l_shoulder_roll" type="revolute">
        <child>l_arm_shoulder_roll</child>
        <parent>l_arm_shoulder_pitch</parent>
        <axis>
          <xyz>-1 0 0</xyz>
          <limit>
            <lower>-3.14159</lower>
            <upper>0.05</upper>
            <effort>390.131</effort>
            <velocity>2.5</velocity>
          </limit>
          <dynamics>
            <damping>0.1</damping>
            <friction>0</friction>
            <spring_reference>0</spring_reference>
            <spring_stiffness>0</spring_stiffness>
          </dynamics>
          <use_parent_model_frame>1</use_parent_model_frame>
        </axis>
        <physics>
          <ode>
            <implicit_spring_damper>1</implicit_spring_damper>
            <cfm_damping>1</cfm_damping>
            <limit>
              <cfm>0</cfm>
              <erp>0.2</erp>
            </limit>
          </ode>
        </physics>
      </joint>
      <link name="l_arm_shoulder_yaw">
        <pose frame="">0 0.234 0.602 0 -0 0</pose>
        <inertial>
          <pose frame="">0 0 -0.129 0 -0 0</pose>
          <mass>2.89</mass>
          <inertia>
            <ixx>0.0115639</ixx>
            <ixy>0</ixy>
            <ixz>0</ixz>
            <iyy>0.0115639</iyy>
            <iyz>0</iyz>
            <izz>0.00308267</izz>
          </inertia>
        </inertial>
        <collision name="l_arm_shoulder_yaw_collision">
          <pose frame="">0 0 -0.129 0 -0 0</pose>
          <geometry>
            <box>
              <size>0.08 0.08 0.204</size>
            </box>
          </geometry>
          <max_contacts>10</max_contacts>
          <surface>
            <contact>
              <ode/>
            </contact>
            <bounce/>
            <friction>
              <torsional>
                <ode/>
              </torsional>
              <ode/>
            </friction>
          </surface>
        </collision>
        <collision name="l_arm_shoulder_yaw_collision_1">
          <pose frame="">0.03 0 -0.246 0 0.785398 0</pose>
          <geometry>
            <box>
              <size>0.06 0.13 0.06</size>
            </box>
          </geometry>
          <max_contacts>10</max_contacts>
          <surface>
            <contact>
              <ode/>
            </contact>
            <bounce/>
            <friction>
              <torsional>
                <ode/>
              </torsional>
              <ode/>
            </friction>
          </surface>
        </collision>
        <visual name="l_arm_shoulder_yaw_visual">
          <pose frame="">0 0 -0.027 1.5708 0 -1.5708</pose>
          <geometry>
            <mesh>
              <scale>0.001 0.001 0.001</scale>
              <uri>model://centaur/meshes/shoulder_yaw_left.stl</uri>
            </mesh>
          </geometry>
        </visual>
        <self_collide>0</self_collide>
        <kinematic>0</kinematic>
      </link>
      <joint name="l_shoulder_yaw" type="revolute">
        <child>l_arm_shoulder_yaw</child>
        <parent>l_arm_shoulder_roll</parent>
        <axis>
          <xyz>0 0 -1</xyz>
          <limit>
            <lower>-1.5708</lower>
            <upper>3.14159</upper>
            <effort>390.131</effort>
            <velocity>2.5</velocity>
          </limit>
          <dynamics>
            <damping>0.1</damping>
            <friction>0</friction>
            <spring_reference>0</spring_reference>
            <spring_stiffness>0</spring_stiffness>
          </dynamics>
          <use_parent_model_frame>1</use_parent_model_frame>
        </axis>
        <physics>
          <ode>
            <implicit_spring_damper>1</implicit_spring_damper>
            <cfm_damping>1</cfm_damping>
            <limit>
              <cfm>0</cfm>
              <erp>0.2</erp>
            </limit>
          </ode>
        </physics>
      </joint>
      <link name="l_arm_elbow">
        <pose frame="">0.03 0.234 0.356 0 -0 0</pose>
        <inertial>
          <pose frame="">0 0 -0 0 -0 0</pose>
          <mass>0.13</mass>
          <inertia>
            <ixx>0.000313083</ixx>
            <ixy>0</ixy>
            <ixz>0</ixz>
            <iyy>0.000108333</iyy>
            <iyz>0</iyz>
            <izz>0.00028275</izz>
          </inertia>
        </inertial>
        <collision name="l_arm_elbow_collision">
          <pose frame="">-0.03 0 -0.02 0 -0 0</pose>
          <geometry>
            <box>
              <size>0.06 0.13 0.08</size>
            </box>
          </geometry>
          <max_contacts>10</max_contacts>
          <surface>
            <contact>
              <ode/>
            </contact>
            <bounce/>
            <friction>
              <torsional>
                <ode/>
              </torsional>
              <ode/>
            </friction>
          </surface>
        </collision>
        <visual name="l_arm_elbow_visual">
          <pose frame="">-0.03 0 0 1.5708 0 -1.5708</pose>
          <geometry>
            <mesh>
              <scale>0.001 0.001 0.001</scale>
              <uri>model://centaur/meshes/elbow_left_mod.stl</uri>
            </mesh>
          </geometry>
        </visual>
        <self_collide>0</self_collide>
        <kinematic>0</kinematic>
      </link>
      <joint name="l_elbow" type="revolute">
        <child>l_arm_elbow</child>
        <parent>l_arm_shoulder_yaw</parent>
        <axis>
          <xyz>0 1 0</xyz>
          <limit>
            <lower>-2.9</lower>
            <upper>0.6</upper>
            <effort>210.142</effort>
            <velocity>2.5</velocity>
          </limit>
          <dynamics>
            <damping>0.1</damping>
            <friction>0</friction>
            <spring_reference>0</spring_reference>
            <spring_stiffness>0</spring_stiffness>
          </dynamics>
          <use_parent_model_frame>1</use_parent_model_frame>
        </axis>
        <physics>
          <ode>
            <implicit_spring_damper>1</implicit_spring_damper>
            <cfm_damping>1</cfm_damping>
            <limit>
              <cfm>0</cfm>
              <erp>0.2</erp>
            </limit>
          </ode>
        </physics>
      </joint>
      <link name="l_arm_wrist_yaw">
        <pose frame="">0 0.234 0.17 0 -0 1.5708</pose>
        <inertial>
          <pose frame="">0 0 0.05 0 -0 0</pose>
          <mass>0.81</mass>
          <inertia>
            <ixx>0.000918</ixx>
            <ixy>0</ixy>
            <ixz>0</ixz>
            <iyy>0.000918</iyy>
            <iyz>0</iyz>
            <izz>0.000486</izz>
          </inertia>
        </inertial>
        <collision name="l_arm_wrist_yaw_collision">
          <pose frame="">0 0 0 0 -0 0</pose>
          <geometry>
            <box>
              <size>0.1 0.06 0.06</size>
            </box>
          </geometry>
          <max_contacts>10</max_contacts>
          <surface>
            <contact>
              <ode/>
            </contact>
            <bounce/>
            <friction>
              <torsional>
                <ode/>
              </torsional>
              <ode/>
            </friction>
          </surface>
        </collision>
        <collision name="l_arm_wrist_yaw_collision_1">
          <pose frame="">0 0 0.07 0 -0 0</pose>
          <geometry>
            <box>
              <size>0.06 0.06 0.1</size>
            </box>
          </geometry>
          <max_contacts>10</max_contacts>
          <surface>
            <contact>
              <ode/>
            </contact>
            <bounce/>
            <friction>
              <torsional>
                <ode/>
              </torsional>
              <ode/>
            </friction>
          </surface>
        </collision>
        <visual name="l_arm_wrist_yaw_visual">
          <pose frame="">0 0 0 1.5708 0 -1.5708</pose>
          <geometry>
            <mesh>
              <scale>0.001 0.001 0.001</scale>
              <uri>model://centaur/meshes/wrist_yaw_left_mod.stl</uri>
            </mesh>
          </geometry>
        </visual>
        <self_collide>0</self_collide>
        <kinematic>0</kinematic>
      </link>
      <joint name="l_wrist_yaw1" type="revolute">
        <child>l_arm_wrist_yaw</child>
        <parent>l_arm_elbow</parent>
        <axis>
          <xyz>0 0 -1</xyz>
          <limit>
            <lower>-3.14159</lower>
            <upper>4.71</upper>
            <effort>50.596</effort>
            <velocity>1.4</velocity>
          </limit>
          <dynamics>
            <damping>0.1</damping>
            <friction>0</friction>
            <spring_reference>0</spring_reference>
            <spring_stiffness>0</spring_stiffness>
          </dynamics>
          <use_parent_model_frame>1</use_parent_model_frame>
        </axis>
        <physics>
          <ode>
            <implicit_spring_damper>1</implicit_spring_damper>
            <cfm_damping>1</cfm_damping>
            <limit>
              <cfm>0</cfm>
              <erp>0.2</erp>
            </limit>
          </ode>
        </physics>
      </joint>
      <link name="l_arm_wrist_roll">
        <pose frame="">0 0.234 0.17 0 -0 1.5708</pose>
        <inertial>
          <pose frame="">0 0 -0.07 0 -0 0</pose>
          <mass>0.27</mass>
          <inertia>
            <ixx>0.000306</ixx>
            <ixy>0</ixy>
            <ixz>0</ixz>
            <iyy>0.000306</iyy>
            <iyz>0</iyz>
            <izz>0.000162</izz>
          </inertia>
        </inertial>
        <collision name="l_arm_wrist_roll_collision">
          <pose frame="">0 0 0 0 -0 0</pose>
          <geometry>
            <box>
              <size>0.1 0.06 0.06</size>
            </box>
          </geometry>
          <max_contacts>10</max_contacts>
          <surface>
            <contact>
              <ode/>
            </contact>
            <bounce/>
            <friction>
              <torsional>
                <ode/>
              </torsional>
              <ode/>
            </friction>
          </surface>
        </collision>
        <collision name="l_arm_wrist_roll_collision_1">
          <pose frame="">0 0 -0.08 0 -0 0</pose>
          <geometry>
            <box>
              <size>0.06 0.06 0.1</size>
            </box>
          </geometry>
          <max_contacts>10</max_contacts>
          <surface>
            <contact>
              <ode/>
            </contact>
            <bounce/>
            <friction>
              <torsional>
                <ode/>
              </torsional>
              <ode/>
            </friction>
          </surface>
        </collision>
        <visual name="l_arm_wrist_roll_visual">
          <pose frame="">0 0 0 1.5708 0 -1.5708</pose>
          <geometry>
            <mesh>
              <scale>0.001 0.001 0.001</scale>
              <uri>model://centaur/meshes/wrist_roll_left_mod.stl</uri>
            </mesh>
          </geometry>
        </visual>
        <self_collide>0</self_collide>
        <kinematic>0</kinematic>
      </link>
      <joint name="l_wrist_roll" type="revolute">
        <child>l_arm_wrist_roll</child>
        <parent>l_arm_wrist_yaw</parent>
        <axis>
          <xyz>0 1 0</xyz>
          <limit>
            <lower>-1.47</lower>
            <upper>1.47</upper>
            <effort>50.596</effort>
            <velocity>1.4</velocity>
          </limit>
          <dynamics>
            <damping>0.1</damping>
            <friction>0</friction>
            <spring_reference>0</spring_reference>
            <spring_stiffness>0</spring_stiffness>
          </dynamics>
          <use_parent_model_frame>1</use_parent_model_frame>
        </axis>
        <physics>
          <ode>
            <implicit_spring_damper>1</implicit_spring_damper>
            <cfm_damping>1</cfm_damping>
            <limit>
              <cfm>0</cfm>
              <erp>0.2</erp>
            </limit>
          </ode>
        </physics>
      </joint>
      <link name="l_hand">
        <pose frame="">0 0.234 0.17 0 -0 1.5708</pose>
        <inertial>
          <pose frame="">0.005474 -0.002901 -0.191607 0 -0 0</pose>
          <mass>0.83</mass>
          <inertia>
            <ixx>0.000516584</ixx>
            <ixy>2.44776e-06</ixy>
            <ixz>4.77597e-05</ixz>
            <iyy>0.000522904</iyy>
            <iyz>-2.53148e-05</iyz>
            <izz>4.24571e-05</izz>
          </inertia>
        </inertial>
        <collision name="l_hand_collision">
          <pose frame="">0 0 -0.135 0 -0 0</pose>
          <geometry>
            <box>
              <size>0.035 0.035 0.01</size>
            </box>
          </geometry>
          <max_contacts>10</max_contacts>
          <surface>
            <contact>
              <ode/>
            </contact>
            <bounce/>
            <friction>
              <torsional>
                <ode/>
              </torsional>
              <ode/>
            </friction>
          </surface>
        </collision>
        <collision name="l_hand_fixed_joint_lump__l_palm_collision_1">
          <pose frame="">0 0 -0.16 3.14159 -0 1.5708</pose>
          <geometry>
            <mesh>
              <scale>1 1 1</scale>
              <uri>model://centaur/meshes/l_palm.stl</uri>
            </mesh>
          </geometry>
          <surface>
            <contact>
              <ode>
                <kp>1e+06</kp>
                <kd>1</kd>
                <max_vel>0.1</max_vel>
                <min_depth>0</min_depth>
              </ode>
            </contact>
            <friction>
              <ode>
                <mu>1.1</mu>
                <mu2>1.1</mu2>
              </ode>
              <torsional>
                <ode/>
              </torsional>
            </friction>
            <bounce/>
          </surface>
          <max_contacts>6</max_contacts>
        </collision>
        <visual name="l_hand_visual">
          <pose frame="">0 0 -0.135 0 -0 0</pose>
          <geometry>
            <box>
              <size>0.035 0.035 0.01</size>
            </box>
          </geometry>
        </visual>
        <visual name="l_hand_fixed_joint_lump__l_palm_visual_1">
          <pose frame="">0 0 -0.16 3.14159 -0 1.5708</pose>
          <geometry>
            <mesh>
              <scale>1 1 1</scale>
              <uri>model://centaur/meshes/l_palm.stl</uri>
            </mesh>
          </geometry>
          <material>
            <script>
              <uri>__default__</uri>
              <name>__default__</name>
            </script>
          </material>
        </visual>
        <gravity>1</gravity>
        <velocity_decay/>
        <self_collide>0</self_collide>
        <kinematic>0</kinematic>
      </link>
      <joint name="l_wrist_yaw2" type="revolute">
        <child>l_hand</child>
        <parent>l_arm_wrist_roll</parent>
        <axis>
          <xyz>0 0 -1</xyz>
          <limit>
            <lower>-2.54</lower>
            <upper>0.9</upper>
            <effort>50.596</effort>
            <velocity>1.4</velocity>
          </limit>
          <dynamics>
            <damping>0.1</damping>
            <friction>0</friction>
            <spring_reference>0</spring_reference>
            <spring_stiffness>0</spring_stiffness>
          </dynamics>
          <use_parent_model_frame>1</use_parent_model_frame>
        </axis>
        <physics>
          <ode>
            <implicit_spring_damper>1</implicit_spring_damper>
            <cfm_damping>1</cfm_damping>
            <limit>
              <cfm>0</cfm>
              <erp>0.2</erp>
            </limit>
          </ode>
        </physics>
      </joint>
      <link name="l_f0_link_0">
        <pose frame="">-0.0355 0.2701 -0.0496 1.82659 -0 3.14159</pose>
        <inertial>
          <pose frame="">-0.0002 0.00092 0.02111 0 -0 0</pose>
          <mass>0.1</mass>
          <inertia>
            <ixx>2.139e-05</ixx>
            <ixy>3.9e-07</ixy>
            <ixz>-7.1e-07</ixz>
            <iyy>1.898e-05</iyy>
            <iyz>-1.36e-06</iyz>
            <izz>4.73e-06</izz>
          </inertia>
        </inertial>
        <collision name="l_f0_link_0_collision">
          <pose frame="">0 0 0 3.14159 1.57079 3.14159</pose>
          <geometry>
            <cylinder>
              <length>0.02</length>
              <radius>0.017</radius>
            </cylinder>
          </geometry>
          <surface>
            <contact>
              <ode>
                <kp>1e+06</kp>
                <kd>10</kd>
                <max_vel>0.1</max_vel>
                <min_depth>0</min_depth>
              </ode>
            </contact>
            <friction>
              <ode>
                <mu>1.1</mu>
                <mu2>1.1</mu2>
              </ode>
              <torsional>
                <ode/>
              </torsional>
            </friction>
            <bounce/>
          </surface>
          <max_contacts>1</max_contacts>
        </collision>
        <collision name="l_f0_link_0_collision_1">
          <pose frame="">0 0 0.02 0 -0 0</pose>
          <geometry>
            <cylinder>
              <length>0.04</length>
              <radius>0.008</radius>
            </cylinder>
          </geometry>
          <surface>
            <contact>
              <ode>
                <kp>1e+06</kp>
                <kd>10</kd>
                <max_vel>0.1</max_vel>
                <min_depth>0</min_depth>
              </ode>
            </contact>
            <friction>
              <ode>
                <mu>1.1</mu>
                <mu2>1.1</mu2>
              </ode>
              <torsional>
                <ode/>
              </torsional>
            </friction>
            <bounce/>
          </surface>
          <max_contacts>1</max_contacts>
        </collision>
        <collision name="l_f0_link_0_collision_2">
          <pose frame="">0 -0.00407 0.042 3.14159 1.57079 3.14159</pose>
          <geometry>
            <cylinder>
              <length>0.02</length>
              <radius>0.014</radius>
            </cylinder>
          </geometry>
          <surface>
            <contact>
              <ode>
                <kp>1e+06</kp>
                <kd>10</kd>
                <max_vel>0.1</max_vel>
                <min_depth>0</min_depth>
              </ode>
            </contact>
            <friction>
              <ode>
                <mu>1.1</mu>
                <mu2>1.1</mu2>
              </ode>
              <torsional>
                <ode/>
              </torsional>
            </friction>
            <bounce/>
          </surface>
          <max_contacts>1</max_contacts>
        </collision>
        <collision name="l_f0_link_0_collision_3">
          <pose frame="">0.001 -0.00207 0.06783 0.4 -0 0</pose>
          <geometry>
            <cylinder>
              <length>0.05</length>
              <radius>0.008</radius>
            </cylinder>
          </geometry>
          <surface>
            <contact>
              <ode>
                <kp>1e+06</kp>
                <kd>10</kd>
                <max_vel>0.1</max_vel>
                <min_depth>0</min_depth>
              </ode>
            </contact>
            <friction>
              <ode>
                <mu>1.1</mu>
                <mu2>1.1</mu2>
              </ode>
              <torsional>
                <ode/>
              </torsional>
            </friction>
            <bounce/>
          </surface>
          <max_contacts>1</max_contacts>
        </collision>
        <visual name="l_f0_link_0_visual">
          <pose frame="">0 0 0 0 -0 0</pose>
          <geometry>
            <mesh>
              <scale>1 1 1</scale>
              <uri>model://centaur/meshes/l_f0_link_0.stl</uri>
            </mesh>
          </geometry>
          <material>
            <script>
              <uri>__default__</uri>
              <name>__default__</name>
            </script>
          </material>
        </visual>
        <visual name="l_f0_link_0_visual_1">
          <pose frame="">0 -0.00407 0.04983 0.4 -0 0</pose>
          <geometry>
            <mesh>
              <scale>1 1 1</scale>
              <uri>model://centaur/meshes/l_f0_link_1.stl</uri>
            </mesh>
          </geometry>
          <material>
            <script>
              <uri>__default__</uri>
              <name>__default__</name>
            </script>
          </material>
        </visual>
        <gravity>1</gravity>
        <velocity_decay/>
        <self_collide>0</self_collide>
        <kinematic>0</kinematic>
      </link>
      <joint name="l_f0_j0" type="revolute">
        <child>l_f0_link_0</child>
        <parent>l_hand</parent>
        <axis>
          <xyz>-1 0 0</xyz>
          <limit>
            <lower>0</lower>
            <upper>2.685</upper>
            <effort>10</effort>
            <velocity>10</velocity>
          </limit>
          <dynamics>
            <spring_reference>0</spring_reference>
            <spring_stiffness>0</spring_stiffness>
          </dynamics>
          <use_parent_model_frame>1</use_parent_model_frame>
        </axis>
        <physics>
          <ode>
            <implicit_spring_damper>1</implicit_spring_damper>
            <cfm_damping>1</cfm_damping>
            <limit>
              <cfm>0</cfm>
              <erp>0.2</erp>
            </limit>
          </ode>
        </physics>
      </joint>
      <link name="l_f1_link_0">
        <pose frame="">0.036 0.2701 -0.0496 1.82659 -0 3.14159</pose>
        <inertial>
          <pose frame="">0.0002 0.00092 0.02111 0 -0 0</pose>
          <mass>0.1</mass>
          <inertia>
            <ixx>2.139e-05</ixx>
            <ixy>-3.9e-07</ixy>
            <ixz>7.1e-07</ixz>
            <iyy>1.898e-05</iyy>
            <iyz>-1.36e-06</iyz>
            <izz>4.73e-06</izz>
          </inertia>
        </inertial>
        <collision name="l_f1_link_0_collision">
          <pose frame="">0 0 0 3.14159 1.57079 3.14159</pose>
          <geometry>
            <cylinder>
              <length>0.02</length>
              <radius>0.017</radius>
            </cylinder>
          </geometry>
          <surface>
            <contact>
              <ode>
                <kp>1e+06</kp>
                <kd>10</kd>
                <max_vel>0.1</max_vel>
                <min_depth>0</min_depth>
              </ode>
            </contact>
            <friction>
              <ode>
                <mu>1.1</mu>
                <mu2>1.1</mu2>
              </ode>
              <torsional>
                <ode/>
              </torsional>
            </friction>
            <bounce/>
          </surface>
          <max_contacts>1</max_contacts>
        </collision>
        <collision name="l_f1_link_0_collision_1">
          <pose frame="">0 0 0.02 0 -0 0</pose>
          <geometry>
            <cylinder>
              <length>0.04</length>
              <radius>0.008</radius>
            </cylinder>
          </geometry>
          <surface>
            <contact>
              <ode>
                <kp>1e+06</kp>
                <kd>10</kd>
                <max_vel>0.1</max_vel>
                <min_depth>0</min_depth>
              </ode>
            </contact>
            <friction>
              <ode>
                <mu>1.1</mu>
                <mu2>1.1</mu2>
              </ode>
              <torsional>
                <ode/>
              </torsional>
            </friction>
            <bounce/>
          </surface>
          <max_contacts>1</max_contacts>
        </collision>
        <collision name="l_f1_link_0_collision_2">
          <pose frame="">0 -0.00407 0.042 3.14159 1.57079 3.14159</pose>
          <geometry>
            <cylinder>
              <length>0.02</length>
              <radius>0.014</radius>
            </cylinder>
          </geometry>
          <surface>
            <contact>
              <ode>
                <kp>1e+06</kp>
                <kd>10</kd>
                <max_vel>0.1</max_vel>
                <min_depth>0</min_depth>
              </ode>
            </contact>
            <friction>
              <ode>
                <mu>1.1</mu>
                <mu2>1.1</mu2>
              </ode>
              <torsional>
                <ode/>
              </torsional>
            </friction>
            <bounce/>
          </surface>
          <max_contacts>1</max_contacts>
        </collision>
        <collision name="l_f1_link_0_collision_3">
          <pose frame="">0.001 -0.00207 0.06783 0.4 -0 0</pose>
          <geometry>
            <cylinder>
              <length>0.05</length>
              <radius>0.008</radius>
            </cylinder>
          </geometry>
          <surface>
            <contact>
              <ode>
                <kp>1e+06</kp>
                <kd>10</kd>
                <max_vel>0.1</max_vel>
                <min_depth>0</min_depth>
              </ode>
            </contact>
            <friction>
              <ode>
                <mu>1.1</mu>
                <mu2>1.1</mu2>
              </ode>
              <torsional>
                <ode/>
              </torsional>
            </friction>
            <bounce/>
          </surface>
          <max_contacts>1</max_contacts>
        </collision>
        <visual name="l_f1_link_0_visual">
          <pose frame="">0 0 0 0 -0 0</pose>
          <geometry>
            <mesh>
              <scale>1 1 1</scale>
              <uri>model://centaur/meshes/l_f1_link_0.stl</uri>
            </mesh>
          </geometry>
          <material>
            <script>
              <uri>__default__</uri>
              <name>__default__</name>
            </script>
          </material>
        </visual>
        <visual name="l_f1_link_0_visual_1">
          <pose frame="">0 -0.00407 0.04983 0.4 -0 0</pose>
          <geometry>
            <mesh>
              <scale>1 1 1</scale>
              <uri>model://centaur/meshes/l_f1_link_1.stl</uri>
            </mesh>
          </geometry>
          <material>
            <script>
              <uri>__default__</uri>
              <name>__default__</name>
            </script>
          </material>
        </visual>
        <gravity>1</gravity>
        <velocity_decay/>
        <self_collide>0</self_collide>
        <kinematic>0</kinematic>
      </link>
      <joint name="l_f1_j0" type="revolute">
        <child>l_f1_link_0</child>
        <parent>l_hand</parent>
        <axis>
          <xyz>-1 0 0</xyz>
          <limit>
            <lower>0</lower>
            <upper>2.685</upper>
            <effort>10</effort>
            <velocity>10</velocity>
          </limit>
          <dynamics>
            <spring_reference>0</spring_reference>
            <spring_stiffness>0</spring_stiffness>
          </dynamics>
          <use_parent_model_frame>1</use_parent_model_frame>
        </axis>
        <physics>
          <ode>
            <implicit_spring_damper>1</implicit_spring_damper>
            <cfm_damping>1</cfm_damping>
            <limit>
              <cfm>0</cfm>
              <erp>0.2</erp>
            </limit>
          </ode>
        </physics>
      </joint>
      <link name="r_arm_shoulder_pitch">
        <pose frame="">0 -0.234 0.602 0 -0 0</pose>
        <inertial>
          <pose frame="">0 0 -0 0 -0 0</pose>
          <mass>0.3</mass>
          <inertia>
            <ixx>0.00018</ixx>
            <ixy>0</ixy>
            <ixz>0</ixz>
            <iyy>0.00045</iyy>
            <iyz>0</iyz>
            <izz>0.00045</izz>
          </inertia>
        </inertial>
        <collision name="r_arm_shoulder_pitch_collision">
          <pose frame="">0 0.01 0 0 -0 0</pose>
          <geometry>
            <box>
              <size>0.16 0.085 0.06</size>
            </box>
          </geometry>
          <max_contacts>10</max_contacts>
          <surface>
            <contact>
              <ode/>
            </contact>
            <bounce/>
            <friction>
              <torsional>
                <ode/>
              </torsional>
              <ode/>
            </friction>
          </surface>
        </collision>
        <visual name="r_arm_shoulder_pitch_visual">
          <pose frame="">0 0.051 0 3.14159 1.57079 3.14159</pose>
          <geometry>
            <mesh>
              <scale>0.001 0.001 0.001</scale>
              <uri>model://centaur/meshes/shoulder_pitch_left.stl</uri>
            </mesh>
          </geometry>
        </visual>
        <self_collide>0</self_collide>
        <kinematic>0</kinematic>
      </link>
      <joint name="r_shoulder_pitch" type="revolute">
        <child>r_arm_shoulder_pitch</child>
        <parent>utorso</parent>
        <axis>
          <xyz>0 -1 0</xyz>
          <limit>
            <lower>-2.3</lower>
            <upper>3.14159</upper>
            <effort>390.131</effort>
            <velocity>2.5</velocity>
          </limit>
          <dynamics>
            <damping>0.1</damping>
            <friction>0</friction>
            <spring_reference>0</spring_reference>
            <spring_stiffness>0</spring_stiffness>
          </dynamics>
          <use_parent_model_frame>1</use_parent_model_frame>
        </axis>
        <physics>
          <ode>
            <implicit_spring_damper>1</implicit_spring_damper>
            <cfm_damping>1</cfm_damping>
            <limit>
              <cfm>0</cfm>
              <erp>0.2</erp>
            </limit>
          </ode>
        </physics>
      </joint>
      <link name="r_arm_shoulder_roll">
        <pose frame="">0 -0.234 0.602 0 -0 0</pose>
        <inertial>
          <pose frame="">0 0 -0 0 -0 0</pose>
          <mass>0.6</mass>
          <inertia>
            <ixx>0.00036</ixx>
            <ixy>0</ixy>
            <ixz>0</ixz>
            <iyy>0.0009</iyy>
            <iyz>0</iyz>
            <izz>0.0009</izz>
          </inertia>
        </inertial>
        <collision name="r_arm_shoulder_roll_collision">
          <pose frame="">0 0 0 0 -0 0</pose>
          <geometry>
            <box>
              <size>0.16 0.06 0.06</size>
            </box>
          </geometry>
          <max_contacts>10</max_contacts>
          <surface>
            <contact>
              <ode/>
            </contact>
            <bounce/>
            <friction>
              <torsional>
                <ode/>
              </torsional>
              <ode/>
            </friction>
          </surface>
        </collision>
        <visual name="r_arm_shoulder_roll_visual">
          <pose frame="">0.024 0 0 1.5708 0 -1.5708</pose>
          <geometry>
            <mesh>
              <scale>0.001 0.001 0.001</scale>
              <uri>model://centaur/meshes/shoulder_roll_left.stl</uri>
            </mesh>
          </geometry>
        </visual>
        <self_collide>0</self_collide>
        <kinematic>0</kinematic>
      </link>
      <joint name="r_shoulder_roll" type="revolute">
        <child>r_arm_shoulder_roll</child>
        <parent>r_arm_shoulder_pitch</parent>
        <axis>
          <xyz>-1 0 0</xyz>
          <limit>
            <lower>-0.05</lower>
            <upper>3.14159</upper>
            <effort>390.131</effort>
            <velocity>2.5</velocity>
          </limit>
          <dynamics>
            <damping>0.1</damping>
            <friction>0</friction>
            <spring_reference>0</spring_reference>
            <spring_stiffness>0</spring_stiffness>
          </dynamics>
          <use_parent_model_frame>1</use_parent_model_frame>
        </axis>
        <physics>
          <ode>
            <implicit_spring_damper>1</implicit_spring_damper>
            <cfm_damping>1</cfm_damping>
            <limit>
              <cfm>0</cfm>
              <erp>0.2</erp>
            </limit>
          </ode>
        </physics>
      </joint>
      <link name="r_arm_shoulder_yaw">
        <pose frame="">0 -0.234 0.602 0 -0 0</pose>
        <inertial>
          <pose frame="">0 0 -0.129 0 -0 0</pose>
          <mass>2.89</mass>
          <inertia>
            <ixx>0.0115639</ixx>
            <ixy>0</ixy>
            <ixz>0</ixz>
            <iyy>0.0115639</iyy>
            <iyz>0</iyz>
            <izz>0.00308267</izz>
          </inertia>
        </inertial>
        <collision name="r_arm_shoulder_yaw_collision">
          <pose frame="">0 0 -0.129 0 -0 0</pose>
          <geometry>
            <box>
              <size>0.08 0.08 0.204</size>
            </box>
          </geometry>
          <max_contacts>10</max_contacts>
          <surface>
            <contact>
              <ode/>
            </contact>
            <bounce/>
            <friction>
              <torsional>
                <ode/>
              </torsional>
              <ode/>
            </friction>
          </surface>
        </collision>
        <collision name="r_arm_shoulder_yaw_collision_1">
          <pose frame="">0.03 0 -0.246 0 0.785398 0</pose>
          <geometry>
            <box>
              <size>0.06 0.13 0.06</size>
            </box>
          </geometry>
          <max_contacts>10</max_contacts>
          <surface>
            <contact>
              <ode/>
            </contact>
            <bounce/>
            <friction>
              <torsional>
                <ode/>
              </torsional>
              <ode/>
            </friction>
          </surface>
        </collision>
        <visual name="r_arm_shoulder_yaw_visual">
          <pose frame="">0 0 -0.027 1.5708 0 -1.5708</pose>
          <geometry>
            <mesh>
              <scale>0.001 0.001 0.001</scale>
              <uri>model://centaur/meshes/shoulder_yaw_left.stl</uri>
            </mesh>
          </geometry>
        </visual>
        <self_collide>0</self_collide>
        <kinematic>0</kinematic>
      </link>
      <joint name="r_shoulder_yaw" type="revolute">
        <child>r_arm_shoulder_yaw</child>
        <parent>r_arm_shoulder_roll</parent>
        <axis>
          <xyz>0 0 -1</xyz>
          <limit>
            <lower>-3.14159</lower>
            <upper>1.5708</upper>
            <effort>390.131</effort>
            <velocity>2.5</velocity>
          </limit>
          <dynamics>
            <damping>0.1</damping>
            <friction>0</friction>
            <spring_reference>0</spring_reference>
            <spring_stiffness>0</spring_stiffness>
          </dynamics>
          <use_parent_model_frame>1</use_parent_model_frame>
        </axis>
        <physics>
          <ode>
            <implicit_spring_damper>1</implicit_spring_damper>
            <cfm_damping>1</cfm_damping>
            <limit>
              <cfm>0</cfm>
              <erp>0.2</erp>
            </limit>
          </ode>
        </physics>
      </joint>
      <link name="r_arm_elbow">
        <pose frame="">0.03 -0.234 0.356 0 -0 0</pose>
        <inertial>
          <pose frame="">0 0 -0 0 -0 0</pose>
          <mass>0.13</mass>
          <inertia>
            <ixx>0.000313083</ixx>
            <ixy>0</ixy>
            <ixz>0</ixz>
            <iyy>0.000108333</iyy>
            <iyz>0</iyz>
            <izz>0.00028275</izz>
          </inertia>
        </inertial>
        <collision name="r_arm_elbow_collision">
          <pose frame="">-0.03 0 -0.02 0 -0 0</pose>
          <geometry>
            <box>
              <size>0.06 0.13 0.08</size>
            </box>
          </geometry>
          <max_contacts>10</max_contacts>
          <surface>
            <contact>
              <ode/>
            </contact>
            <bounce/>
            <friction>
              <torsional>
                <ode/>
              </torsional>
              <ode/>
            </friction>
          </surface>
        </collision>
        <visual name="r_arm_elbow_visual">
          <pose frame="">-0.03 0 0 1.5708 0 -1.5708</pose>
          <geometry>
            <mesh>
              <scale>0.001 0.001 0.001</scale>
              <uri>model://centaur/meshes/elbow_left_mod.stl</uri>
            </mesh>
          </geometry>
        </visual>
        <self_collide>0</self_collide>
        <kinematic>0</kinematic>
      </link>
      <joint name="r_elbow" type="revolute">
        <child>r_arm_elbow</child>
        <parent>r_arm_shoulder_yaw</parent>
        <axis>
          <xyz>0 -1 0</xyz>
          <limit>
            <lower>-0.6</lower>
            <upper>2.9</upper>
            <effort>210.142</effort>
            <velocity>2.5</velocity>
          </limit>
          <dynamics>
            <damping>0.1</damping>
            <friction>0</friction>
            <spring_reference>0</spring_reference>
            <spring_stiffness>0</spring_stiffness>
          </dynamics>
          <use_parent_model_frame>1</use_parent_model_frame>
        </axis>
        <physics>
          <ode>
            <implicit_spring_damper>1</implicit_spring_damper>
            <cfm_damping>1</cfm_damping>
            <limit>
              <cfm>0</cfm>
              <erp>0.2</erp>
            </limit>
          </ode>
        </physics>
      </joint>
      <link name="r_arm_wrist_yaw">
        <pose frame="">0 -0.234 0.17 0 0 -1.5708</pose>
        <inertial>
          <pose frame="">0 0 0.05 0 -0 0</pose>
          <mass>0.81</mass>
          <inertia>
            <ixx>0.000918</ixx>
            <ixy>0</ixy>
            <ixz>0</ixz>
            <iyy>0.000918</iyy>
            <iyz>0</iyz>
            <izz>0.000486</izz>
          </inertia>
        </inertial>
        <collision name="r_arm_wrist_yaw_collision">
          <pose frame="">0 0 0 0 -0 0</pose>
          <geometry>
            <box>
              <size>0.1 0.06 0.06</size>
            </box>
          </geometry>
          <max_contacts>10</max_contacts>
          <surface>
            <contact>
              <ode/>
            </contact>
            <bounce/>
            <friction>
              <torsional>
                <ode/>
              </torsional>
              <ode/>
            </friction>
          </surface>
        </collision>
        <collision name="r_arm_wrist_yaw_collision_1">
          <pose frame="">0 0 0.07 0 -0 0</pose>
          <geometry>
            <box>
              <size>0.06 0.06 0.1</size>
            </box>
          </geometry>
          <max_contacts>10</max_contacts>
          <surface>
            <contact>
              <ode/>
            </contact>
            <bounce/>
            <friction>
              <torsional>
                <ode/>
              </torsional>
              <ode/>
            </friction>
          </surface>
        </collision>
        <visual name="r_arm_wrist_yaw_visual">
          <pose frame="">0 0 0 1.5708 0 -1.5708</pose>
          <geometry>
            <mesh>
              <scale>0.001 0.001 0.001</scale>
              <uri>model://centaur/meshes/wrist_yaw_left_mod.stl</uri>
            </mesh>
          </geometry>
        </visual>
        <self_collide>0</self_collide>
        <kinematic>0</kinematic>
      </link>
      <joint name="r_wrist_yaw1" type="revolute">
        <child>r_arm_wrist_yaw</child>
        <parent>r_arm_elbow</parent>
        <axis>
          <xyz>0 0 -1</xyz>
          <limit>
            <lower>-4.71</lower>
            <upper>3.14159</upper>
            <effort>50.596</effort>
            <velocity>1.4</velocity>
          </limit>
          <dynamics>
            <damping>0.1</damping>
            <friction>0</friction>
            <spring_reference>0</spring_reference>
            <spring_stiffness>0</spring_stiffness>
          </dynamics>
          <use_parent_model_frame>1</use_parent_model_frame>
        </axis>
        <physics>
          <ode>
            <implicit_spring_damper>1</implicit_spring_damper>
            <cfm_damping>1</cfm_damping>
            <limit>
              <cfm>0</cfm>
              <erp>0.2</erp>
            </limit>
          </ode>
        </physics>
      </joint>
      <link name="r_arm_wrist_roll">
        <pose frame="">0 -0.234 0.17 0 0 -1.5708</pose>
        <inertial>
          <pose frame="">0 0 -0.07 0 -0 0</pose>
          <mass>0.27</mass>
          <inertia>
            <ixx>0.000306</ixx>
            <ixy>0</ixy>
            <ixz>0</ixz>
            <iyy>0.000306</iyy>
            <iyz>0</iyz>
            <izz>0.000162</izz>
          </inertia>
        </inertial>
        <collision name="r_arm_wrist_roll_collision">
          <pose frame="">0 0 0 0 -0 0</pose>
          <geometry>
            <box>
              <size>0.1 0.06 0.06</size>
            </box>
          </geometry>
          <max_contacts>10</max_contacts>
          <surface>
            <contact>
              <ode/>
            </contact>
            <bounce/>
            <friction>
              <torsional>
                <ode/>
              </torsional>
              <ode/>
            </friction>
          </surface>
        </collision>
        <collision name="r_arm_wrist_roll_collision_1">
          <pose frame="">0 0 -0.08 0 -0 0</pose>
          <geometry>
            <box>
              <size>0.06 0.06 0.1</size>
            </box>
          </geometry>
          <max_contacts>10</max_contacts>
          <surface>
            <contact>
              <ode/>
            </contact>
            <bounce/>
            <friction>
              <torsional>
                <ode/>
              </torsional>
              <ode/>
            </friction>
          </surface>
        </collision>
        <visual name="r_arm_wrist_roll_visual">
          <pose frame="">0 0 0 1.5708 0 -1.5708</pose>
          <geometry>
            <mesh>
              <scale>0.001 0.001 0.001</scale>
              <uri>model://centaur/meshes/wrist_roll_left_mod.stl</uri>
            </mesh>
          </geometry>
        </visual>
        <self_collide>0</self_collide>
        <kinematic>0</kinematic>
      </link>
      <joint name="r_wrist_roll" type="revolute">
        <child>r_arm_wrist_roll</child>
        <parent>r_arm_wrist_yaw</parent>
        <axis>
          <xyz>0 -1 0</xyz>
          <limit>
            <lower>-1.47</lower>
            <upper>1.47</upper>
            <effort>50.596</effort>
            <velocity>1.4</velocity>
          </limit>
          <dynamics>
            <damping>0.1</damping>
            <friction>0</friction>
            <spring_reference>0</spring_reference>
            <spring_stiffness>0</spring_stiffness>
          </dynamics>
          <use_parent_model_frame>1</use_parent_model_frame>
        </axis>
        <physics>
          <ode>
            <implicit_spring_damper>1</implicit_spring_damper>
            <cfm_damping>1</cfm_damping>
            <limit>
              <cfm>0</cfm>
              <erp>0.2</erp>
            </limit>
          </ode>
        </physics>
      </joint>
      <link name="r_hand">
        <pose frame="">0 -0.234 0.17 0 0 -1.5708</pose>
        <inertial>
          <pose frame="">0.005474 0.002901 -0.191607 0 -0 0</pose>
          <mass>0.83</mass>
          <inertia>
            <ixx>0.000516584</ixx>
            <ixy>-2.44775e-06</ixy>
            <ixz>4.77597e-05</ixz>
            <iyy>0.000522904</iyy>
            <iyz>2.53147e-05</iyz>
            <izz>4.24571e-05</izz>
          </inertia>
        </inertial>
        <collision name="r_hand_collision">
          <pose frame="">0 0 -0.135 0 -0 0</pose>
          <geometry>
            <box>
              <size>0.035 0.035 0.01</size>
            </box>
          </geometry>
          <max_contacts>10</max_contacts>
          <surface>
            <contact>
              <ode/>
            </contact>
            <bounce/>
            <friction>
              <torsional>
                <ode/>
              </torsional>
              <ode/>
            </friction>
          </surface>
        </collision>
        <collision name="r_hand_fixed_joint_lump__r_palm_collision_1">
          <pose frame="">0 0 -0.16 3.14159 -0 1.5708</pose>
          <geometry>
            <mesh>
              <scale>1 1 1</scale>
              <uri>model://centaur/meshes/r_palm.stl</uri>
            </mesh>
          </geometry>
          <surface>
            <contact>
              <ode>
                <kp>1e+06</kp>
                <kd>1</kd>
                <max_vel>0.1</max_vel>
                <min_depth>0</min_depth>
              </ode>
            </contact>
            <friction>
              <ode>
                <mu>1.1</mu>
                <mu2>1.1</mu2>
              </ode>
              <torsional>
                <ode/>
              </torsional>
            </friction>
            <bounce/>
          </surface>
          <max_contacts>6</max_contacts>
        </collision>
        <visual name="r_hand_visual">
          <pose frame="">0 0 -0.135 0 -0 0</pose>
          <geometry>
            <box>
              <size>0.035 0.035 0.01</size>
            </box>
          </geometry>
        </visual>
        <visual name="r_hand_fixed_joint_lump__r_palm_visual_1">
          <pose frame="">0 0 -0.16 3.14159 -0 1.5708</pose>
          <geometry>
            <mesh>
              <scale>1 1 1</scale>
              <uri>model://centaur/meshes/r_palm.stl</uri>
            </mesh>
          </geometry>
          <material>
            <script>
              <uri>__default__</uri>
              <name>__default__</name>
            </script>
          </material>
        </visual>
        <gravity>1</gravity>
        <velocity_decay/>
        <self_collide>0</self_collide>
        <kinematic>0</kinematic>
      </link>
      <joint name="r_wrist_yaw2" type="revolute">
        <child>r_hand</child>
        <parent>r_arm_wrist_roll</parent>
        <axis>
          <xyz>0 0 -1</xyz>
          <limit>
            <lower>-0.9</lower>
            <upper>2.54</upper>
            <effort>50.596</effort>
            <velocity>1.4</velocity>
          </limit>
          <dynamics>
            <damping>0.1</damping>
            <friction>0</friction>
            <spring_reference>0</spring_reference>
            <spring_stiffness>0</spring_stiffness>
          </dynamics>
          <use_parent_model_frame>1</use_parent_model_frame>
        </axis>
        <physics>
          <ode>
            <implicit_spring_damper>1</implicit_spring_damper>
            <cfm_damping>1</cfm_damping>
            <limit>
              <cfm>0</cfm>
              <erp>0.2</erp>
            </limit>
          </ode>
        </physics>
      </joint>
      <link name="r_f0_link_0">
        <pose frame="">-0.0355 -0.2701 -0.0496 1.82659 -0 0</pose>
        <inertial>
          <pose frame="">0.0002 0.00092 0.02111 0 -0 0</pose>
          <mass>0.1</mass>
          <inertia>
            <ixx>2.139e-05</ixx>
            <ixy>-3.9e-07</ixy>
            <ixz>7.1e-07</ixz>
            <iyy>1.898e-05</iyy>
            <iyz>-1.36e-06</iyz>
            <izz>4.73e-06</izz>
          </inertia>
        </inertial>
        <collision name="r_f0_link_0_collision">
          <pose frame="">0 0 0 3.14159 1.57079 3.14159</pose>
          <geometry>
            <cylinder>
              <length>0.02</length>
              <radius>0.017</radius>
            </cylinder>
          </geometry>
          <surface>
            <contact>
              <ode>
                <kp>1e+06</kp>
                <kd>10</kd>
                <max_vel>0.1</max_vel>
                <min_depth>0</min_depth>
              </ode>
            </contact>
            <friction>
              <ode>
                <mu>1.1</mu>
                <mu2>1.1</mu2>
              </ode>
              <torsional>
                <ode/>
              </torsional>
            </friction>
            <bounce/>
          </surface>
          <max_contacts>1</max_contacts>
        </collision>
        <collision name="r_f0_link_0_collision_1">
          <pose frame="">0 0 0.02 0 -0 0</pose>
          <geometry>
            <cylinder>
              <length>0.04</length>
              <radius>0.008</radius>
            </cylinder>
          </geometry>
          <surface>
            <contact>
              <ode>
                <kp>1e+06</kp>
                <kd>10</kd>
                <max_vel>0.1</max_vel>
                <min_depth>0</min_depth>
              </ode>
            </contact>
            <friction>
              <ode>
                <mu>1.1</mu>
                <mu2>1.1</mu2>
              </ode>
              <torsional>
                <ode/>
              </torsional>
            </friction>
            <bounce/>
          </surface>
          <max_contacts>1</max_contacts>
        </collision>
        <collision name="r_f0_link_0_collision_2">
          <pose frame="">0 -0.00407 0.042 3.14159 1.57079 3.14159</pose>
          <geometry>
            <cylinder>
              <length>0.02</length>
              <radius>0.014</radius>
            </cylinder>
          </geometry>
          <surface>
            <contact>
              <ode>
                <kp>1e+06</kp>
                <kd>10</kd>
                <max_vel>0.1</max_vel>
                <min_depth>0</min_depth>
              </ode>
            </contact>
            <friction>
              <ode>
                <mu>1.1</mu>
                <mu2>1.1</mu2>
              </ode>
              <torsional>
                <ode/>
              </torsional>
            </friction>
            <bounce/>
          </surface>
          <max_contacts>1</max_contacts>
        </collision>
        <collision name="r_f0_link_0_collision_3">
          <pose frame="">0.001 -0.00207 0.06783 0.4 -0 0</pose>
          <geometry>
            <cylinder>
              <length>0.05</length>
              <radius>0.008</radius>
            </cylinder>
          </geometry>
          <surface>
            <contact>
              <ode>
                <kp>1e+06</kp>
                <kd>10</kd>
                <max_vel>0.1</max_vel>
                <min_depth>0</min_depth>
              </ode>
            </contact>
            <friction>
              <ode>
                <mu>1.1</mu>
                <mu2>1.1</mu2>
              </ode>
              <torsional>
                <ode/>
              </torsional>
            </friction>
            <bounce/>
          </surface>
          <max_contacts>1</max_contacts>
        </collision>
        <visual name="r_f0_link_0_visual">
          <pose frame="">0 0 0 0 -0 0</pose>
          <geometry>
            <mesh>
              <scale>1 1 1</scale>
              <uri>model://centaur/meshes/r_f0_link_0.stl</uri>
            </mesh>
          </geometry>
          <material>
            <script>
              <uri>__default__</uri>
              <name>__default__</name>
            </script>
          </material>
        </visual>
        <visual name="r_f0_link_0_visual_1">
          <pose frame="">0 -0.00407 0.04983 0.4 -0 0</pose>
          <geometry>
            <mesh>
              <scale>1 1 1</scale>
              <uri>model://centaur/meshes/r_f0_link_1.stl</uri>
            </mesh>
          </geometry>
          <material>
            <script>
              <uri>__default__</uri>
              <name>__default__</name>
            </script>
          </material>
        </visual>
        <gravity>1</gravity>
        <velocity_decay/>
        <self_collide>0</self_collide>
        <kinematic>0</kinematic>
      </link>
      <joint name="r_f0_j0" type="revolute">
        <child>r_f0_link_0</child>
        <parent>r_hand</parent>
        <axis>
          <xyz>1 0 0</xyz>
          <limit>
            <lower>0</lower>
            <upper>2.685</upper>
            <effort>10</effort>
            <velocity>10</velocity>
          </limit>
          <dynamics>
            <spring_reference>0</spring_reference>
            <spring_stiffness>0</spring_stiffness>
          </dynamics>
          <use_parent_model_frame>1</use_parent_model_frame>
        </axis>
        <physics>
          <ode>
            <implicit_spring_damper>1</implicit_spring_damper>
            <cfm_damping>1</cfm_damping>
            <limit>
              <cfm>0</cfm>
              <erp>0.2</erp>
            </limit>
          </ode>
        </physics>
      </joint>
      <link name="r_f1_link_0">
        <pose frame="">0.036 -0.2701 -0.0496 1.82659 -0 0</pose>
        <inertial>
          <pose frame="">-0.0002 0.00092 0.02111 0 -0 0</pose>
          <mass>0.1</mass>
          <inertia>
            <ixx>2.139e-05</ixx>
            <ixy>3.9e-07</ixy>
            <ixz>-7.1e-07</ixz>
            <iyy>1.898e-05</iyy>
            <iyz>-1.36e-06</iyz>
            <izz>4.73e-06</izz>
          </inertia>
        </inertial>
        <collision name="r_f1_link_0_collision">
          <pose frame="">0 0 0 3.14159 1.57079 3.14159</pose>
          <geometry>
            <cylinder>
              <length>0.02</length>
              <radius>0.017</radius>
            </cylinder>
          </geometry>
          <surface>
            <contact>
              <ode>
                <kp>1e+06</kp>
                <kd>10</kd>
                <max_vel>0.1</max_vel>
                <min_depth>0</min_depth>
              </ode>
            </contact>
            <friction>
              <ode>
                <mu>1.1</mu>
                <mu2>1.1</mu2>
              </ode>
              <torsional>
                <ode/>
              </torsional>
            </friction>
            <bounce/>
          </surface>
          <max_contacts>1</max_contacts>
        </collision>
        <collision name="r_f1_link_0_collision_1">
          <pose frame="">0 0 0.02 0 -0 0</pose>
          <geometry>
            <cylinder>
              <length>0.04</length>
              <radius>0.008</radius>
            </cylinder>
          </geometry>
          <surface>
            <contact>
              <ode>
                <kp>1e+06</kp>
                <kd>10</kd>
                <max_vel>0.1</max_vel>
                <min_depth>0</min_depth>
              </ode>
            </contact>
            <friction>
              <ode>
                <mu>1.1</mu>
                <mu2>1.1</mu2>
              </ode>
              <torsional>
                <ode/>
              </torsional>
            </friction>
            <bounce/>
          </surface>
          <max_contacts>1</max_contacts>
        </collision>
        <collision name="r_f1_link_0_collision_2">
          <pose frame="">0 -0.00407 0.042 3.14159 1.57079 3.14159</pose>
          <geometry>
            <cylinder>
              <length>0.02</length>
              <radius>0.014</radius>
            </cylinder>
          </geometry>
          <surface>
            <contact>
              <ode>
                <kp>1e+06</kp>
                <kd>10</kd>
                <max_vel>0.1</max_vel>
                <min_depth>0</min_depth>
              </ode>
            </contact>
            <friction>
              <ode>
                <mu>1.1</mu>
                <mu2>1.1</mu2>
              </ode>
              <torsional>
                <ode/>
              </torsional>
            </friction>
            <bounce/>
          </surface>
          <max_contacts>1</max_contacts>
        </collision>
        <collision name="r_f1_link_0_collision_3">
          <pose frame="">0.001 -0.00207 0.06783 0.4 -0 0</pose>
          <geometry>
            <cylinder>
              <length>0.05</length>
              <radius>0.008</radius>
            </cylinder>
          </geometry>
          <surface>
            <contact>
              <ode>
                <kp>1e+06</kp>
                <kd>10</kd>
                <max_vel>0.1</max_vel>
                <min_depth>0</min_depth>
              </ode>
            </contact>
            <friction>
              <ode>
                <mu>1.1</mu>
                <mu2>1.1</mu2>
              </ode>
              <torsional>
                <ode/>
              </torsional>
            </friction>
            <bounce/>
          </surface>
          <max_contacts>1</max_contacts>
        </collision>
        <visual name="r_f1_link_0_visual">
          <pose frame="">0 0 0 0 -0 0</pose>
          <geometry>
            <mesh>
              <scale>1 1 1</scale>
              <uri>model://centaur/meshes/r_f1_link_0.stl</uri>
            </mesh>
          </geometry>
          <material>
            <script>
              <uri>__default__</uri>
              <name>__default__</name>
            </script>
          </material>
        </visual>
        <visual name="r_f1_link_0_visual_1">
          <pose frame="">0 -0.00407 0.04983 0.4 -0 0</pose>
          <geometry>
            <mesh>
              <scale>1 1 1</scale>
              <uri>model://centaur/meshes/r_f1_link_1.stl</uri>
            </mesh>
          </geometry>
          <material>
            <script>
              <uri>__default__</uri>
              <name>__default__</name>
            </script>
          </material>
        </visual>
        <gravity>1</gravity>
        <velocity_decay/>
        <self_collide>0</self_collide>
        <kinematic>0</kinematic>
      </link>
      <joint name="r_f1_j0" type="revolute">
        <child>r_f1_link_0</child>
        <parent>r_hand</parent>
        <axis>
          <xyz>1 0 0</xyz>
          <limit>
            <lower>0</lower>
            <upper>2.685</upper>
            <effort>10</effort>
            <velocity>10</velocity>
          </limit>
          <dynamics>
            <spring_reference>0</spring_reference>
            <spring_stiffness>0</spring_stiffness>
          </dynamics>
          <use_parent_model_frame>1</use_parent_model_frame>
        </axis>
        <physics>
          <ode>
            <implicit_spring_damper>1</implicit_spring_damper>
            <cfm_damping>1</cfm_damping>
            <limit>
              <cfm>0</cfm>
              <erp>0.2</erp>
            </limit>
          </ode>
        </physics>
      </joint>
      <link name="cameraYawServo">
        <pose frame="">0.2 0 0.24 0 -0 0</pose>
        <inertial>
          <pose frame="">0 0 0 0 -0 0</pose>
          <mass>0.1</mass>
          <inertia>
            <ixx>4.9e-05</ixx>
            <ixy>0</ixy>
            <ixz>0</ixz>
            <iyy>4.9e-05</iyy>
            <iyz>0</iyz>
            <izz>4.9e-05</izz>
          </inertia>
        </inertial>
        <collision name="cameraYawServo_collision">
          <pose frame="">0 0 0.0425 0 -0 0</pose>
          <geometry>
            <box>
              <size>0.04 0.03 0.085</size>
            </box>
          </geometry>
          <max_contacts>10</max_contacts>
          <surface>
            <contact>
              <ode/>
            </contact>
            <bounce/>
            <friction>
              <torsional>
                <ode/>
              </torsional>
              <ode/>
            </friction>
          </surface>
        </collision>
        <visual name="cameraYawServo_visual">
          <pose frame="">0 0 0.0425 0 -0 0</pose>
          <geometry>
            <box>
              <size>0.04 0.03 0.085</size>
            </box>
          </geometry>
        </visual>
        <self_collide>0</self_collide>
        <kinematic>0</kinematic>
      </link>
      <joint name="camera/z" type="revolute">
        <child>cameraYawServo</child>
        <parent>base_link</parent>
        <axis>
          <xyz>0 0 1</xyz>
          <limit>
            <lower>-2.35619</lower>
            <upper>2.35619</upper>
            <effort>100</effort>
            <velocity>100</velocity>
          </limit>
          <dynamics>
            <spring_reference>0</spring_reference>
            <spring_stiffness>0</spring_stiffness>
          </dynamics>
          <use_parent_model_frame>1</use_parent_model_frame>
        </axis>
      </joint>
      <link name="mounting_link">
        <pose frame="">0.2 0 0.325 0 -0 0</pose>
        <inertial>
          <pose frame="">0.04425 0.001769 0.042212 0 -0 0</pose>
          <mass>0.26</mass>
          <inertia>
            <ixx>0.000772367</ixx>
            <ixy>-2.875e-06</ixy>
            <ixz>-0.000118094</ixz>
            <iyy>0.00032343</iyy>
            <iyz>2.05673e-05</iyz>
            <izz>0.000761982</izz>
          </inertia>
        </inertial>
        <collision name="mounting_link_fixed_joint_lump__infrared_frame_collision">
          <pose frame="">0.0505 0.046 -0.0025 0 -0 0</pose>
          <geometry>
            <mesh>
              <scale>1 1 1</scale>
              <uri>model://centaur/meshes/thermaleye_camera_hector_v2.stl</uri>
            </mesh>
          </geometry>
          <surface>
            <contact>
              <ode/>
            </contact>
            <friction>
              <ode/>
              <torsional>
                <ode/>
              </torsional>
            </friction>
            <bounce/>
          </surface>
          <max_contacts>10</max_contacts>
        </collision>
        <collision name="mounting_link_fixed_joint_lump__openni_link_collision_1">
          <pose frame="">0.055 0 0.055 0 -0 0</pose>
          <geometry>
            <mesh>
              <scale>1 1 1</scale>
              <uri>model://centaur/meshes/asus_camera_simple.dae</uri>
            </mesh>
          </geometry>
          <max_contacts>10</max_contacts>
          <surface>
            <contact>
              <ode/>
            </contact>
            <bounce/>
            <friction>
              <torsional>
                <ode/>
              </torsional>
              <ode/>
            </friction>
          </surface>
        </collision>
        <visual name="mounting_link_fixed_joint_lump__infrared_frame_visual">
          <pose frame="">0.0505 0.046 -0.0025 0 -0 0</pose>
          <geometry>
            <mesh>
              <scale>1 1 1</scale>
              <uri>model://centaur/meshes/thermaleye_camera_hector_v2.dae</uri>
            </mesh>
          </geometry>
          <material>
            <script>
              <uri>__default__</uri>
              <name>__default__</name>
            </script>
          </material>
        </visual>
        <visual name="mounting_link_fixed_joint_lump__openni_link_visual_1">
          <pose frame="">0.055 0 0.055 0 -0 0</pose>
          <geometry>
            <mesh>
              <scale>1 1 1</scale>
              <uri>model://centaur/meshes/asus_camera_simple.dae</uri>
            </mesh>
          </geometry>
        </visual>
        <velocity_decay/>
        <sensor name="thermal_camera_sensor" type="camera">
          <visualize>false</visualize>
          <update_rate>10</update_rate>
          <camera name="thermal">
            <horizontal_fov>1.5708</horizontal_fov>
            <image>
              <format>R8G8B8</format>
              <width>160</width>
              <height>120</height>
            </image>
            <clip>
              <near>0.01</near>
              <far>100</far>
            </clip>
  <!--
            <noise>
              <type>gaussian</type>
              <mean>0.0</mean>
              <stddev>0.007</stddev>
            </noise>
  -->
          </camera>
          <plugin name="thermal_camera_controller" filename="libgazebo_ros_thermal_camera_pink.so">
            <alwaysOn>true</alwaysOn>
            <updateRate>10</updateRate>
            <imageTopicName>thermal/image_raw</imageTopicName>
            <cameraInfoTopicName>thermal/camera_info</cameraInfoTopicName>
            <frameName>infrared_optical_frame</frameName>
          </plugin>
          <pose frame="">0.0505 0.046 -0.0025 0 -0 0</pose>
        </sensor>
        <gravity>1</gravity>
        <velocity_decay/>
        <sensor name="kinect_camera" type="depth">
          <update_rate>10</update_rate>
          <camera name="kinect_camera">
            <horizontal_fov>1.0472</horizontal_fov>
            <image>
              <format>R8G8B8</format>
              <width>320</width>
              <height>240</height>
            </image>
            <clip>
              <near>0.05</near>
              <far>3</far>
            </clip>
          </camera>
          <plugin name="kinect_camera_controller" filename="libgazebo_ros_openni_kinect.so">
            <cameraName>kinect_camera</cameraName>
            <alwaysOn>true</alwaysOn>
            <updateRate>10</updateRate>
            <imageTopicName>openni/rgb/image_color</imageTopicName>
            <cameraInfoTopicName>openni/camera_info</cameraInfoTopicName>
            <depthImageTopicName>openni/depth/image_raw</depthImageTopicName>
            <depthImageCameraInfoTopicName>openni/depth/camera_info</depthImageCameraInfoTopicName>
            <pointCloudTopicName>openni/depth/points</pointCloudTopicName>
            <frameName>openni_depth_optical_frame</frameName>
            <pointCloudCutoff>0.5</pointCloudCutoff>
            <distortionK1>0</distortionK1>
            <distortionK2>0</distortionK2>
            <distortionK3>0</distortionK3>
            <distortionT1>0</distortionT1>
            <distortionT2>0</distortionT2>
            <CxPrime>0</CxPrime>
            <Cx>0</Cx>
            <Cy>0</Cy>
            <focalLength>0</focalLength>
            <hackBaseline>0</hackBaseline>
          </plugin>
          <pose frame="">0.055 0.049 0.055 0 -0 0</pose>
        </sensor>
        <self_collide>0</self_collide>
        <kinematic>0</kinematic>
      </link>
      <joint name="camera/y" type="revolute">
        <child>mounting_link</child>
        <parent>cameraYawServo</parent>
        <axis>
          <xyz>0 1 0</xyz>
          <limit>
            <lower>-1.5708</lower>
            <upper>1.5708</upper>
            <effort>100</effort>
            <velocity>100</velocity>
          </limit>
          <dynamics>
            <spring_reference>0</spring_reference>
            <spring_stiffness>0</spring_stiffness>
          </dynamics>
          <use_parent_model_frame>1</use_parent_model_frame>
        </axis>
      </joint>
      <link name="left_front_flipper_base_link">
        <pose frame="">0.218 0.245 0 0 -0 0</pose>
        <inertial>
          <pose frame="">0.1125 -0.245 0 0 -0 0</pose>
          <mass>6</mass>
          <inertia>
            <ixx>0.37955</ixx>
            <ixy>0</ixy>
            <ixz>0</ixz>
            <iyy>0.0415125</iyy>
            <iyz>0</iyz>
            <izz>0.388662</izz>
          </inertia>
        </inertial>
        <collision name="left_front_flipper_base_link_collision">
          <pose frame="">0 0 0 1.5708 -0 0</pose>
          <geometry>
            <cylinder>
              <length>0.08</length>
              <radius>0.09</radius>
            </cylinder>
          </geometry>
          <max_contacts>10</max_contacts>
          <surface>
            <contact>
              <ode/>
            </contact>
            <bounce/>
            <friction>
              <torsional>
                <ode/>
              </torsional>
              <ode/>
            </friction>
          </surface>
        </collision>
        <collision name="left_front_flipper_base_link_collision_1">
          <pose frame="">0.225 0 0 1.5708 -0 0</pose>
          <geometry>
            <cylinder>
              <length>0.08</length>
              <radius>0.09</radius>
            </cylinder>
          </geometry>
          <max_contacts>10</max_contacts>
          <surface>
            <contact>
              <ode/>
            </contact>
            <bounce/>
            <friction>
              <torsional>
                <ode/>
              </torsional>
              <ode/>
            </friction>
          </surface>
        </collision>
        <collision name="left_front_flipper_base_link_collision_2">
          <pose frame="">0.1125 0 0 0 -0 0</pose>
          <geometry>
            <box>
              <size>0.225 0.08 0.18</size>
            </box>
          </geometry>
          <max_contacts>10</max_contacts>
          <surface>
            <contact>
              <ode/>
            </contact>
            <bounce/>
            <friction>
              <torsional>
                <ode/>
              </torsional>
              <ode/>
            </friction>
          </surface>
        </collision>
        <collision name="left_front_flipper_base_link_fixed_joint_lump__right_front_flipper_base_link_collision_3">
          <pose frame="">0 -0.49 0 1.5708 -0 0</pose>
          <geometry>
            <cylinder>
              <length>0.08</length>
              <radius>0.09</radius>
            </cylinder>
          </geometry>
          <max_contacts>10</max_contacts>
          <surface>
            <contact>
              <ode/>
            </contact>
            <bounce/>
            <friction>
              <torsional>
                <ode/>
              </torsional>
              <ode/>
            </friction>
          </surface>
        </collision>
        <collision name="left_front_flipper_base_link_fixed_joint_lump__right_front_flipper_base_link_collision_4">
          <pose frame="">0.225 -0.49 0 1.5708 -0 0</pose>
          <geometry>
            <cylinder>
              <length>0.08</length>
              <radius>0.09</radius>
            </cylinder>
          </geometry>
          <max_contacts>10</max_contacts>
          <surface>
            <contact>
              <ode/>
            </contact>
            <bounce/>
            <friction>
              <torsional>
                <ode/>
              </torsional>
              <ode/>
            </friction>
          </surface>
        </collision>
        <collision name="left_front_flipper_base_link_fixed_joint_lump__right_front_flipper_base_link_collision_5">
          <pose frame="">0.1125 -0.49 0 0 -0 0</pose>
          <geometry>
            <box>
              <size>0.225 0.08 0.18</size>
            </box>
          </geometry>
          <max_contacts>10</max_contacts>
          <surface>
            <contact>
              <ode/>
            </contact>
            <bounce/>
            <friction>
              <torsional>
                <ode/>
              </torsional>
              <ode/>
            </friction>
          </surface>
        </collision>
        <visual name="left_front_flipper_base_link_visual">
          <pose frame="">0 0 0 1.5708 -0 0</pose>
          <geometry>
            <cylinder>
              <length>0.08</length>
              <radius>0.09</radius>
            </cylinder>
          </geometry>
        </visual>
        <visual name="left_front_flipper_base_link_visual_1">
          <pose frame="">0.225 0 0 1.5708 -0 0</pose>
          <geometry>
            <cylinder>
              <length>0.08</length>
              <radius>0.09</radius>
            </cylinder>
          </geometry>
        </visual>
        <visual name="left_front_flipper_base_link_visual_2">
          <pose frame="">0.1125 0 0 0 -0 0</pose>
          <geometry>
            <box>
              <size>0.225 0.08 0.18</size>
            </box>
          </geometry>
        </visual>
        <visual name="left_front_flipper_base_link_fixed_joint_lump__right_front_flipper_base_link_visual_3">
          <pose frame="">0 -0.49 0 1.5708 -0 0</pose>
          <geometry>
            <cylinder>
              <length>0.08</length>
              <radius>0.09</radius>
            </cylinder>
          </geometry>
        </visual>
        <visual name="left_front_flipper_base_link_fixed_joint_lump__right_front_flipper_base_link_visual_4">
          <pose frame="">0.225 -0.49 0 1.5708 -0 0</pose>
          <geometry>
            <cylinder>
              <length>0.08</length>
              <radius>0.09</radius>
            </cylinder>
          </geometry>
        </visual>
        <visual name="left_front_flipper_base_link_fixed_joint_lump__right_front_flipper_base_link_visual_5">
          <pose frame="">0.1125 -0.49 0 0 -0 0</pose>
          <geometry>
            <box>
              <size>0.225 0.08 0.18</size>
            </box>
          </geometry>
        </visual>
        <self_collide>0</self_collide>
        <kinematic>0</kinematic>
      </link>
      <joint name="front_flipper_joint" type="revolute">
        <child>left_front_flipper_base_link</child>
        <parent>base_link</parent>
        <axis>
          <xyz>0 1 0</xyz>
          <limit>
            <lower>-1.5708</lower>
            <upper>1.5708</upper>
            <effort>20000</effort>
            <velocity>1.91986</velocity>
          </limit>
          <dynamics>
            <spring_reference>0</spring_reference>
            <spring_stiffness>0</spring_stiffness>
          </dynamics>
          <use_parent_model_frame>1</use_parent_model_frame>
        </axis>
      </joint>
      <link name="laser1RollServo">
        <pose frame="">0.146 0 0.2 0 -0 0</pose>
        <inertial>
          <pose frame="">0 0 0 0 -0 0</pose>
          <mass>0.1</mass>
          <inertia>
            <ixx>4.9e-05</ixx>
            <ixy>0</ixy>
            <ixz>0</ixz>
            <iyy>4.9e-05</iyy>
            <iyz>0</iyz>
            <izz>4.9e-05</izz>
          </inertia>
        </inertial>
        <collision name="laser1RollServo_collision">
          <pose frame="">0.032 0 0 0 -0 0</pose>
          <geometry>
            <box>
              <size>0.064 0.03 0.04</size>
            </box>
          </geometry>
          <max_contacts>10</max_contacts>
          <surface>
            <contact>
              <ode/>
            </contact>
            <bounce/>
            <friction>
              <torsional>
                <ode/>
              </torsional>
              <ode/>
            </friction>
          </surface>
        </collision>
        <visual name="laser1RollServo_visual">
          <pose frame="">0.032 0 0 0 -0 0</pose>
          <geometry>
            <box>
              <size>0.064 0.03 0.04</size>
            </box>
          </geometry>
        </visual>
        <self_collide>0</self_collide>
        <kinematic>0</kinematic>
      </link>
      <joint name="laser1/x" type="revolute">
        <child>laser1RollServo</child>
        <parent>base_link</parent>
        <axis>
          <xyz>1 0 0</xyz>
          <limit>
            <lower>-1.5708</lower>
            <upper>1.5708</upper>
            <effort>100</effort>
            <velocity>100</velocity>
          </limit>
          <dynamics>
            <spring_reference>0</spring_reference>
            <spring_stiffness>0</spring_stiffness>
          </dynamics>
          <use_parent_model_frame>1</use_parent_model_frame>
        </axis>
      </joint>
      <link name="laser1_link">
        <pose frame="">0.21 0 0.2 0 -0 0</pose>
        <inertial>
          <pose frame="">0.021892 0 0.062027 0 -0 0</pose>
          <mass>0.37</mass>
          <inertia>
            <ixx>0.00083943</ixx>
            <ixy>0</ixy>
            <ixz>-0.000186081</ixz>
            <iyy>0.000905105</iyy>
            <iyz>0</iyz>
            <izz>0.000276676</izz>
          </inertia>
        </inertial>
        <collision name="laser1_link_collision">
          <pose frame="">0 0 0.045 0 -0 0</pose>
          <geometry>
            <box>
              <size>0.05 0.05 0.01</size>
            </box>
          </geometry>
          <max_contacts>10</max_contacts>
          <surface>
            <contact>
              <ode/>
            </contact>
            <bounce/>
            <friction>
              <torsional>
                <ode/>
              </torsional>
              <ode/>
            </friction>
          </surface>
        </collision>
        <collision name="laser1_link_fixed_joint_lump__laser1_frame_collision_1">
          <pose frame="">0.03 0 0.0735 0 -0 0</pose>
          <geometry>
            <box>
              <size>0.058 0.058 0.087</size>
            </box>
          </geometry>
          <surface>
            <contact>
              <ode/>
            </contact>
            <friction>
              <ode/>
              <torsional>
                <ode/>
              </torsional>
            </friction>
            <bounce/>
          </surface>
          <max_contacts>10</max_contacts>
        </collision>
        <visual name="laser1_link_visual">
          <pose frame="">0 0 0.045 0 -0 0</pose>
          <geometry>
            <box>
              <size>0.05 0.05 0.01</size>
            </box>
          </geometry>
        </visual>
        <visual name="laser1_link_fixed_joint_lump__laser1_frame_visual_1">
          <pose frame="">0.03 0 0.085 0 -0 0</pose>
          <geometry>
            <mesh>
              <scale>1 1 1</scale>
              <uri>model://centaur/meshes/hokuyo_utm_30lx.dae</uri>
            </mesh>
          </geometry>
          <material>
            <script>
              <uri>__default__</uri>
              <name>__default__</name>
            </script>
          </material>
        </visual>
        <gravity>1</gravity>
        <velocity_decay/>
        <sensor name="laser1" type="ray">
          <always_on>1</always_on>
          <update_rate>40</update_rate>
          <visualize>0</visualize>
          <ray>
            <scan>
              <horizontal>
                <samples>1081</samples>
                <resolution>1</resolution>
                <min_angle>2.35619</min_angle>
                <max_angle>-2.35619</max_angle>
              </horizontal>
              <vertical>
                <samples>1</samples>
                <min_angle>0</min_angle>
                <max_angle>0</max_angle>
              </vertical>
            </scan>
            <range>
              <min>0.2</min>
              <max>30</max>
              <resolution>0.01</resolution>
            </range>
            <noise>
              <type>gaussian</type>
              <mean>0</mean>
              <stddev>0.004</stddev>
            </noise>
          </ray>
          <plugin name="gazebo_ros_laser1_controller" filename="libgazebo_ros_laser.so">
            <topicName>laser1/scan_no_intensities_from_gazebo</topicName>
            <frameName>laser1_frame</frameName>
          </plugin>
          <pose frame="">0.03 0 0.085 0 -0 0</pose>
        </sensor>
        <self_collide>0</self_collide>
        <kinematic>0</kinematic>
      </link>
      <joint name="laser1/y" type="revolute">
        <child>laser1_link</child>
        <parent>laser1RollServo</parent>
        <axis>
          <xyz>0 1 0</xyz>
          <limit>
            <lower>-1.5708</lower>
            <upper>1.5708</upper>
            <effort>100</effort>
            <velocity>100</velocity>
          </limit>
          <dynamics>
            <spring_reference>0</spring_reference>
            <spring_stiffness>0</spring_stiffness>
          </dynamics>
          <use_parent_model_frame>1</use_parent_model_frame>
        </axis>
      </joint>
      <link name="left_rear_flipper_base_link">
        <pose frame="">-0.218 0.245 0 0 -0 0</pose>
        <inertial>
          <pose frame="">-0.1125 -0.245 0 0 -0 0</pose>
          <mass>6</mass>
          <inertia>
            <ixx>0.37955</ixx>
            <ixy>0</ixy>
            <ixz>0</ixz>
            <iyy>0.0415125</iyy>
            <iyz>0</iyz>
            <izz>0.388662</izz>
          </inertia>
        </inertial>
        <collision name="left_rear_flipper_base_link_collision">
          <pose frame="">0 0 0 1.5708 -0 0</pose>
          <geometry>
            <cylinder>
              <length>0.08</length>
              <radius>0.09</radius>
            </cylinder>
          </geometry>
          <max_contacts>10</max_contacts>
          <surface>
            <contact>
              <ode/>
            </contact>
            <bounce/>
            <friction>
              <torsional>
                <ode/>
              </torsional>
              <ode/>
            </friction>
          </surface>
        </collision>
        <collision name="left_rear_flipper_base_link_collision_1">
          <pose frame="">-0.225 0 0 1.5708 -0 0</pose>
          <geometry>
            <cylinder>
              <length>0.08</length>
              <radius>0.09</radius>
            </cylinder>
          </geometry>
          <max_contacts>10</max_contacts>
          <surface>
            <contact>
              <ode/>
            </contact>
            <bounce/>
            <friction>
              <torsional>
                <ode/>
              </torsional>
              <ode/>
            </friction>
          </surface>
        </collision>
        <collision name="left_rear_flipper_base_link_collision_2">
          <pose frame="">-0.1125 0 0 0 -0 0</pose>
          <geometry>
            <box>
              <size>0.225 0.08 0.18</size>
            </box>
          </geometry>
          <max_contacts>10</max_contacts>
          <surface>
            <contact>
              <ode/>
            </contact>
            <bounce/>
            <friction>
              <torsional>
                <ode/>
              </torsional>
              <ode/>
            </friction>
          </surface>
        </collision>
        <collision name="left_rear_flipper_base_link_fixed_joint_lump__right_rear_flipper_base_link_collision_3">
          <pose frame="">0 -0.49 0 1.5708 -0 0</pose>
          <geometry>
            <cylinder>
              <length>0.08</length>
              <radius>0.09</radius>
            </cylinder>
          </geometry>
          <max_contacts>10</max_contacts>
          <surface>
            <contact>
              <ode/>
            </contact>
            <bounce/>
            <friction>
              <torsional>
                <ode/>
              </torsional>
              <ode/>
            </friction>
          </surface>
        </collision>
        <collision name="left_rear_flipper_base_link_fixed_joint_lump__right_rear_flipper_base_link_collision_4">
          <pose frame="">-0.225 -0.49 0 1.5708 -0 0</pose>
          <geometry>
            <cylinder>
              <length>0.08</length>
              <radius>0.09</radius>
            </cylinder>
          </geometry>
          <max_contacts>10</max_contacts>
          <surface>
            <contact>
              <ode/>
            </contact>
            <bounce/>
            <friction>
              <torsional>
                <ode/>
              </torsional>
              <ode/>
            </friction>
          </surface>
        </collision>
        <collision name="left_rear_flipper_base_link_fixed_joint_lump__right_rear_flipper_base_link_collision_5">
          <pose frame="">-0.1125 -0.49 0 0 -0 0</pose>
          <geometry>
            <box>
              <size>0.225 0.08 0.18</size>
            </box>
          </geometry>
          <max_contacts>10</max_contacts>
          <surface>
            <contact>
              <ode/>
            </contact>
            <bounce/>
            <friction>
              <torsional>
                <ode/>
              </torsional>
              <ode/>
            </friction>
          </surface>
        </collision>
        <visual name="left_rear_flipper_base_link_visual">
          <pose frame="">0 0 0 1.5708 -0 0</pose>
          <geometry>
            <cylinder>
              <length>0.08</length>
              <radius>0.09</radius>
            </cylinder>
          </geometry>
        </visual>
        <visual name="left_rear_flipper_base_link_visual_1">
          <pose frame="">-0.225 0 0 1.5708 -0 0</pose>
          <geometry>
            <cylinder>
              <length>0.08</length>
              <radius>0.09</radius>
            </cylinder>
          </geometry>
        </visual>
        <visual name="left_rear_flipper_base_link_visual_2">
          <pose frame="">-0.1125 0 0 0 -0 0</pose>
          <geometry>
            <box>
              <size>0.225 0.08 0.18</size>
            </box>
          </geometry>
        </visual>
        <visual name="left_rear_flipper_base_link_fixed_joint_lump__right_rear_flipper_base_link_visual_3">
          <pose frame="">0 -0.49 0 1.5708 -0 0</pose>
          <geometry>
            <cylinder>
              <length>0.08</length>
              <radius>0.09</radius>
            </cylinder>
          </geometry>
        </visual>
        <visual name="left_rear_flipper_base_link_fixed_joint_lump__right_rear_flipper_base_link_visual_4">
          <pose frame="">-0.225 -0.49 0 1.5708 -0 0</pose>
          <geometry>
            <cylinder>
              <length>0.08</length>
              <radius>0.09</radius>
            </cylinder>
          </geometry>
        </visual>
        <visual name="left_rear_flipper_base_link_fixed_joint_lump__right_rear_flipper_base_link_visual_5">
          <pose frame="">-0.1125 -0.49 0 0 -0 0</pose>
          <geometry>
            <box>
              <size>0.225 0.08 0.18</size>
            </box>
          </geometry>
        </visual>
        <self_collide>0</self_collide>
        <kinematic>0</kinematic>
      </link>
      <joint name="rear_flipper_joint" type="revolute">
        <child>left_rear_flipper_base_link</child>
        <parent>base_link</parent>
        <axis>
          <xyz>0 1 0</xyz>
          <limit>
            <lower>-1.5708</lower>
            <upper>1.5708</upper>
            <effort>20000</effort>
            <velocity>1.91986</velocity>
          </limit>
          <dynamics>
            <spring_reference>0</spring_reference>
            <spring_stiffness>0</spring_stiffness>
          </dynamics>
          <use_parent_model_frame>1</use_parent_model_frame>
        </axis>
      </joint>

      <plugin name="force_based_move_controller" filename="libgazebo_ros_force_based_move.so">
        <commandTopic>cmd_vel</commandTopic>
        <odometryTopic>odom_raw</odometryTopic>
        <odometryFrame>odom</odometryFrame>
        <odometryRate>20.0</odometryRate>
        <robotBaseFrame>base_link</robotBaseFrame>
        <publishOdometryTf>0</publishOdometryTf>
        <yaw_velocity_p_gain>4000.0</yaw_velocity_p_gain>
        <x_velocity_p_gain>10000.0</x_velocity_p_gain>
        <y_velocity_p_gain>10000.0</y_velocity_p_gain>
      </plugin>

      <plugin name="imu_controller" filename="libhector_gazebo_ros_imu.so">
        <alwaysOn>true</alwaysOn>
        <updateRate>50.0</updateRate>
        <bodyName>base_link</bodyName>
        <topicName>imu_quat</topicName>
        <accelDrift>0.0 0.0 0.0</accelDrift>
        <accelGaussianNoise>0.1 0.1 0.1</accelGaussianNoise>
        <rateDrift>0.0 0.0 0.0</rateDrift>
        <rateGaussianNoise>0.05 0.05 0.05</rateGaussianNoise>
        <headingDrift>0.0</headingDrift>
        <headingGaussianNoise>0.05</headingGaussianNoise>
      </plugin>

      <plugin name="p3d_base_controller" filename="libgazebo_ros_p3d.so">
        <alwaysOn>true</alwaysOn>
        <updateRate>50.0</updateRate>
        <bodyName>base_link</bodyName>
        <topicName>ground_truth/state</topicName>
        <gaussianNoise>0.01</gaussianNoise>
        <frameName>world</frameName>
        <xyzOffsets>0 0 0</xyzOffsets>
        <rpyOffsets>0 0 0</rpyOffsets>
      </plugin>

      <plugin name="gazebo_ros_control" filename="libgazebo_ros_control.so">
        <robotParam>robot_description</robotParam>
      </plugin>

<!--
      <plugin name="gazebo_ros_control" filename="libgazebo_ros_control.so">
        <robot Namespace>robot/obelix</robot Namespace>
        <robotParam>robot_description</robotParam>
      </plugin>

      <plugin name="gazebo_ros_control" filename="libgazebo_ros_control.so">
        <robot Namespace>robot/thor_mang</robot Namespace>
        <robotParam>robot_description</robotParam>
      </plugin>
-->
      
      <plugin name="pelvis_imu_controller" filename="libhector_gazebo_ros_imu.so">
        <alwaysOn>true</alwaysOn>
        <updateRate>125.0</updateRate>
        <topicName>pelvis_imu</topicName>
        <accelDrift>0.0 0.0 0.0</accelDrift>
        <accelGaussianNoise>0.1 0.1 0.1</accelGaussianNoise>
        <rateDrift>0.0 0.0 0.0</rateDrift>
        <rateGaussianNoise>0.05 0.05 0.05</rateGaussianNoise>
        <headingDrift>0.0</headingDrift>
        <headingGaussianNoise>0.05</headingGaussianNoise>
        <bodyName>base_link</bodyName>
        <xyzOffset>0 0 -0.3</xyzOffset>
        <rpyOffset>0 -0 0</rpyOffset>
      </plugin>

      <plugin name="laser1_servo_controller" filename="libhector_servo_plugin.so">
        <alwaysOn>true</alwaysOn>
        <controlRate>50.0</controlRate>
        <updateRate>0.0</updateRate>
        <firstServoName>laser1/x</firstServoName>
        <firstServoAxis>1 0 0</firstServoAxis>
        <secondServoName>laser1/y</secondServoName>
        <secondServoAxis>0 1 0</secondServoAxis>
        <torque>0.5</torque>
        <topicName>laser1/command</topicName>
        <jointStateName>joint_states</jointStateName>
        <proportionalControllerGain>8.0</proportionalControllerGain>
        <derivativeControllerGain>0.0</derivativeControllerGain>
        <maxVelocity>0.0</maxVelocity>
      </plugin>
      
      <plugin name="camera_servo_controller" filename="libhector_servo_plugin.so">
        <alwaysOn>true</alwaysOn>
        <controlRate>50.0</controlRate>
        <updateRate>0.0</updateRate>
        <firstServoName>camera/z</firstServoName>
        <firstServoAxis>0 0 1</firstServoAxis>
        <secondServoName>camera/y</secondServoName>
        <secondServoAxis>0 1 0</secondServoAxis>
        <torque>0.5</torque>
        <topicName>camera/command</topicName>
        <jointStateName>joint_states</jointStateName>
        <proportionalControllerGain>8.0</proportionalControllerGain>
        <derivativeControllerGain>0.0</derivativeControllerGain>
        <maxVelocity>2.0</maxVelocity>
      </plugin>

      <pose frame="">0 0 0.4 0 -0 0</pose>
    </model>

<!--
  <node name="spawn_robot" pkg="gazebo_ros" type="spawn_model"
    args="-param robot_description
          -urdf
          -model robot_description
          -J head_pan 0
          -J head_tilt 0
          -J l_elbow -2.0
          -J l_shoulder_pitch 0.0
          -J l_shoulder_roll -0.0
          -J l_shoulder_yaw 0.0211927
          -J l_wrist_roll 1.15
          -J l_wrist_yaw1 -2.9
          -J l_wrist_yaw2 0.816801445
          -J r_elbow 2.3
          -J r_shoulder_pitch -0.0
          -J r_shoulder_roll 0.0
          -J r_shoulder_yaw -0.02119781
          -J r_wrist_roll 0.79
          -J r_wrist_yaw1 -0.16
          -J r_wrist_yaw2 -0.816799906
          -J waist_lidar 0
          -J waist_pan 0
          -J waist_tilt 0
          -J front_flipper_joint -0.75
          -J rear_flipper_joint 1.38
          -x 0
          -y 0
          -z 0.4
          -R 0
          -P 0.0
          -Y 0"
    respawn="false" output="screen" />
-->


</sdf>
