<?xml version="1.0" ?>
<!-- =================================================================================== -->
<!-- |    This document was autogenerated by xacro from /home/masaru/hammering_test/src/hector_centaur/hector_centaur_description/robots/centaur_default.urdf.xacro | -->
<!-- |    EDITING THIS FILE BY HAND IS NOT RECOMMENDED                                 | -->
<!-- =================================================================================== -->
<robot name="centaur" xmlns:xacro="http://www.ros.org/wiki/xacro">
  <!-- Included URDF Files -->
  <!-- Included URDF Files -->
  <!-- Properties (Constants) -->
  <!--<xacro:property name="wheel_radius" value="0.185" />-->
  <!--<xacro:property name="wheel_size_y" value="0.0824" />-->
  <!-- half of wheel width + half of socket width + gap -->
  <!-- wheel_radius - socket height -->
  <!-- Properties (Constants) -->
  <!--    <xacro:property name="wheel_offset_y" value="${(total_width - wheel_size_y) / 2}" />-->
  <!--
  Note macros below are exact copies of each with expection of the
  visual/collision tags.
  -->
  <!-- Links and Joints (i.e., the robot) -->
  <link name="base_link">
    <inertial>
      <origin rpy="0 0 0" xyz="0 0.0 0.0"/>
      <mass value="40"/>
      <inertia ixx="0.154413333333" ixy="0.0" ixz="0.0" iyy="0.947746666667" iyz="0.0" izz="1.00933333333"/>
    </inertial>
    <visual>
      <origin rpy="0 0 0" xyz="0.0 0.0 0.0"/>
      <geometry>
        <box size="0.52 0.18 0.118"/>
      </geometry>
      <geometry>
        <box size="0.52 0.18 0.118"/>
      </geometry>
      <material name="Grey">
        <color rgba="0.8 0.8 0.8 1"/>
      </material>
    </visual>
    <visual>
      <origin rpy="1.57079632679 0 0" xyz="0.218 0.155 -0.006"/>
      <geometry>
        <cylinder length="0.1" radius="0.09"/>
      </geometry>
    </visual>
    <visual>
      <origin rpy="1.57079632679 0 0" xyz="-0.218 0.155 -0.006"/>
      <geometry>
        <cylinder length="0.1" radius="0.09"/>
      </geometry>
    </visual>
    <visual>
      <origin rpy="0 0 0" xyz="0.0 0.155 -0.006"/>
      <geometry>
        <box size="0.43 0.1 0.18"/>
      </geometry>
    </visual>
    <visual>
      <origin rpy="1.57079632679 0 0" xyz="0.218 -0.155 -0.006"/>
      <geometry>
        <cylinder length="0.1" radius="0.09"/>
      </geometry>
    </visual>
    <visual>
      <origin rpy="1.57079632679 0 0" xyz="-0.218 -0.155 -0.006"/>
      <geometry>
        <cylinder length="0.1" radius="0.09"/>
      </geometry>
    </visual>
    <visual>
      <origin rpy="0 0 0" xyz="0.0 -0.155 -0.006"/>
      <geometry>
        <box size="0.43 0.1 0.18"/>
      </geometry>
    </visual>
    <collision>
      <origin rpy="0 0 0" xyz="0.0 0.0 0.0"/>
      <geometry>
        <box size="0.52 0.18 0.118"/>
      </geometry>
      <geometry>
        <box size="0.52 0.18 0.118"/>
      </geometry>
    </collision>
    <collision>
      <origin rpy="1.57079632679 0 0" xyz="0.218 0.155 -0.006"/>
      <geometry>
        <cylinder length="0.1" radius="0.09"/>
      </geometry>
    </collision>
    <collision>
      <origin rpy="1.57079632679 0 0" xyz="-0.218 0.155 -0.006"/>
      <geometry>
        <cylinder length="0.1" radius="0.09"/>
      </geometry>
    </collision>
    <collision>
      <origin rpy="0 0 0" xyz="0.0 0.155 -0.006"/>
      <geometry>
        <box size="0.43 0.1 0.18"/>
      </geometry>
    </collision>
    <collision>
      <origin rpy="1.57079632679 0 0" xyz="0.218 -0.155 -0.006"/>
      <geometry>
        <cylinder length="0.1" radius="0.09"/>
      </geometry>
    </collision>
    <collision>
      <origin rpy="1.57079632679 0 0" xyz="-0.218 -0.155 -0.006"/>
      <geometry>
        <cylinder length="0.1" radius="0.09"/>
      </geometry>
    </collision>
    <collision>
      <origin rpy="0 0 0" xyz="0.0 -0.155 -0.006"/>
      <geometry>
        <box size="0.43 0.1 0.18"/>
      </geometry>
    </collision>
  </link>
  <!--
  Note macros below are exact copies of each with expection of the
  visual/collision tags.
  -->
  <!-- use for 2*2 flippers -->
  <!-- front is either 1 (for front flipper) or -1 (for back flipper) -->
  <!-- <joint name="${parent}_${name}_flipper_joint" type="fixed">   -->
  <joint name="front_flipper_joint" type="revolute">
    <origin rpy="0 0 0" xyz="0.218  0.245  0 "/>
    <axis xyz="0 1 0"/>
    <limit effort="20000" lower="-1.57079632679" upper="1.57079632679" velocity="1.91986217719"/>
    <parent link="base_link"/>
    <child link="left_front_flipper_base_link"/>
  </joint>
  <link name="left_front_flipper_base_link">
    <origin rpy="0 0 0" xyz="0 0 0"/>
    <inertial>
      <origin rpy="0 0 0" xyz="0.1125 0 0"/>
      <mass value="3"/>
      <inertia ixx="0.0097" ixy="0.0" ixz="0.0" iyy="0.02075625" iyz="0.0" izz="0.01425625"/>
    </inertial>
    <visual>
      <material name="Grey">
        <color rgba="0.8 0.8 0.8 1"/>
      </material>
      <origin rpy="1.57079632679 0 0" xyz="0 0 0"/>
      <geometry>
        <cylinder length="0.08" radius="0.09"/>
      </geometry>
    </visual>
    <visual>
      <origin rpy="1.57079632679 0 0" xyz="0.225 0 0"/>
      <geometry>
        <cylinder length="0.08" radius="0.09"/>
      </geometry>
    </visual>
    <visual>
      <origin rpy="0 0 0" xyz="0.1125 0 0"/>
      <geometry>
        <box size="0.225 0.08 0.18"/>
      </geometry>
    </visual>
    <collision>
      <origin rpy="1.57079632679 0 0" xyz="0 0 0"/>
      <geometry>
        <cylinder length="0.08" radius="0.09"/>
      </geometry>
    </collision>
    <collision>
      <origin rpy="1.57079632679 0 0" xyz="0.225 0 0"/>
      <geometry>
        <cylinder length="0.08" radius="0.09"/>
      </geometry>
    </collision>
    <collision>
      <origin rpy="0 0 0" xyz="0.1125 0 0"/>
      <geometry>
        <box size="0.225 0.08 0.18"/>
      </geometry>
    </collision>
  </link>
  <joint name="right_front_flipper_joint" type="fixed">
    <origin rpy="0 0 0" xyz="0 -0.49 0"/>
    <parent link="left_front_flipper_base_link"/>
    <child link="right_front_flipper_base_link"/>
  </joint>
  <link name="right_front_flipper_base_link">
    <origin rpy="0 0 0" xyz="0 0 0"/>
    <inertial>
      <origin rpy="0 0 0" xyz="0.1125 0 0"/>
      <mass value="3"/>
      <inertia ixx="0.0097" ixy="0.0" ixz="0.0" iyy="0.02075625" iyz="0.0" izz="0.01425625"/>
    </inertial>
    <visual>
      <material name="Grey">
        <color rgba="0.8 0.8 0.8 1"/>
      </material>
      <origin rpy="1.57079632679 0 0" xyz="0 0 0"/>
      <geometry>
        <cylinder length="0.08" radius="0.09"/>
      </geometry>
    </visual>
    <visual>
      <origin rpy="1.57079632679 0 0" xyz="0.225 0 0"/>
      <geometry>
        <cylinder length="0.08" radius="0.09"/>
      </geometry>
    </visual>
    <visual>
      <origin rpy="0 0 0" xyz="0.1125 0 0"/>
      <geometry>
        <box size="0.225 0.08 0.18"/>
      </geometry>
    </visual>
    <collision>
      <origin rpy="1.57079632679 0 0" xyz="0 0 0"/>
      <geometry>
        <cylinder length="0.08" radius="0.09"/>
      </geometry>
    </collision>
    <collision>
      <origin rpy="1.57079632679 0 0" xyz="0.225 0 0"/>
      <geometry>
        <cylinder length="0.08" radius="0.09"/>
      </geometry>
    </collision>
    <collision>
      <origin rpy="0 0 0" xyz="0.1125 0 0"/>
      <geometry>
        <box size="0.225 0.08 0.18"/>
      </geometry>
    </collision>
  </link>
  <!--Needed for gazebo-->
  <transmission name="front_flipper_joint_transmission">
    <type>transmission_interface/SimpleTransmission</type>
    <joint name="front_flipper_joint">
      <hardwareInterface>EffortJointInterface</hardwareInterface>
    </joint>
    <actuator name="front_flipper_joint_motor">
      <hardwareInterface>EffortJointInterface</hardwareInterface>
      <mechanicalReduction>1</mechanicalReduction>
    </actuator>
  </transmission>
  <gazebo reference="front_left_flipper_base_link">
    <!--<material>Gazebo/Grey</material>-->
    <mu1>0</mu1>
    <mu2>0</mu2>
    <kp>1000000.0</kp>
    <kd>100.0</kd>
    <minDepth>0.001</minDepth>
    <maxVel>1.0</maxVel>
    <maxContacts>1</maxContacts>
  </gazebo>
  <gazebo reference="front_right_flipper_base_link">
    <!--<material>Gazebo/Grey</material>-->
    <mu1>0</mu1>
    <mu2>0</mu2>
    <kp>1000000.0</kp>
    <kd>100.0</kd>
    <minDepth>0.001</minDepth>
    <maxVel>1.0</maxVel>
    <maxContacts>1</maxContacts>
  </gazebo>
  <!-- front is either 1 (for front flipper) or -1 (for back flipper) -->
  <!-- <joint name="${parent}_${name}_flipper_joint" type="fixed">   -->
  <joint name="rear_flipper_joint" type="revolute">
    <origin rpy="0 0 0" xyz="-0.218  0.245  0  "/>
    <axis xyz="0 1 0"/>
    <limit effort="20000" lower="-1.57079632679" upper="1.57079632679" velocity="1.91986217719"/>
    <parent link="base_link"/>
    <child link="left_rear_flipper_base_link"/>
  </joint>
  <link name="left_rear_flipper_base_link">
    <origin rpy="0 0 0" xyz="0 0 0"/>
    <inertial>
      <origin rpy="0 0 0" xyz="-0.1125 0 0"/>
      <mass value="3"/>
      <inertia ixx="0.0097" ixy="0.0" ixz="0.0" iyy="0.02075625" iyz="0.0" izz="0.01425625"/>
    </inertial>
    <visual>
      <material name="Grey">
        <color rgba="0.8 0.8 0.8 1"/>
      </material>
      <origin rpy="1.57079632679 0 0" xyz="0 0 0"/>
      <geometry>
        <cylinder length="0.08" radius="0.09"/>
      </geometry>
    </visual>
    <visual>
      <origin rpy="1.57079632679 0 0" xyz="-0.225 0 0"/>
      <geometry>
        <cylinder length="0.08" radius="0.09"/>
      </geometry>
    </visual>
    <visual>
      <origin rpy="0 0 0" xyz="-0.1125 0 0"/>
      <geometry>
        <box size="0.225 0.08 0.18"/>
      </geometry>
    </visual>
    <collision>
      <origin rpy="1.57079632679 0 0" xyz="0 0 0"/>
      <geometry>
        <cylinder length="0.08" radius="0.09"/>
      </geometry>
    </collision>
    <collision>
      <origin rpy="1.57079632679 0 0" xyz="-0.225 0 0"/>
      <geometry>
        <cylinder length="0.08" radius="0.09"/>
      </geometry>
    </collision>
    <collision>
      <origin rpy="0 0 0" xyz="-0.1125 0 0"/>
      <geometry>
        <box size="0.225 0.08 0.18"/>
      </geometry>
    </collision>
  </link>
  <joint name="right_rear_flipper_joint" type="fixed">
    <origin rpy="0 0 0" xyz="0 -0.49 0"/>
    <parent link="left_rear_flipper_base_link"/>
    <child link="right_rear_flipper_base_link"/>
  </joint>
  <link name="right_rear_flipper_base_link">
    <origin rpy="0 0 0" xyz="0 0 0"/>
    <inertial>
      <origin rpy="0 0 0" xyz="-0.1125 0 0"/>
      <mass value="3"/>
      <inertia ixx="0.0097" ixy="0.0" ixz="0.0" iyy="0.02075625" iyz="0.0" izz="0.01425625"/>
    </inertial>
    <visual>
      <material name="Grey">
        <color rgba="0.8 0.8 0.8 1"/>
      </material>
      <origin rpy="1.57079632679 0 0" xyz="0 0 0"/>
      <geometry>
        <cylinder length="0.08" radius="0.09"/>
      </geometry>
    </visual>
    <visual>
      <origin rpy="1.57079632679 0 0" xyz="-0.225 0 0"/>
      <geometry>
        <cylinder length="0.08" radius="0.09"/>
      </geometry>
    </visual>
    <visual>
      <origin rpy="0 0 0" xyz="-0.1125 0 0"/>
      <geometry>
        <box size="0.225 0.08 0.18"/>
      </geometry>
    </visual>
    <collision>
      <origin rpy="1.57079632679 0 0" xyz="0 0 0"/>
      <geometry>
        <cylinder length="0.08" radius="0.09"/>
      </geometry>
    </collision>
    <collision>
      <origin rpy="1.57079632679 0 0" xyz="-0.225 0 0"/>
      <geometry>
        <cylinder length="0.08" radius="0.09"/>
      </geometry>
    </collision>
    <collision>
      <origin rpy="0 0 0" xyz="-0.1125 0 0"/>
      <geometry>
        <box size="0.225 0.08 0.18"/>
      </geometry>
    </collision>
  </link>
  <!--Needed for gazebo-->
  <transmission name="rear_flipper_joint_transmission">
    <type>transmission_interface/SimpleTransmission</type>
    <joint name="rear_flipper_joint">
      <hardwareInterface>EffortJointInterface</hardwareInterface>
    </joint>
    <actuator name="rear_flipper_joint_motor">
      <hardwareInterface>EffortJointInterface</hardwareInterface>
      <mechanicalReduction>1</mechanicalReduction>
    </actuator>
  </transmission>
  <gazebo reference="rear_left_flipper_base_link">
    <!--<material>Gazebo/Grey</material>-->
    <mu1>0</mu1>
    <mu2>0</mu2>
    <kp>1000000.0</kp>
    <kd>100.0</kd>
    <minDepth>0.001</minDepth>
    <maxVel>1.0</maxVel>
    <maxContacts>1</maxContacts>
  </gazebo>
  <gazebo reference="rear_right_flipper_base_link">
    <!--<material>Gazebo/Grey</material>-->
    <mu1>0</mu1>
    <mu2>0</mu2>
    <kp>1000000.0</kp>
    <kd>100.0</kd>
    <minDepth>0.001</minDepth>
    <maxVel>1.0</maxVel>
    <maxContacts>1</maxContacts>
  </gazebo>
  <gazebo reference="base_link">
    <!--<material>Gazebo/White</material>-->
    <mu1>0.0</mu1>
    <mu2>0.0</mu2>
    <kp>1000000.0</kp>
    <kd>100.0</kd>
    <minDepth>0.001</minDepth>
    <maxVel>1.0</maxVel>
  </gazebo>
  <gazebo>
    <plugin filename="libgazebo_ros_force_based_move.so" name="force_based_move_controller">
      <commandTopic>/cmd_vel_raw</commandTopic>
      <odometryTopic>odom_raw</odometryTopic>
      <odometryFrame>odom</odometryFrame>
      <odometryRate>20.0</odometryRate>
      <robotBaseFrame>base_link</robotBaseFrame>
      <publishOdometryTf>0</publishOdometryTf>
      <yaw_velocity_p_gain>4000.0</yaw_velocity_p_gain>
      <x_velocity_p_gain>10000.0</x_velocity_p_gain>
      <y_velocity_p_gain>10000.0</y_velocity_p_gain>
    </plugin>
    <!-- ros_control plugin -->
    <!-- <plugin filename="libgazebo_ros_control.so" name="gazebo_ros_control">
      <robotNamespace>obelix_robot</robotNamespace>
    </plugin> -->
    <plugin filename="libgazebo_ros_p3d.so" name="p3d_base_controller">
      <alwaysOn>true</alwaysOn>
      <updateRate>50.0</updateRate>
      <bodyName>base_link</bodyName>
      <topicName>ground_truth/state</topicName>
      <gaussianNoise>0.01</gaussianNoise>
      <frameName>world</frameName>
      <xyzOffsets>0 0 0</xyzOffsets>
      <rpyOffsets>0 0 0</rpyOffsets>
    </plugin>
    <plugin filename="libhector_gazebo_ros_imu.so" name="imu_controller">
      <alwaysOn>true</alwaysOn>
      <updateRate>50.0</updateRate>
      <bodyName>base_link</bodyName>
      <topicName>imu_quat</topicName>
      <accelDrift>0.0 0.0 0.0</accelDrift>
      <accelGaussianNoise>0.1 0.1 0.1</accelGaussianNoise>
      <rateDrift>0.0 0.0 0.0</rateDrift>
      <rateGaussianNoise>0.05 0.05 0.05</rateGaussianNoise>
      <headingDrift>0.0</headingDrift>
      <headingGaussianNoise>0.05</headingGaussianNoise>
    </plugin>
  </gazebo>
  <joint name="base_to_pelvis_joint" type="fixed">
    <origin rpy="0 0 0" xyz="0.0 0 0.3"/>
    <!--rpy="0.000329950722368627 -3.91151844547536E-19 1.16573417585641E-15"-->
    <parent link="base_link"/>
    <child link="pelvis"/>
    <!--
    <axis
      xyz="0 0 1" />
    <xacro:joint_medium_servo_limits_macro lower="${-1.8}" upper="${1.3}"/>
    -->
  </joint>
  <!-- unit conversions -->
  <!-- inventor sometimes gives ridiculous units -->
  <!-- such conversion factors make description easier to read -->
  <!-- colors -->
  <!-- colors -->
  <!--<xacro:include filename="$(find thor_mang_description)/urdf/thor_mang_simple_mesh_visual_geoms.urdf.xacro.xml" />    -->
  <!-- unit conversions -->
  <!-- inventor sometimes gives ridiculous units -->
  <!-- such conversion factors make description easier to read -->
  <!-- colors -->
  <!-- colors -->
  <!-- unit conversions -->
  <!-- inventor sometimes gives ridiculous units -->
  <!-- such conversion factors make description easier to read -->
  <!-- colors -->
  <!-- colors -->
  <!--<xacro:include filename="$(find thor_mang_description)/urdf/thor_mang_mesh_collision_geoms.urdf.xacro.xml" />    -->
  <!-- unit conversions -->
  <!-- inventor sometimes gives ridiculous units -->
  <!-- such conversion factors make description easier to read -->
  <!-- colors -->
  <!-- colors -->
  <!--<xacro:include filename="$(find thor_mang_description)/urdf/joint_params.xacro" />-->
  <!-- Increased effort limit by x10 for gazebo -->
  <!--Indices starting at 0 from torso-->
  <!--<xacro:include filename="$(find thor_mang_description)/urdf/joint_params.xacro" />-->
  <!--Indices starting at 0 from pelvis -->
  <!--Note pelvis origin is 7.92 cm below COM-->
  <!--<xacro:include filename="$(find thor_mang_description)/urdf/joint_params.xacro" />-->
  <!--<xacro:include filename="$(find thor_mang_description)/urdf/joint_params.xacro" />-->
  <!-- Increased effort limit by x10 for gazebo -->
  <!--Indices starting at 0 from torso-->
  <!--<xacro:include filename="$(find thor_mang_description)/urdf/joint_params.xacro" />-->
  <!-- Increased effort limit by x10 for gazebo -->
  <!--Indices starting at 0 from torso-->
  <!--  
  <macro name="thor_arm_7dof_simple_macro" params="parent name reflect *origin">
    <thor_arm_7dof_simple_with_offsets_macro parent="${parent}" name="${name}" reflect="${reflect}" j1_offset="-1.4" j2_offset="${M_PI*0.5}" j3_offset="-0.6" j4_offset="0.0" j5_offset="0.0">
      <insert_block name="origin"/>
    </thor_arm_7dof_simple_with_offsets_macro>
  </macro>
  -->
  <!--<xacro:include filename="$(find thor_mang_description)/urdf/joint_params.xacro" />-->
  <!-- Increased effort limit by x10 for gazebo -->
  <!--
     The asus_camera_model macro only adds the model, it does not also add
     the openni gazebo plugin. See the 'asus_camera' macro below for that
    -->
  <!--
     The asus_camera macro only adds the model, and also adds
     the openni gazebo plugin.
    -->
  <!--<xacro:include filename="$(find thor_mang_description)/urdf/joint_params.xacro" />-->
  <!-- Increased effort limit by x10 for gazebo -->
  <!--Indices starting at 0 from torso-->
  <!--  
  <macro name="thor_arm_7dof_simple_macro" params="parent name reflect *origin">
    <thor_arm_7dof_simple_with_offsets_macro parent="${parent}" name="${name}" reflect="${reflect}" j1_offset="-1.4" j2_offset="${M_PI*0.5}" j3_offset="-0.6" j4_offset="0.0" j5_offset="0.0">
      <insert_block name="origin"/>
    </thor_arm_7dof_simple_with_offsets_macro>
  </macro>
  -->
  <!--<xacro:include filename="$(find thor_mang_description)/robots/offsets/thor_mang_tud_joint_offsets.urdf.xacro.xml" /-->
  &gt;
  
  <!--  <macro name="thor_mang_tud_simple_macro">-->
  <link name="pelvis">
    <inertial>
      <origin rpy="0 0 0" xyz="-0.0264 0.0 0.0162"/>
      <mass value="8.2"/>
      <inertia ixx="0.0341666666667" ixy="0.0" ixz="0.0" iyy="0.0341666666667" iyz="0.0" izz="0.0546666666667"/>
    </inertial>
    <visual>
      <origin rpy=" 1.57079632679 0 1.57079632679" xyz="0 0 0"/>
      <geometry>
        <mesh filename="package://centaur/meshes/centaur/pelvis.stl" scale="0.001 0.001 0.001"/>
      </geometry>
      <material name="blue">
        <color rgba="0.2 0.2 0.2 1"/>
      </material>
    </visual>
    <collision>
      <origin rpy="0 0 0" xyz="-0.01 0 0.025"/>
      <geometry>
        <box size="0.23 0.23 0.24"/>
      </geometry>
    </collision>
  </link>
  <joint name="waist_pan" type="revolute">
    <origin rpy="0 0 0" xyz="0.0 0 0.137"/>
    <!--rpy="0.000329950722368627 -3.91151844547536E-19 1.16573417585641E-15"-->
    <parent link="pelvis"/>
    <child link="waist"/>
    <axis xyz="0 0 1"/>
    <limit effort="210.142" lower="-1.8" upper="1.3" velocity="2.5"/>
    <dynamics damping="0.1" friction="0"/>
  </joint>
  <link name="waist">
    <!--    
    <xacro:inertial_sphere_with_pose_macro mass="0.1" diameter="0.05">
      <origin xyz="0.0 0.0 0.0" rpy="0 0 0"/>
    </xacro:inertial_sphere_with_pose_macro>
    -->
    <inertial>
      <origin rpy="0 0 0" xyz="0.0 0.0 0.0"/>
      <mass value="0.8"/>
      <inertia ixx="0.0012" ixy="0.0" ixz="0.0" iyy="0.00048" iyz="0.0" izz="0.0012"/>
    </inertial>
    <visual>
      <origin rpy=" 1.57079632679 0 1.57079632679" xyz="0 0 -0.039"/>
      <geometry>
        <mesh filename="package://centaur/meshes/centaur/waist.stl" scale="0.001 0.001 0.001"/>
      </geometry>
      <material name="blue">
        <color rgba="0.2 0.2 0.2 1"/>
      </material>
    </visual>
    <collision>
      <origin rpy="0 0 0" xyz="0.024 0 0"/>
      <geometry>
        <box size="0.03 0.08 0.03"/>
      </geometry>
    </collision>
  </link>
  <joint name="waist_tilt" type="revolute">
    <origin rpy="0 0 0" xyz="0 0 0.0"/>
    <!--rpy="0.000329950722368627 -3.91151844547536E-19 1.16573417585641E-15"-->
    <parent link="waist"/>
    <child link="utorso"/>
    <axis xyz="0 1 0"/>
    <limit effort="390.131" lower="-0.05" upper="1.07" velocity="2.5"/>
    <dynamics damping="0.1" friction="0"/>
  </joint>
  <link name="utorso">
    <inertial>
      <origin rpy="0 0 0" xyz="-0.0264 0.0 0.155"/>
      <mass value="10.91"/>
      <inertia ixx="0.118191666667" ixy="0.0" ixz="0.0" iyy="0.0931895833333" iyz="0.0" izz="0.138647916667"/>
    </inertial>
    <visual>
      <origin rpy=" 1.57079632679 0 1.57079632679" xyz="-0.0 0 0.159"/>
      <geometry>
        <mesh filename="package://centaur/meshes/centaur/chest.stl" scale="0.001 0.001 0.001"/>
      </geometry>
      <material name="blue">
        <color rgba="0.2 0.2 0.2 1"/>
      </material>
    </visual>
    <collision>
      <origin rpy="0 0 0" xyz="-0.075 0 0.11"/>
      <geometry>
        <box size="0.24 0.31 0.24"/>
      </geometry>
    </collision>
    <collision>
      <origin rpy="0 0 0" xyz="0.1 0.13 0.12"/>
      <geometry>
        <cylinder length="0.23" radius="0.04"/>
      </geometry>
    </collision>
    <collision>
      <origin rpy="0 0 0" xyz="0.1 -0.13 0.12"/>
      <geometry>
        <cylinder length="0.23" radius="0.04"/>
      </geometry>
    </collision>
  </link>
  <!--Transmissions for gazebo ros control-->
  <transmission name="waist_pan_transmssion">
    <type>transmission_interface/SimpleTransmission</type>
    <joint name="waist_pan">
      <hardwareInterface>EffortJointInterface</hardwareInterface>
    </joint>
    <actuator name="waist_pan_motor">
      <hardwareInterface>EffortJointInterface</hardwareInterface>
      <mechanicalReduction>1</mechanicalReduction>
    </actuator>
  </transmission>
  <gazebo reference="waist_pan">
    <implicitSpringDamper>1</implicitSpringDamper>
  </gazebo>
  <transmission name="waist_tilt_transmssion">
    <type>transmission_interface/SimpleTransmission</type>
    <joint name="waist_tilt">
      <hardwareInterface>EffortJointInterface</hardwareInterface>
    </joint>
    <actuator name="waist_tilt_motor">
      <hardwareInterface>EffortJointInterface</hardwareInterface>
      <mechanicalReduction>1</mechanicalReduction>
    </actuator>
  </transmission>
  <gazebo reference="waist_tilt">
    <implicitSpringDamper>1</implicitSpringDamper>
  </gazebo>
  <!--Coloring for Gazebo-->
  <!--    <gazebo reference="${link_name}">
      <material>Gazebo/White</material>
    </gazebo>-->
  <!--    <gazebo reference="${link_name}">
      <material>Gazebo/White</material>
    </gazebo>-->
  <!--    <gazebo reference="${link_name}">
      <material>Gazebo/White</material>
    </gazebo>-->
  <gazebo>
    <plugin filename="libhector_gazebo_ros_imu.so" name="pelvis_imu_controller">
      <alwaysOn>true</alwaysOn>
      <updateRate>125.0</updateRate>
      <bodyName>pelvis</bodyName>
      <topicName>/thor_mang/pelvis_imu</topicName>
      <accelDrift>0.0 0.0 0.0</accelDrift>
      <accelGaussianNoise>0.1 0.1 0.1</accelGaussianNoise>
      <rateDrift>0.0 0.0 0.0</rateDrift>
      <rateGaussianNoise>0.05 0.05 0.05</rateGaussianNoise>
      <headingDrift>0.0</headingDrift>
      <headingGaussianNoise>0.05</headingGaussianNoise>
    </plugin>
  </gazebo>
  <!--  
  <thor_mang_leg_macro parent="pelvis" name="l" reflect="1" leg_joint3_limit_lower="${-M_PI*0.15}" leg_joint3_limit_upper="${M_PI}">
    <origin xyz="0.0 0.072 -0.145" rpy="0 0 0"/>
  </thor_mang_leg_macro>
  
  <thor_mang_leg_macro parent="pelvis" name="r" reflect="-1" leg_joint3_limit_lower="${-M_PI}" leg_joint3_limit_upper="${M_PI*0.15}">
    <origin xyz="0.0 -0.072 -0.145" rpy="0 0 0"/>
  </thor_mang_leg_macro>
  
  <thor_poking_stick_macro parent="utorso">    
    <origin xyz="0.185 0.130 0.224" rpy="0 ${0 + l_arm_j0_offset} 0"/>
  </thor_poking_stick_macro>
  -->
  <!-- lower3 -M_PI  upper3 M_PI*0.1 -->
  <!-- limit_6 could be -M_PI*1.3 -->
  <joint name="l_shoulder_pitch" type="revolute">
    <origin rpy="0 0.0 0" xyz="0.0 0.234 0.165"/>
    <parent link="utorso"/>
    <child link="l_arm_shoulder_pitch"/>
    <axis xyz="0 1 0"/>
    <limit effort="390.131" lower="-3.14159265359" upper="2.3" velocity="2.5"/>
    <dynamics damping="0.1" friction="0"/>
  </joint>
  <link name="l_arm_shoulder_pitch">
    <!--    
    <xacro:inertial_sphere_with_pose_macro mass="0.3" diameter="0.03">
      <origin xyz="0.0 ${reflect*(arm_link_0_y_offset+0.05)} -0.0" rpy="0 0 0"/>
    </xacro:inertial_sphere_with_pose_macro>
    -->
    <inertial>
      <origin rpy="0 0 0" xyz="0.0 0.0 -0.0"/>
      <mass value="0.3"/>
      <inertia ixx="0.00018" ixy="0.0" ixz="0.0" iyy="0.00045" iyz="0.0" izz="0.00045"/>
    </inertial>
    <visual>
      <origin rpy=" 3.14159265359 1.57079632679 0" xyz="0 -0.051 0"/>
      <geometry>
        <mesh filename="package://centaur/meshes/centaur/shoulder_pitch_left.stl" scale="0.001 0.001 0.001"/>
      </geometry>
      <material name="blue">
        <color rgba="0.2 0.2 0.2 1"/>
      </material>
    </visual>
    <collision>
      <origin rpy="0 0 0" xyz="0 -0.01 0"/>
      <geometry>
        <box size="0.16 0.085 0.06"/>
      </geometry>
    </collision>
  </link>
  <joint name="l_shoulder_roll" type="revolute">
    <origin rpy="0.0 0 0" xyz="0.0 0.0 0"/>
    <parent link="l_arm_shoulder_pitch"/>
    <child link="l_arm_shoulder_roll"/>
    <axis xyz="-1 0 0"/>
    <limit effort="390.131" lower="-3.14159265359" upper="0.05" velocity="2.5"/>
    <dynamics damping="0.1" friction="0"/>
  </joint>
  <link name="l_arm_shoulder_roll">
    <!--      
    <xacro:inertial_sphere_with_pose_macro mass="0.3" diameter="0.03">
      <origin xyz="0.0 0.0 -0.0" rpy="0 0 0"/>
    </xacro:inertial_sphere_with_pose_macro>
    -->
    <inertial>
      <origin rpy="0 0 0" xyz="0.0 0.0 -0.0"/>
      <mass value="0.6"/>
      <inertia ixx="0.00036" ixy="0.0" ixz="0.0" iyy="0.0009" iyz="0.0" izz="0.0009"/>
    </inertial>
    <visual>
      <origin rpy=" 1.57079632679 0 -1.57079632679" xyz="0.024 0 0"/>
      <geometry>
        <mesh filename="package://centaur/meshes/centaur/shoulder_roll_left.stl" scale="0.001 0.001 0.001"/>
      </geometry>
      <material name="blue">
        <color rgba="0.2 0.2 0.2 1"/>
      </material>
    </visual>
    <collision>
      <origin rpy="0 0 0" xyz="0 0 0"/>
      <geometry>
        <box size="0.16 0.06 0.06"/>
      </geometry>
    </collision>
  </link>
  <joint name="l_shoulder_yaw" type="revolute">
    <origin rpy="0 0 0.0" xyz="0 0 0"/>
    <!--rpy="0.000329950722368627 -3.91151844547536E-19 1.16573417585641E-15"-->
    <parent link="l_arm_shoulder_roll"/>
    <child link="l_arm_shoulder_yaw"/>
    <axis xyz="0 0 -1"/>
    <limit effort="390.131" lower="-1.57079632679" upper="3.14159265359" velocity="2.5"/>
    <dynamics damping="0.1" friction="0"/>
  </joint>
  <link name="l_arm_shoulder_yaw">
    <!--
    <xacro:inertial_sphere_with_pose_macro mass="2.89" diameter="0.15">
      <origin xyz="0.0 0.0 ${-0.102+arm_link_2_z_offset}" rpy="0 0 0"/>
    </xacro:inertial_sphere_with_pose_macro>
    -->
    <inertial>
      <origin rpy="0 0 0" xyz="0.0 0.0 -0.129"/>
      <mass value="2.89"/>
      <inertia ixx="0.0115638533333" ixy="0.0" ixz="0.0" iyy="0.0115638533333" iyz="0.0" izz="0.00308266666667"/>
    </inertial>
    <visual>
      <origin rpy=" 1.57079632679 0 -1.57079632679" xyz="0 0 -0.027"/>
      <geometry>
        <mesh filename="package://centaur/meshes/centaur/shoulder_yaw_left.stl" scale="0.001 0.001 0.001"/>
      </geometry>
      <material name="blue">
        <color rgba="0.2 0.2 0.2 1"/>
      </material>
    </visual>
    <collision>
      <origin rpy=" 0 0 0" xyz="0 0 -0.129"/>
      <geometry>
        <box size="0.08 0.08 0.204"/>
      </geometry>
    </collision>
    <collision>
      <origin rpy=" 0 0.785398163397 0" xyz="0.03 0 -0.246"/>
      <geometry>
        <box size="0.06 0.13 0.06"/>
      </geometry>
    </collision>
  </link>
  <joint name="l_elbow" type="revolute">
    <origin rpy="0 0.0 0" xyz="0.03 0 -0.246"/>
    <!--rpy="0.000329950722368627 -3.91151844547536E-19 1.16573417585641E-15"-->
    <parent link="l_arm_shoulder_yaw"/>
    <child link="l_arm_elbow"/>
    <axis xyz="0 1 0"/>
    <limit effort="210.142" lower="-2.9" upper="0.6" velocity="2.5"/>
    <dynamics damping="0.1" friction="0"/>
  </joint>
  <link name="l_arm_elbow">
    <!--    
    <xacro:inertial_sphere_with_pose_macro mass="0.13" diameter="0.05">
      
    </xacro:inertial_sphere_with_pose_macro>
    -->
    <inertial>
      <origin rpy="0 0 0" xyz="0.0 0.0 -0.0"/>
      <mass value="0.13"/>
      <inertia ixx="0.000313083333333" ixy="0.0" ixz="0.0" iyy="0.000108333333333" iyz="0.0" izz="0.00028275"/>
    </inertial>
    <visual>
      <origin rpy=" 1.57079632679 0 -1.57079632679" xyz="-0.03 0 0"/>
      <geometry>
        <mesh filename="package://centaur/meshes/centaur/elbow_left_mod.stl" scale="0.001 0.001 0.001"/>
      </geometry>
      <material name="blue">
        <color rgba="0.2 0.2 0.2 1"/>
      </material>
    </visual>
    <collision>
      <origin rpy=" 0 0 0" xyz="-0.03 0 -0.02"/>
      <geometry>
        <box size="0.06 0.13 0.08"/>
      </geometry>
    </collision>
  </link>
  <joint name="l_wrist_yaw1" type="revolute">
    <origin rpy="0 0 1.57079632679" xyz="-0.030 0 -0.18600"/>
    <!--rpy="0.000329950722368627 -3.91151844547536E-19 1.16573417585641E-15"-->
    <parent link="l_arm_elbow"/>
    <child link="l_arm_wrist_yaw"/>
    <axis xyz="0 0 -1"/>
    <limit effort="50.596" lower="-3.14159265359" upper="4.71" velocity="1.4"/>
    <dynamics damping="0.1" friction="0"/>
  </joint>
  <link name="l_arm_wrist_yaw">
    <!--    
    <xacro:inertial_sphere_with_pose_macro mass="0.81" diameter="0.05">
      <origin xyz="0.0 0.0 -0.0" rpy="0 0 0"/>
    </xacro:inertial_sphere_with_pose_macro>
    -->
    <inertial>
      <origin rpy="0 0 0" xyz="0.0 0.0 0.05"/>
      <mass value="0.81"/>
      <inertia ixx="0.000918" ixy="0.0" ixz="0.0" iyy="0.000918" iyz="0.0" izz="0.000486"/>
    </inertial>
    <visual>
      <origin rpy=" 1.57079632679 0 -1.57079632679" xyz="0 0 0"/>
      <geometry>
        <mesh filename="package://centaur/meshes/centaur/wrist_yaw_left_mod.stl" scale="0.001 0.001 0.001"/>
      </geometry>
      <material name="blue">
        <color rgba="0.2 0.2 0.2 1"/>
      </material>
    </visual>
    <collision>
      <origin rpy="0 0 0" xyz="0 0 0"/>
      <geometry>
        <box size="0.1 0.06 0.06"/>
      </geometry>
    </collision>
    <collision>
      <origin rpy=" 0 0 0" xyz="0 0 0.07"/>
      <geometry>
        <box size="0.06 0.06 0.10"/>
      </geometry>
    </collision>
  </link>
  <joint name="l_wrist_roll" type="revolute">
    <origin rpy="0.0 0 0" xyz="0 0 0"/>
    <!--rpy="0.000329950722368627 -3.91151844547536E-19 1.16573417585641E-15"-->
    <parent link="l_arm_wrist_yaw"/>
    <child link="l_arm_wrist_roll"/>
    <axis xyz="1 0 0"/>
    <limit effort="50.596" lower="-1.47" upper="1.47" velocity="1.4"/>
    <dynamics damping="0.1" friction="0"/>
  </joint>
  <link name="l_arm_wrist_roll">
    <!--
    <xacro:inertial_sphere_with_pose_macro mass="0.27" diameter="0.03">
      <origin xyz="0.0 0.0 -0.03" rpy="0 0 0"/>
    </xacro:inertial_sphere_with_pose_macro>
    -->
    <inertial>
      <origin rpy="0 0 0" xyz="0.0 0.0 -0.07"/>
      <mass value="0.27"/>
      <inertia ixx="0.000306" ixy="0.0" ixz="0.0" iyy="0.000306" iyz="0.0" izz="0.000162"/>
    </inertial>
    <visual>
      <origin rpy=" 1.57079632679 0 -1.57079632679" xyz="0 0 0"/>
      <geometry>
        <mesh filename="package://centaur/meshes/centaur/wrist_roll_left_mod.stl" scale="-0.001 0.001 0.001"/>
      </geometry>
      <material name="blue">
        <color rgba="0.2 0.2 0.2 1"/>
      </material>
    </visual>
    <collision>
      <origin rpy="0 0 0" xyz="0 0 0"/>
      <geometry>
        <box size="0.1 0.06 0.06"/>
      </geometry>
    </collision>
    <collision>
      <origin rpy=" 0 0 0" xyz="0 0 -0.08"/>
      <geometry>
        <box size="0.06 0.06 0.10"/>
      </geometry>
    </collision>
  </link>
  <joint name="l_wrist_yaw2" type="revolute">
    <origin rpy="0 0 0.0" xyz="0 0 0"/>
    <!--rpy="0.000329950722368627 -3.91151844547536E-19 1.16573417585641E-15"-->
    <parent link="l_arm_wrist_roll"/>
    <child link="l_hand"/>
    <axis xyz="0 0 -1"/>
    <limit effort="50.596" lower="-2.54" upper="0.9" velocity="1.4"/>
    <dynamics damping="0.1" friction="0"/>
  </joint>
  <link name="l_hand">
    <!--
    <xacro:inertial_sphere_with_pose_macro mass="0.81" diameter="0.05">
      <origin xyz="0.0 0.0 -0.0" rpy="0 0 0"/>
    </xacro:inertial_sphere_with_pose_macro>
    -->
    <inertial>
      <origin rpy="0 0 0" xyz="0.0 0.0 -0.135"/>
      <mass value="0.13"/>
      <inertia ixx="1.43541666667e-05" ixy="0.0" ixz="0.0" iyy="1.43541666667e-05" iyz="0.0" izz="2.65416666667e-05"/>
    </inertial>
    <visual>
      <origin rpy=" 0 0 0" xyz="0 0 -0.135"/>
      <geometry>
        <box size="0.035 .035 .01"/>
        <!--<mesh
          filename="package://centaur/meshes/centaur/wrist_yaw_left.stl" scale="0.001 0.001 0.001"/>-->
      </geometry>
      <material name="blue">
        <color rgba="0.2 0.2 0.2 1"/>
      </material>
    </visual>
    <collision>
      <origin rpy=" 0 0 0" xyz="0 0 -0.135"/>
      <geometry>
        <box size="0.035 .035 .01"/>
        <!--<mesh
          filename="package://centaur/meshes/centaur/wrist_yaw_left.stl" scale="0.001 0.001 0.001"/>-->
      </geometry>
    </collision>
  </link>
  <!--    <joint name="${name}_hand_joint" type="fixed">
    <origin
      xyz="0 0 -0.135"
      rpy="0 0 0"/>
    <parent
      link="${name}_arm_wrist_yaw2" />
    <child
      link="${name}_hand" />

  </joint>
  
  <link name="${name}_hand">
  </link>
  -->
  <!--Transmissions for gazebo ros control-->
  <transmission name="l_shoulder_pitch_transmssion">
    <type>transmission_interface/SimpleTransmission</type>
    <joint name="l_shoulder_pitch">
      <hardwareInterface>EffortJointInterface</hardwareInterface>
    </joint>
    <actuator name="l_shoulder_pitch_motor">
      <hardwareInterface>EffortJointInterface</hardwareInterface>
      <mechanicalReduction>1</mechanicalReduction>
    </actuator>
  </transmission>
  <gazebo reference="l_shoulder_pitch">
    <implicitSpringDamper>1</implicitSpringDamper>
  </gazebo>
  <transmission name="l_shoulder_roll_transmssion">
    <type>transmission_interface/SimpleTransmission</type>
    <joint name="l_shoulder_roll">
      <hardwareInterface>EffortJointInterface</hardwareInterface>
    </joint>
    <actuator name="l_shoulder_roll_motor">
      <hardwareInterface>EffortJointInterface</hardwareInterface>
      <mechanicalReduction>1</mechanicalReduction>
    </actuator>
  </transmission>
  <gazebo reference="l_shoulder_roll">
    <implicitSpringDamper>1</implicitSpringDamper>
  </gazebo>
  <transmission name="l_shoulder_yaw_transmssion">
    <type>transmission_interface/SimpleTransmission</type>
    <joint name="l_shoulder_yaw">
      <hardwareInterface>EffortJointInterface</hardwareInterface>
    </joint>
    <actuator name="l_shoulder_yaw_motor">
      <hardwareInterface>EffortJointInterface</hardwareInterface>
      <mechanicalReduction>1</mechanicalReduction>
    </actuator>
  </transmission>
  <gazebo reference="l_shoulder_yaw">
    <implicitSpringDamper>1</implicitSpringDamper>
  </gazebo>
  <transmission name="l_elbow_transmssion">
    <type>transmission_interface/SimpleTransmission</type>
    <joint name="l_elbow">
      <hardwareInterface>EffortJointInterface</hardwareInterface>
    </joint>
    <actuator name="l_elbow_motor">
      <hardwareInterface>EffortJointInterface</hardwareInterface>
      <mechanicalReduction>1</mechanicalReduction>
    </actuator>
  </transmission>
  <gazebo reference="l_elbow">
    <implicitSpringDamper>1</implicitSpringDamper>
  </gazebo>
  <transmission name="l_wrist_yaw1_transmssion">
    <type>transmission_interface/SimpleTransmission</type>
    <joint name="l_wrist_yaw1">
      <hardwareInterface>EffortJointInterface</hardwareInterface>
    </joint>
    <actuator name="l_wrist_yaw1_motor">
      <hardwareInterface>EffortJointInterface</hardwareInterface>
      <mechanicalReduction>1</mechanicalReduction>
    </actuator>
  </transmission>
  <gazebo reference="l_wrist_yaw1">
    <implicitSpringDamper>1</implicitSpringDamper>
  </gazebo>
  <transmission name="l_wrist_roll_transmssion">
    <type>transmission_interface/SimpleTransmission</type>
    <joint name="l_wrist_roll">
      <hardwareInterface>EffortJointInterface</hardwareInterface>
    </joint>
    <actuator name="l_wrist_roll_motor">
      <hardwareInterface>EffortJointInterface</hardwareInterface>
      <mechanicalReduction>1</mechanicalReduction>
    </actuator>
  </transmission>
  <gazebo reference="l_wrist_roll">
    <implicitSpringDamper>1</implicitSpringDamper>
  </gazebo>
  <transmission name="l_wrist_yaw2_transmssion">
    <type>transmission_interface/SimpleTransmission</type>
    <joint name="l_wrist_yaw2">
      <hardwareInterface>EffortJointInterface</hardwareInterface>
    </joint>
    <actuator name="l_wrist_yaw2_motor">
      <hardwareInterface>EffortJointInterface</hardwareInterface>
      <mechanicalReduction>1</mechanicalReduction>
    </actuator>
  </transmission>
  <gazebo reference="l_wrist_yaw2">
    <implicitSpringDamper>1</implicitSpringDamper>
  </gazebo>
  <!--Coloring for Gazebo-->
  <!--    <gazebo reference="${link_name}">
      <material>Gazebo/White</material>
    </gazebo>-->
  <!--    <gazebo reference="${link_name}">
      <material>Gazebo/White</material>
    </gazebo>-->
  <!--    <gazebo reference="${link_name}">
      <material>Gazebo/White</material>
    </gazebo>-->
  <!--    <gazebo reference="${link_name}">
      <material>Gazebo/White</material>
    </gazebo>-->
  <!--    <gazebo reference="${link_name}">
      <material>Gazebo/White</material>
    </gazebo>-->
  <!--    <gazebo reference="${link_name}">
      <material>Gazebo/White</material>
    </gazebo>-->
  <joint name="r_shoulder_pitch" type="revolute">
    <origin rpy="0 0.0 0" xyz="0.0 -0.234 0.165"/>
    <parent link="utorso"/>
    <child link="r_arm_shoulder_pitch"/>
    <axis xyz="0 -1 0"/>
    <limit effort="390.131" lower="-2.3" upper="3.14159265359" velocity="2.5"/>
    <dynamics damping="0.1" friction="0"/>
  </joint>
  <link name="r_arm_shoulder_pitch">
    <!--    
    <xacro:inertial_sphere_with_pose_macro mass="0.3" diameter="0.03">
      <origin xyz="0.0 ${reflect*(arm_link_0_y_offset+0.05)} -0.0" rpy="0 0 0"/>
    </xacro:inertial_sphere_with_pose_macro>
    -->
    <inertial>
      <origin rpy="0 0 0" xyz="0.0 0.0 -0.0"/>
      <mass value="0.3"/>
      <inertia ixx="0.00018" ixy="0.0" ixz="0.0" iyy="0.00045" iyz="0.0" izz="0.00045"/>
    </inertial>
    <visual>
      <origin rpy=" 3.14159265359 1.57079632679 0" xyz="0 0.051 0"/>
      <geometry>
        <mesh filename="package://centaur/meshes/centaur/shoulder_pitch_left.stl" scale="0.001 -0.001 0.001"/>
      </geometry>
      <material name="blue">
        <color rgba="0.2 0.2 0.2 1"/>
      </material>
    </visual>
    <collision>
      <origin rpy="0 0 0" xyz="0 0.01 0"/>
      <geometry>
        <box size="0.16 0.085 0.06"/>
      </geometry>
    </collision>
  </link>
  <joint name="r_shoulder_roll" type="revolute">
    <origin rpy="0.0 0 0" xyz="0.0 0.0 0"/>
    <parent link="r_arm_shoulder_pitch"/>
    <child link="r_arm_shoulder_roll"/>
    <axis xyz="-1 0 0"/>
    <limit effort="390.131" lower="-0.05" upper="3.14159265359" velocity="2.5"/>
    <dynamics damping="0.1" friction="0"/>
  </joint>
  <link name="r_arm_shoulder_roll">
    <!--      
    <xacro:inertial_sphere_with_pose_macro mass="0.3" diameter="0.03">
      <origin xyz="0.0 0.0 -0.0" rpy="0 0 0"/>
    </xacro:inertial_sphere_with_pose_macro>
    -->
    <inertial>
      <origin rpy="0 0 0" xyz="0.0 0.0 -0.0"/>
      <mass value="0.6"/>
      <inertia ixx="0.00036" ixy="0.0" ixz="0.0" iyy="0.0009" iyz="0.0" izz="0.0009"/>
    </inertial>
    <visual>
      <origin rpy=" 1.57079632679 0 -1.57079632679" xyz="0.024 0 0"/>
      <geometry>
        <mesh filename="package://centaur/meshes/centaur/shoulder_roll_left.stl" scale="0.001 0.001 0.001"/>
      </geometry>
      <material name="blue">
        <color rgba="0.2 0.2 0.2 1"/>
      </material>
    </visual>
    <collision>
      <origin rpy="0 0 0" xyz="0 0 0"/>
      <geometry>
        <box size="0.16 0.06 0.06"/>
      </geometry>
    </collision>
  </link>
  <joint name="r_shoulder_yaw" type="revolute">
    <origin rpy="0 0 0.0" xyz="0 0 0"/>
    <!--rpy="0.000329950722368627 -3.91151844547536E-19 1.16573417585641E-15"-->
    <parent link="r_arm_shoulder_roll"/>
    <child link="r_arm_shoulder_yaw"/>
    <axis xyz="0 0 -1"/>
    <limit effort="390.131" lower="-3.14159265359" upper="1.57079632679" velocity="2.5"/>
    <dynamics damping="0.1" friction="0"/>
  </joint>
  <link name="r_arm_shoulder_yaw">
    <!--
    <xacro:inertial_sphere_with_pose_macro mass="2.89" diameter="0.15">
      <origin xyz="0.0 0.0 ${-0.102+arm_link_2_z_offset}" rpy="0 0 0"/>
    </xacro:inertial_sphere_with_pose_macro>
    -->
    <inertial>
      <origin rpy="0 0 0" xyz="0.0 0.0 -0.129"/>
      <mass value="2.89"/>
      <inertia ixx="0.0115638533333" ixy="0.0" ixz="0.0" iyy="0.0115638533333" iyz="0.0" izz="0.00308266666667"/>
    </inertial>
    <visual>
      <origin rpy=" 1.57079632679 0 -1.57079632679" xyz="0 0 -0.027"/>
      <geometry>
        <mesh filename="package://centaur/meshes/centaur/shoulder_yaw_left.stl" scale="0.001 0.001 0.001"/>
      </geometry>
      <material name="blue">
        <color rgba="0.2 0.2 0.2 1"/>
      </material>
    </visual>
    <collision>
      <origin rpy=" 0 0 0" xyz="0 0 -0.129"/>
      <geometry>
        <box size="0.08 0.08 0.204"/>
      </geometry>
    </collision>
    <collision>
      <origin rpy=" 0 0.785398163397 0" xyz="0.03 0 -0.246"/>
      <geometry>
        <box size="0.06 0.13 0.06"/>
      </geometry>
    </collision>
  </link>
  <joint name="r_elbow" type="revolute">
    <origin rpy="0 0.0 0" xyz="0.03 0 -0.246"/>
    <!--rpy="0.000329950722368627 -3.91151844547536E-19 1.16573417585641E-15"-->
    <parent link="r_arm_shoulder_yaw"/>
    <child link="r_arm_elbow"/>
    <axis xyz="0 -1 0"/>
    <limit effort="210.142" lower="-0.6" upper="2.9" velocity="2.5"/>
    <dynamics damping="0.1" friction="0"/>
  </joint>
  <link name="r_arm_elbow">
    <!--    
    <xacro:inertial_sphere_with_pose_macro mass="0.13" diameter="0.05">
      
    </xacro:inertial_sphere_with_pose_macro>
    -->
    <inertial>
      <origin rpy="0 0 0" xyz="0.0 0.0 -0.0"/>
      <mass value="0.13"/>
      <inertia ixx="0.000313083333333" ixy="0.0" ixz="0.0" iyy="0.000108333333333" iyz="0.0" izz="0.00028275"/>
    </inertial>
    <visual>
      <origin rpy=" 1.57079632679 0 -1.57079632679" xyz="-0.03 0 0"/>
      <geometry>
        <mesh filename="package://centaur/meshes/centaur/elbow_left_mod.stl" scale="0.001 0.001 0.001"/>
      </geometry>
      <material name="blue">
        <color rgba="0.2 0.2 0.2 1"/>
      </material>
    </visual>
    <collision>
      <origin rpy=" 0 0 0" xyz="-0.03 0 -0.02"/>
      <geometry>
        <box size="0.06 0.13 0.08"/>
      </geometry>
    </collision>
  </link>
  <joint name="r_wrist_yaw1" type="revolute">
    <origin rpy="0 0 -1.57079632679" xyz="-0.030 0 -0.18600"/>
    <!--rpy="0.000329950722368627 -3.91151844547536E-19 1.16573417585641E-15"-->
    <parent link="r_arm_elbow"/>
    <child link="r_arm_wrist_yaw"/>
    <axis xyz="0 0 -1"/>
    <limit effort="50.596" lower="-4.71" upper="3.14159265359" velocity="1.4"/>
    <dynamics damping="0.1" friction="0"/>
  </joint>
  <link name="r_arm_wrist_yaw">
    <!--    
    <xacro:inertial_sphere_with_pose_macro mass="0.81" diameter="0.05">
      <origin xyz="0.0 0.0 -0.0" rpy="0 0 0"/>
    </xacro:inertial_sphere_with_pose_macro>
    -->
    <inertial>
      <origin rpy="0 0 0" xyz="0.0 0.0 0.05"/>
      <mass value="0.81"/>
      <inertia ixx="0.000918" ixy="0.0" ixz="0.0" iyy="0.000918" iyz="0.0" izz="0.000486"/>
    </inertial>
    <visual>
      <origin rpy=" 1.57079632679 0 -1.57079632679" xyz="0 0 0"/>
      <geometry>
        <mesh filename="package://centaur/meshes/centaur/wrist_yaw_left_mod.stl" scale="0.001 0.001 0.001"/>
      </geometry>
      <material name="blue">
        <color rgba="0.2 0.2 0.2 1"/>
      </material>
    </visual>
    <collision>
      <origin rpy="0 0 0" xyz="0 0 0"/>
      <geometry>
        <box size="0.1 0.06 0.06"/>
      </geometry>
    </collision>
    <collision>
      <origin rpy=" 0 0 0" xyz="0 0 0.07"/>
      <geometry>
        <box size="0.06 0.06 0.10"/>
      </geometry>
    </collision>
  </link>
  <joint name="r_wrist_roll" type="revolute">
    <origin rpy="0.0 0 0" xyz="0 0 0"/>
    <!--rpy="0.000329950722368627 -3.91151844547536E-19 1.16573417585641E-15"-->
    <parent link="r_arm_wrist_yaw"/>
    <child link="r_arm_wrist_roll"/>
    <axis xyz="1 0 0"/>
    <limit effort="50.596" lower="-1.47" upper="1.47" velocity="1.4"/>
    <dynamics damping="0.1" friction="0"/>
  </joint>
  <link name="r_arm_wrist_roll">
    <!--
    <xacro:inertial_sphere_with_pose_macro mass="0.27" diameter="0.03">
      <origin xyz="0.0 0.0 -0.03" rpy="0 0 0"/>
    </xacro:inertial_sphere_with_pose_macro>
    -->
    <inertial>
      <origin rpy="0 0 0" xyz="0.0 0.0 -0.07"/>
      <mass value="0.27"/>
      <inertia ixx="0.000306" ixy="0.0" ixz="0.0" iyy="0.000306" iyz="0.0" izz="0.000162"/>
    </inertial>
    <visual>
      <origin rpy=" 1.57079632679 0 -1.57079632679" xyz="0 0 0"/>
      <geometry>
        <mesh filename="package://centaur/meshes/centaur/wrist_roll_left_mod.stl" scale="0.001 0.001 0.001"/>
      </geometry>
      <material name="blue">
        <color rgba="0.2 0.2 0.2 1"/>
      </material>
    </visual>
    <collision>
      <origin rpy="0 0 0" xyz="0 0 0"/>
      <geometry>
        <box size="0.1 0.06 0.06"/>
      </geometry>
    </collision>
    <collision>
      <origin rpy=" 0 0 0" xyz="0 0 -0.08"/>
      <geometry>
        <box size="0.06 0.06 0.10"/>
      </geometry>
    </collision>
  </link>
  <joint name="r_wrist_yaw2" type="revolute">
    <origin rpy="0 0 0.0" xyz="0 0 0"/>
    <!--rpy="0.000329950722368627 -3.91151844547536E-19 1.16573417585641E-15"-->
    <parent link="r_arm_wrist_roll"/>
    <child link="r_hand"/>
    <axis xyz="0 0 -1"/>
    <limit effort="50.596" lower="-0.9" upper="2.54" velocity="1.4"/>
    <dynamics damping="0.1" friction="0"/>
  </joint>
  <link name="r_hand">
    <!--
    <xacro:inertial_sphere_with_pose_macro mass="0.81" diameter="0.05">
      <origin xyz="0.0 0.0 -0.0" rpy="0 0 0"/>
    </xacro:inertial_sphere_with_pose_macro>
    -->
    <inertial>
      <origin rpy="0 0 0" xyz="0.0 0.0 -0.135"/>
      <mass value="0.13"/>
      <inertia ixx="1.43541666667e-05" ixy="0.0" ixz="0.0" iyy="1.43541666667e-05" iyz="0.0" izz="2.65416666667e-05"/>
    </inertial>
    <visual>
      <origin rpy=" 0 0 0" xyz="0 0 -0.135"/>
      <geometry>
        <box size="0.035 .035 .01"/>
        <!--<mesh
          filename="package://centaur/meshes/centaur/wrist_yaw_left.stl" scale="0.001 0.001 0.001"/>-->
      </geometry>
      <material name="blue">
        <color rgba="0.2 0.2 0.2 1"/>
      </material>
    </visual>
    <collision>
      <origin rpy=" 0 0 0" xyz="0 0 -0.135"/>
      <geometry>
        <box size="0.035 .035 .01"/>
        <!--<mesh
          filename="package://centaur/meshes/centaur/wrist_yaw_left.stl" scale="0.001 0.001 0.001"/>-->
      </geometry>
    </collision>
  </link>
  <!--    <joint name="${name}_hand_joint" type="fixed">
    <origin
      xyz="0 0 -0.135"
      rpy="0 0 0"/>
    <parent
      link="${name}_arm_wrist_yaw2" />
    <child
      link="${name}_hand" />

  </joint>
  
  <link name="${name}_hand">
  </link>
  -->
  <!--Transmissions for gazebo ros control-->
  <transmission name="r_shoulder_pitch_transmssion">
    <type>transmission_interface/SimpleTransmission</type>
    <joint name="r_shoulder_pitch">
      <hardwareInterface>EffortJointInterface</hardwareInterface>
    </joint>
    <actuator name="r_shoulder_pitch_motor">
      <hardwareInterface>EffortJointInterface</hardwareInterface>
      <mechanicalReduction>1</mechanicalReduction>
    </actuator>
  </transmission>
  <gazebo reference="r_shoulder_pitch">
    <implicitSpringDamper>1</implicitSpringDamper>
  </gazebo>
  <transmission name="r_shoulder_roll_transmssion">
    <type>transmission_interface/SimpleTransmission</type>
    <joint name="r_shoulder_roll">
      <hardwareInterface>EffortJointInterface</hardwareInterface>
    </joint>
    <actuator name="r_shoulder_roll_motor">
      <hardwareInterface>EffortJointInterface</hardwareInterface>
      <mechanicalReduction>1</mechanicalReduction>
    </actuator>
  </transmission>
  <gazebo reference="r_shoulder_roll">
    <implicitSpringDamper>1</implicitSpringDamper>
  </gazebo>
  <transmission name="r_shoulder_yaw_transmssion">
    <type>transmission_interface/SimpleTransmission</type>
    <joint name="r_shoulder_yaw">
      <hardwareInterface>EffortJointInterface</hardwareInterface>
    </joint>
    <actuator name="r_shoulder_yaw_motor">
      <hardwareInterface>EffortJointInterface</hardwareInterface>
      <mechanicalReduction>1</mechanicalReduction>
    </actuator>
  </transmission>
  <gazebo reference="r_shoulder_yaw">
    <implicitSpringDamper>1</implicitSpringDamper>
  </gazebo>
  <transmission name="r_elbow_transmssion">
    <type>transmission_interface/SimpleTransmission</type>
    <joint name="r_elbow">
      <hardwareInterface>EffortJointInterface</hardwareInterface>
    </joint>
    <actuator name="r_elbow_motor">
      <hardwareInterface>EffortJointInterface</hardwareInterface>
      <mechanicalReduction>1</mechanicalReduction>
    </actuator>
  </transmission>
  <gazebo reference="r_elbow">
    <implicitSpringDamper>1</implicitSpringDamper>
  </gazebo>
  <transmission name="r_wrist_yaw1_transmssion">
    <type>transmission_interface/SimpleTransmission</type>
    <joint name="r_wrist_yaw1">
      <hardwareInterface>EffortJointInterface</hardwareInterface>
    </joint>
    <actuator name="r_wrist_yaw1_motor">
      <hardwareInterface>EffortJointInterface</hardwareInterface>
      <mechanicalReduction>1</mechanicalReduction>
    </actuator>
  </transmission>
  <gazebo reference="r_wrist_yaw1">
    <implicitSpringDamper>1</implicitSpringDamper>
  </gazebo>
  <transmission name="r_wrist_roll_transmssion">
    <type>transmission_interface/SimpleTransmission</type>
    <joint name="r_wrist_roll">
      <hardwareInterface>EffortJointInterface</hardwareInterface>
    </joint>
    <actuator name="r_wrist_roll_motor">
      <hardwareInterface>EffortJointInterface</hardwareInterface>
      <mechanicalReduction>1</mechanicalReduction>
    </actuator>
  </transmission>
  <gazebo reference="r_wrist_roll">
    <implicitSpringDamper>1</implicitSpringDamper>
  </gazebo>
  <transmission name="r_wrist_yaw2_transmssion">
    <type>transmission_interface/SimpleTransmission</type>
    <joint name="r_wrist_yaw2">
      <hardwareInterface>EffortJointInterface</hardwareInterface>
    </joint>
    <actuator name="r_wrist_yaw2_motor">
      <hardwareInterface>EffortJointInterface</hardwareInterface>
      <mechanicalReduction>1</mechanicalReduction>
    </actuator>
  </transmission>
  <gazebo reference="r_wrist_yaw2">
    <implicitSpringDamper>1</implicitSpringDamper>
  </gazebo>
  <!--Coloring for Gazebo-->
  <!--    <gazebo reference="${link_name}">
      <material>Gazebo/White</material>
    </gazebo>-->
  <!--    <gazebo reference="${link_name}">
      <material>Gazebo/White</material>
    </gazebo>-->
  <!--    <gazebo reference="${link_name}">
      <material>Gazebo/White</material>
    </gazebo>-->
  <!--    <gazebo reference="${link_name}">
      <material>Gazebo/White</material>
    </gazebo>-->
  <!--    <gazebo reference="${link_name}">
      <material>Gazebo/White</material>
    </gazebo>-->
  <!--    <gazebo reference="${link_name}">
      <material>Gazebo/White</material>
    </gazebo>-->
  <joint name="head_pan" type="revolute">
    <origin rpy="0 0.0 0" xyz="0.0 0.0 0.320"/>
    <parent link="utorso"/>
    <child link="neck_link"/>
    <axis xyz="0 0 1"/>
    <limit effort="50.596" lower="-1.57079632679" upper="2.45" velocity="1.4"/>
    <dynamics damping="0.1" friction="0"/>
  </joint>
  <link name="neck_link">
    <inertial>
      <origin rpy="0 0 0" xyz="0.0 0.0 0.0"/>
      <mass value="0.1"/>
      <inertia ixx="9e-06" ixy="0.0" ixz="0.0" iyy="9e-06" iyz="0.0" izz="9e-06"/>
    </inertial>
    <visual>
      <origin rpy=" 1.57079632679 0 -1.57079632679" xyz="0 0 -0.111"/>
      <geometry>
        <mesh filename="package://centaur/meshes/centaur/neck.stl" scale="0.001 0.001 0.001"/>
      </geometry>
      <material name="blue">
        <color rgba="0.2 0.2 0.2 1"/>
      </material>
    </visual>
    <collision>
      <origin rpy="0 0 0" xyz="0 0 -0.05"/>
      <geometry>
        <box size="0.045 0.045 0.15"/>
      </geometry>
    </collision>
  </link>
  <gazebo reference="neck_link">
    <audio_sink/>
  </gazebo>
  <joint name="head_tilt" type="revolute">
    <origin rpy="0 0.0 0" xyz="0 0 0"/>
    <parent link="neck_link"/>
    <child link="head_link"/>
    <axis xyz="0 1 0"/>
    <limit effort="50.596" lower="-1.32" upper="0.79" velocity="1.4"/>
    <dynamics damping="0.1" friction="0"/>
  </joint>
  <!--Transmissions for gazebo ros control-->
  <transmission name="head_pan_transmssion">
    <type>transmission_interface/SimpleTransmission</type>
    <joint name="head_pan">
      <hardwareInterface>EffortJointInterface</hardwareInterface>
    </joint>
    <actuator name="head_pan_motor">
      <hardwareInterface>EffortJointInterface</hardwareInterface>
      <mechanicalReduction>1</mechanicalReduction>
    </actuator>
  </transmission>
  <gazebo reference="head_pan">
    <implicitSpringDamper>1</implicitSpringDamper>
  </gazebo>
  <transmission name="head_tilt_transmssion">
    <type>transmission_interface/SimpleTransmission</type>
    <joint name="head_tilt">
      <hardwareInterface>EffortJointInterface</hardwareInterface>
    </joint>
    <actuator name="head_tilt_motor">
      <hardwareInterface>EffortJointInterface</hardwareInterface>
      <mechanicalReduction>1</mechanicalReduction>
    </actuator>
  </transmission>
  <gazebo reference="head_tilt">
    <implicitSpringDamper>1</implicitSpringDamper>
  </gazebo>
  <!--Coloring for Gazebo-->
  <!--    <gazebo reference="${link_name}">
      <material>Gazebo/White</material>
    </gazebo>-->
  <link name="head_link">
    <inertial>
      <mass value="0.8"/>
      <inertia ixx="0.0025" ixy="0.0" ixz="0.0001" iyy="0.0013" iyz="0.0" izz="0.0026"/>
    </inertial>
    <collision name="collision">
      <origin rpy="1.57079632679 0.0 1.57079632679" xyz="0.0 0.0 -0.006"/>
      <geometry>
        <mesh filename="package://centaur/meshes/centaur/multisensor_head_collision.stl" scale="0.001 0.001 0.001"/>
      </geometry>
    </collision>
    <visual>
      <origin rpy="1.57079632679 0.0 1.57079632679" xyz="0.0 0.0 -0.006"/>
      <geometry>
        <mesh filename="package://centaur/meshes/centaur/multisensor_head.stl" scale="0.001 0.001 0.001"/>
      </geometry>
    </visual>
  </link>
  <joint name="head_lidar_spinning_joint" type="continuous">
    <origin rpy="0 0 0" xyz="0.061 0.0 0.134"/>
    <parent link="head_link"/>
    <child link="head_lidar_mount_link"/>
    <axis rpy="0 0 0" xyz="1 0 0"/>
    <limit effort="1000" velocity="100"/>
    <joint_properties damping="500.0" friction="200.0"/>
  </joint>
  <link name="head_lidar_mount_link">
    <inertial>
      <origin rpy="0 0 0" xyz="0.0 0.0 0.0"/>
      <mass value="0.1"/>
      <inertia ixx="9e-06" ixy="0.0" ixz="0.0" iyy="9e-06" iyz="0.0" izz="9e-06"/>
    </inertial>
  </link>
  <joint name="head_link_hokuyo_laser_joint" type="fixed">
    <origin rpy="0.0 0.021197 -0.00357142" xyz="0.0 0.000323461 0.0127965"/>
    <parent link="head_lidar_mount_link"/>
    <child link="head_link_hokuyo_laser_frame"/>
  </joint>
  <link name="head_link_hokuyo_laser_frame">
    <inertial>
      <mass value="0.270"/>
      <origin rpy="0 0 0" xyz="0 0 0"/>
      <inertia ixx="2.632e-4" ixy="0" ixz="0" iyy="2.632e-4" iyz="0" izz="1.62e-4"/>
    </inertial>
    <visual>
      <origin rpy="0 0 0" xyz="0 0 0"/>
      <geometry>
        <mesh filename="package://centaur/meshes/centaur/hokuyo_utm_30lx.dae"/>
      </geometry>
    </visual>
    <collision>
      <origin rpy="0 0 0" xyz="0 0 -0.0115"/>
      <geometry>
        <box size="0.058 0.058 0.087"/>
        <!--<mesh filename="package://centaur/meshes/centaur/hokuyo_utm_30lx.stl"/>-->
      </geometry>
    </collision>
  </link>
  <gazebo reference="head_link_hokuyo_laser_frame">
    <sensor name="head_link_hokuyo_laser" type="ray">
      <always_on>true</always_on>
      <update_rate>40</update_rate>
      <pose>0 0 0 0 0 0</pose>
      <visualize>false</visualize>
      <ray>
        <scan>
          <horizontal>
            <samples>1040</samples>
            <resolution>1</resolution>
            <min_angle>2.26892802759</min_angle>
            <max_angle>-2.26892802759</max_angle>
          </horizontal>
        </scan>
        <range>
          <min>0.2</min>
          <max>30.0</max>
          <resolution>0.01</resolution>
        </range>
        <noise>
          <type>gaussian</type>
          <mean>0.0</mean>
          <stddev>0.004</stddev>
        </noise>
      </ray>
      <plugin filename="libgazebo_ros_laser.so" name="gazebo_ros_head_link_hokuyo_laser_controller">
        <topicName>/head_lidar/scan</topicName>
        <frameName>head_link_hokuyo_laser_frame</frameName>
      </plugin>
    </sensor>
  </gazebo>
  <transmission name="head_lidar_spinning_joint_transmission">
    <type>transmission_interface/SimpleTransmission</type>
    <joint name="head_lidar_spinning_joint">
      <hardwareInterface>EffortJointInterface</hardwareInterface>
    </joint>
    <actuator name="head_lidar_spinning_joint_motor">
      <hardwareInterface>EffortJointInterface</hardwareInterface>
      <mechanicalReduction>1</mechanicalReduction>
    </actuator>
  </transmission>
  <gazebo reference="head_lidar_spinning_joint">
    <implicitSpringDamper>1</implicitSpringDamper>
  </gazebo>
  <joint name="head_cam_joint" type="fixed">
    <origin rpy="0 0 0" xyz="0.065 0.0 0.23"/>
    <parent link="head_link"/>
    <child link="head_cam_link"/>
  </joint>
  <link name="head_cam_link">
    <inertial>
      <mass value="0.200"/>
      <origin rpy="0 0 0" xyz="0 0 0"/>
      <inertia ixx="5.8083e-4" ixy="0" ixz="0" iyy="3.0833e-5" iyz="0" izz="5.9083e-4"/>
    </inertial>
    <visual>
      <origin rpy="0 0 0" xyz="0 0 0"/>
      <geometry>
        <mesh filename="package://centaur/meshes/centaur/asus_camera_simple.dae"/>
      </geometry>
    </visual>
    <!--        
       <collision>
          <origin xyz="0 0 0" rpy="0 0 0" />
          <geometry>
            <box size="0.035 0.185 0.025"/>
          </geometry>
        </collision>
        -->
    <collision>
      <origin rpy="0 0 0" xyz="0 0 0"/>
      <geometry>
        <mesh filename="package://centaur/meshes/centaur/asus_camera_simple.dae"/>
      </geometry>
    </collision>
  </link>
  <joint name="head_cam_depth_joint" type="fixed">
    <origin rpy="0 0 0" xyz="0.0 0.049 0.0"/>
    <parent link="head_cam_link"/>
    <child link="head_cam_depth_frame"/>
  </joint>
  <link name="head_cam_depth_frame"/>
  <joint name="head_cam_depth_optical_joint" type="fixed">
    <origin rpy="-1.57079632679 0.0 -1.57079632679" xyz="0 0 0"/>
    <parent link="head_cam_depth_frame"/>
    <child link="head_cam_depth_optical_frame"/>
  </joint>
  <link name="head_cam_depth_optical_frame"/>
  <joint name="head_cam_rgb_joint" type="fixed">
    <origin rpy="0 0 0" xyz="0.0 0.022 0.0"/>
    <parent link="head_cam_link"/>
    <child link="head_cam_rgb_frame"/>
  </joint>
  <link name="head_cam_rgb_frame"/>
  <joint name="head_cam_rgb_optical_joint" type="fixed">
    <origin rpy="-1.57079632679 0.0 -1.57079632679" xyz="0 0 0"/>
    <parent link="head_cam_rgb_frame"/>
    <child link="head_cam_rgb_optical_frame"/>
  </joint>
  <link name="head_cam_rgb_optical_frame"/>
  <!-- ASUS Xtion PRO camera for simulation -->
  <gazebo reference="head_cam_depth_frame">
    <sensor name="head_cam" type="depth">
      <update_rate>20</update_rate>
      <camera>
        <horizontal_fov>1.09606677025</horizontal_fov>
        <image>
          <format>R8G8B8</format>
          <width>640</width>
          <height>480</height>
        </image>
        <clip>
          <near>0.5</near>
          <far>9</far>
        </clip>
      </camera>
      <plugin filename="libgazebo_ros_openni_kinect.so" name="head_cam_camera_controller">
        <imageTopicName>head_cam/rgb/image_raw</imageTopicName>
        <cameraInfoTopicName>head_cam/rgb/camera_info</cameraInfoTopicName>
        <depthImageTopicName>head_cam/depth/image_raw</depthImageTopicName>
        <depthImageCameraInfoTopicName>head_cam/depth/camera_info</depthImageCameraInfoTopicName>
        <pointCloudTopicName>head_cam/depth/points</pointCloudTopicName>
        <frameName>head_cam_depth_optical_frame</frameName>
      </plugin>
    </sensor>
  </gazebo>
  <!-- <gazebo reference="${name}_spinning_lidar_root_link"><material>Gazebo/Grey</material></gazebo><gazebo reference="${name}_spinning_lidar_spin_link"><material>Gazebo/Grey</material></gazebo> -->
  <!--  
  <thor_lidar_pan_unit_macro parent="utorso" name="waist">
    <origin xyz="0.05 0.0 0.08" rpy="0 0 0"/>
  </thor_lidar_pan_unit_macro>
  -->
  <!--<xacro:include filename="$(find thor_vt_hand_description)/urdf/vt_finger_tud.urdf.xacro"/>-->
  <!--<xacro:include filename="$(find thor_mang_description)/urdf/joint_params.xacro" />-->
  <!-- Increased effort limit by x10 for gazebo -->
  <!-- unit conversions -->
  <!-- inventor sometimes gives ridiculous units -->
  <!-- such conversion factors make description easier to read -->
  <!-- colors -->
  <!-- colors -->
  <!--<xacro:include filename="$(find thor_mang_description)/urdf/joint_params.xacro" />-->
  <!-- Increased effort limit by x10 for gazebo -->
  <!-- link list -->
  <link name="l_f1_link_0">
    <visual>
      <origin rpy="0 0 0" xyz="0 0 0"/>
      <geometry>
        <mesh filename="package://centaur/meshes/centaur/l_f1_link_0.stl"/>
      </geometry>
      <material name="green">
        <color rgba="0 1 0 1"/>
      </material>
    </visual>
    <visual>
      <origin rpy="0.4 0 0" xyz="0 -0.00407 0.04983"/>
      <geometry>
        <mesh filename="package://centaur/meshes/centaur/l_f1_link_1.stl"/>
      </geometry>
      <material name="green"/>
    </visual>
    <collision>
      <origin rpy="0 1.57079632679 0" xyz="0 0 0"/>
      <geometry>
        <cylinder length="0.02" radius="0.017"/>
      </geometry>
      <material name="yellow">
        <color rgba="0 1 1 1"/>
      </material>
    </collision>
    <collision>
      <origin rpy="0 0 0" xyz="0 0 0.02"/>
      <geometry>
        <cylinder length="0.04" radius="0.008"/>
      </geometry>
      <material name="yellow"/>
    </collision>
    <collision>
      <origin rpy="0 1.57079632679 0" xyz="0 -0.00407 0.042"/>
      <geometry>
        <cylinder length="0.02" radius="0.014"/>
      </geometry>
      <material name="yellow">
        <color rgba="0 1 1 1"/>
      </material>
    </collision>
    <collision>
      <!--<origin xyz="0 -0.00407 0.04983" rpy="0.4 0 0"/>-->
      <origin rpy="0.4 0 0" xyz="0.001 -0.00207 0.06783 "/>
      <geometry>
        <cylinder length="0.05" radius="0.008"/>
      </geometry>
      <material name="yellow"/>
    </collision>
    <!-- WARNING: INERTIA NOT CORRECT -->
    <inertial>
      <origin rpy="0 0 0" xyz="0.0002 0.92e-03 21.11e-03"/>
      <mass value="0.1"/>
      <inertia ixx="21.39e-06" ixy="-3.9e-07" ixz="7.1e-07" iyy="18.98e-06" iyz="-1.36e-06" izz="4.73e-06"/>
    </inertial>
  </link>
  <gazebo reference="l_f1_link_0">
    <mu1>1.1</mu1>
    <mu2>1.1</mu2>
    <kp>1000000.0</kp>
    <kd>10.0</kd>
    <maxVel>0.1</maxVel>
    <minDepth>0.00</minDepth>
    <maxContacts>1</maxContacts>
  </gazebo>
  <!--    <link name="${prefix}_link_1">
      <visual>
        <origin xyz="0 0 0" rpy="0 0 0"/>
        <geometry>
          <mesh filename="package://centaur/meshes/centaur/${prefix}_link_1.stl"/>
        </geometry>
        <material name="green"/>
      </visual>
      <collision>
        <origin xyz="-0.002 0.007 0.018" rpy="0 0 0"/>
        <geometry>
          <cylinder length="0.05" radius="0.008"/>
        </geometry>
        <material name="yellow"/>
      </collision>
    </link>-->
  <!--    <gazebo reference="${prefix}_link_1">
      <mu1>1.1</mu1>
      <mu2>1.1</mu2>
      <kp>1000000.0</kp>
      <kd>10.0</kd>
      <maxVel>0.1</maxVel>
      <minDepth>0.00</minDepth>
      <maxContacts>1</maxContacts>

    </gazebo>-->
  <!-- end of link list -->
  <!-- joint list -->
  <!-- WARNING: UPPER LIMIT NOT CORRECT/IGNORED WHILE USING MIMIC JOINT TYPE -->
  <!--		
                <joint name="${prefix}_j1" type="revolute">
                        <parent link="${prefix}_link_0"/>
                        <child link="${prefix}_link_1"/>
                        <axis xyz="1 0 0"/>
                        <origin xyz="0 -0.00407 0.04983" rpy="0.4 0 0"/>
                        <limit lower="0" upper="0.8" effort="100" velocity="100"/>
                        <mimic joint="${prefix}_j0" multiplier="0.4" offset="0"/>
                </joint>
                -->
  <!--   
    <joint name="${prefix}_j1" type="fixed">
      <parent link="${prefix}_link_0"/>
      <child link="${prefix}_link_1"/>
      <axis xyz="1 0 0"/>
      <origin xyz="0 -0.00407 0.04983" rpy="0.4 0 0"/>
      <limit lower="0" upper="0.8" effort="100" velocity="100"/>
    </joint>
    -->
  <!-- end of joint list -->
  <!-- link list -->
  <link name="l_f0_link_0">
    <visual>
      <origin rpy="0 0 0" xyz="0 0 0"/>
      <geometry>
        <mesh filename="package://centaur/meshes/centaur/l_f0_link_0.stl"/>
      </geometry>
      <material name="green">
        <color rgba="0 1 0 1"/>
      </material>
    </visual>
    <visual>
      <origin rpy="0.4 0 0" xyz="0 -0.00407 0.04983"/>
      <geometry>
        <mesh filename="package://centaur/meshes/centaur/l_f0_link_1.stl"/>
      </geometry>
      <material name="green"/>
    </visual>
    <collision>
      <origin rpy="0 1.57079632679 0" xyz="0 0 0"/>
      <geometry>
        <cylinder length="0.02" radius="0.017"/>
      </geometry>
      <material name="yellow">
        <color rgba="0 1 1 1"/>
      </material>
    </collision>
    <collision>
      <origin rpy="0 0 0" xyz="0 0 0.02"/>
      <geometry>
        <cylinder length="0.04" radius="0.008"/>
      </geometry>
      <material name="yellow"/>
    </collision>
    <collision>
      <origin rpy="0 1.57079632679 0" xyz="0 -0.00407 0.042"/>
      <geometry>
        <cylinder length="0.02" radius="0.014"/>
      </geometry>
      <material name="yellow">
        <color rgba="0 1 1 1"/>
      </material>
    </collision>
    <collision>
      <!--<origin xyz="0 -0.00407 0.04983" rpy="0.4 0 0"/>-->
      <origin rpy="0.4 0 0" xyz="0.001 -0.00207 0.06783 "/>
      <geometry>
        <cylinder length="0.05" radius="0.008"/>
      </geometry>
      <material name="yellow"/>
    </collision>
    <!-- WARNING: INERTIA NOT CORRECT -->
    <inertial>
      <origin rpy="0 0 0" xyz="-0.0002 0.92e-03 21.11e-03"/>
      <mass value="0.1"/>
      <inertia ixx="21.39e-06" ixy="3.9e-07" ixz="-7.1e-07" iyy="18.98e-06" iyz="-1.36e-06" izz="4.73e-06"/>
    </inertial>
  </link>
  <gazebo reference="l_f0_link_0">
    <mu1>1.1</mu1>
    <mu2>1.1</mu2>
    <kp>1000000.0</kp>
    <kd>10.0</kd>
    <maxVel>0.1</maxVel>
    <minDepth>0.00</minDepth>
    <maxContacts>1</maxContacts>
  </gazebo>
  <!--    <link name="${prefix}_link_1">
      <visual>
        <origin xyz="0 0 0" rpy="0 0 0"/>
        <geometry>
          <mesh filename="package://centaur/meshes/centaur/${prefix}_link_1.stl"/>
        </geometry>
        <material name="green"/>
      </visual>
      <collision>
        <origin xyz="-0.002 0.007 0.018" rpy="0 0 0"/>
        <geometry>
          <cylinder length="0.05" radius="0.008"/>
        </geometry>
        <material name="yellow"/>
      </collision>
    </link>-->
  <!--    <gazebo reference="${prefix}_link_1">
      <mu1>1.1</mu1>
      <mu2>1.1</mu2>
      <kp>1000000.0</kp>
      <kd>10.0</kd>
      <maxVel>0.1</maxVel>
      <minDepth>0.00</minDepth>
      <maxContacts>1</maxContacts>

    </gazebo>-->
  <!-- end of link list -->
  <!-- joint list -->
  <!-- WARNING: UPPER LIMIT NOT CORRECT/IGNORED WHILE USING MIMIC JOINT TYPE -->
  <!--		
                <joint name="${prefix}_j1" type="revolute">
                        <parent link="${prefix}_link_0"/>
                        <child link="${prefix}_link_1"/>
                        <axis xyz="1 0 0"/>
                        <origin xyz="0 -0.00407 0.04983" rpy="0.4 0 0"/>
                        <limit lower="0" upper="0.8" effort="100" velocity="100"/>
                        <mimic joint="${prefix}_j0" multiplier="0.4" offset="0"/>
                </joint>
                -->
  <!--   
    <joint name="${prefix}_j1" type="fixed">
      <parent link="${prefix}_link_0"/>
      <child link="${prefix}_link_1"/>
      <axis xyz="1 0 0"/>
      <origin xyz="0 -0.00407 0.04983" rpy="0.4 0 0"/>
      <limit lower="0" upper="0.8" effort="100" velocity="100"/>
    </joint>
    -->
  <!-- end of joint list -->
  <joint name="l_vt_hand_joint" type="fixed">
    <origin rpy="3.141592 0 1.570796" xyz="0 0 -0.16"/>
    <parent link="l_hand"/>
    <child link="l_palm"/>
  </joint>
  <!-- link list -->
  <link name="l_palm">
    <!--
      <collision name="collision_aaa">
        <geometry>
          <mesh filename="package://centaur/meshes/centaur/${prefix}_palm.stl"/>
        </geometry>
      </collision>
      <visual>
        <geometry>
          <mesh filename="package://centaur/meshes/centaur/${prefix}_palm.stl"/>
        </geometry>
        <material name="green">
          <color rgba="0 1 0 1"/>
        </material>
      </visual>
-->
    <visual>
      <origin rpy="0 0 0" xyz="0 0 0"/>
      <geometry>
        <mesh filename="package://centaur/meshes/centaur/l_palm.stl"/>
      </geometry>
      <material name="green">
        <color rgba="0 1 0 1"/>
      </material>
    </visual>
    <collision>
      <origin rpy="0 0 0" xyz="0 0 0"/>
      <geometry>
        <mesh filename="package://centaur/meshes/centaur/l_palm.stl"/>
      </geometry>
      <material name="yellow">
        <color rgba="0 1 1 1"/>
      </material>
    </collision>
    <!-- WARNING: INERTIA NOT CORRECT -->
    <inertial>
      <origin rpy="0 0 0" xyz="-0.00344 6.49e-03 42.12e-03"/>
      <mass value="0.7"/>
      <inertia ixx="0.1e-04" ixy="0" ixz="0" iyy="0.07e-04" iyz="0" izz="0.1e-04"/>
    </inertial>
  </link>
  <gazebo reference="l_palm">
    <sensor name="l_HT_contact" type="contact">
      <plugin filename="libcontactHT.so" name="l_HT_plugin"/>
      <contact>
        <collision>r_hand_fixed_joint_lump__r_palm_collision_1</collision>
        <collision>l_hand_fixed_joint_lump__l_palm_collision_1</collision>
      </contact>
    </sensor>
    <!--
      <audio_source>
        <uri>file://media/audio/Hammering_normal.wav</uri>
        <pitch>2.0</pitch>
        <gain>1.0</gain>
        <loop>false</loop>
        <contact>
          <collision>r_hand_fixed_joint_lump__r_palm_collision_1</collision>
          <collision>l_hand_fixed_joint_lump__l_palm_collision_1</collision>
        </contact>
      </audio_source>
-->
  </gazebo>
  <gazebo reference="l_palm">
    <mu1>1.1</mu1>
    <mu2>1.1</mu2>
    <kp>1000000.0</kp>
    <kd>1.0</kd>
    <maxVel>0.1</maxVel>
    <minDepth>0.00</minDepth>
    <maxContacts>6</maxContacts>
    <!--<material>Gazebo/FlatBlack</material>-->
  </gazebo>
  <!-- end of link list -->
  <!-- joint list -->
  <joint name="l_f1_j0" type="revolute">
    <parent link="l_palm"/>
    <child link="l_f1_link_0"/>
    <axis xyz="1 0 0"/>
    <origin rpy="-1.315 0 0" xyz="-0.036 0.0361 0.0596"/>
    <limit effort="10" lower="0" upper="2.685" velocity="10"/>
    <!--<dynamics damping="0.1"/>-->
  </joint>
  <joint name="l_f0_j0" type="revolute">
    <parent link="l_palm"/>
    <child link="l_f0_link_0"/>
    <axis xyz="1 0 0"/>
    <origin rpy="-1.315 0 0" xyz="0.0355 0.0361 0.0596"/>
    <limit effort="10" lower="0" upper="2.685" velocity="10"/>
    <!--<dynamics damping="0.1"/>-->
  </joint>
  <!-- end of joint list -->
  <!--<gazebo>
        <plugin name="THOR_VT_HandPlugin" filename="libTHOR_VT_HandPlugin.so">
		<prefix>${prefix}</prefix>
        </plugin>

        <kp>1000000.0</kp>
    	<kd>100.0</kd>
   	<mu1>1.5</mu1>
    	<mu2>1.5</mu2>
    	<fdir1>1 0 0</fdir1>
    	<maxVel>1.0</maxVel>
        <minDepth>0.00</minDepth>
        <implicitSpringDamper>1</implicitSpringDamper>
	</gazebo>-->
  <!--Transmissions for gazebo ros control-->
  <transmission name="l_f0_j0_transmssion">
    <type>transmission_interface/SimpleTransmission</type>
    <joint name="l_f0_j0">
      <hardwareInterface>EffortJointInterface</hardwareInterface>
    </joint>
    <actuator name="l_f0_j0_motor">
      <hardwareInterface>EffortJointInterface</hardwareInterface>
      <mechanicalReduction>1</mechanicalReduction>
    </actuator>
  </transmission>
  <gazebo reference="l_f0_j0">
    <implicitSpringDamper>1</implicitSpringDamper>
  </gazebo>
  <transmission name="l_f1_j0_transmssion">
    <type>transmission_interface/SimpleTransmission</type>
    <joint name="l_f1_j0">
      <hardwareInterface>EffortJointInterface</hardwareInterface>
    </joint>
    <actuator name="l_f1_j0_motor">
      <hardwareInterface>EffortJointInterface</hardwareInterface>
      <mechanicalReduction>1</mechanicalReduction>
    </actuator>
  </transmission>
  <gazebo reference="l_f1_j0">
    <implicitSpringDamper>1</implicitSpringDamper>
  </gazebo>
  <!--gazebo>
    <plugin name="gazebo_ros_control" filename="libgazebo_ros_control.so">
      <robotNamespace>thor_mang</robotNamespace>
      <robotSimType>gazebo_ros_control/VT_Hand_HWSim</robotSimType>
    </plugin>
  </gazebo-->
  <!--<xacro:include filename="$(find thor_vt_hand_description)/urdf/vt_finger_tud.urdf.xacro"/>-->
  <!--<xacro:include filename="$(find thor_mang_description)/urdf/joint_params.xacro" />-->
  <!-- Increased effort limit by x10 for gazebo -->
  <!-- unit conversions -->
  <!-- inventor sometimes gives ridiculous units -->
  <!-- such conversion factors make description easier to read -->
  <!-- colors -->
  <!-- colors -->
  <!--<xacro:include filename="$(find thor_mang_description)/urdf/joint_params.xacro" />-->
  <!-- Increased effort limit by x10 for gazebo -->
  <!-- link list -->
  <link name="r_f1_link_0">
    <visual>
      <origin rpy="0 0 0" xyz="0 0 0"/>
      <geometry>
        <mesh filename="package://centaur/meshes/centaur/r_f1_link_0.stl"/>
      </geometry>
      <material name="green">
        <color rgba="0 1 0 1"/>
      </material>
    </visual>
    <visual>
      <origin rpy="0.4 0 0" xyz="0 -0.00407 0.04983"/>
      <geometry>
        <mesh filename="package://centaur/meshes/centaur/r_f1_link_1.stl"/>
      </geometry>
      <material name="green"/>
    </visual>
    <collision>
      <origin rpy="0 1.57079632679 0" xyz="0 0 0"/>
      <geometry>
        <cylinder length="0.02" radius="0.017"/>
      </geometry>
      <material name="yellow">
        <color rgba="0 1 1 1"/>
      </material>
    </collision>
    <collision>
      <origin rpy="0 0 0" xyz="0 0 0.02"/>
      <geometry>
        <cylinder length="0.04" radius="0.008"/>
      </geometry>
      <material name="yellow"/>
    </collision>
    <collision>
      <origin rpy="0 1.57079632679 0" xyz="0 -0.00407 0.042"/>
      <geometry>
        <cylinder length="0.02" radius="0.014"/>
      </geometry>
      <material name="yellow">
        <color rgba="0 1 1 1"/>
      </material>
    </collision>
    <collision>
      <!--<origin xyz="0 -0.00407 0.04983" rpy="0.4 0 0"/>-->
      <origin rpy="0.4 0 0" xyz="0.001 -0.00207 0.06783 "/>
      <geometry>
        <cylinder length="0.05" radius="0.008"/>
      </geometry>
      <material name="yellow"/>
    </collision>
    <!-- WARNING: INERTIA NOT CORRECT -->
    <inertial>
      <origin rpy="0 0 0" xyz="-0.0002 0.92e-03 21.11e-03"/>
      <mass value="0.1"/>
      <inertia ixx="21.39e-06" ixy="3.9e-07" ixz="-7.1e-07" iyy="18.98e-06" iyz="-1.36e-06" izz="4.73e-06"/>
    </inertial>
  </link>
  <gazebo reference="r_f1_link_0">
    <mu1>1.1</mu1>
    <mu2>1.1</mu2>
    <kp>1000000.0</kp>
    <kd>10.0</kd>
    <maxVel>0.1</maxVel>
    <minDepth>0.00</minDepth>
    <maxContacts>1</maxContacts>
  </gazebo>
  <!--    <link name="${prefix}_link_1">
      <visual>
        <origin xyz="0 0 0" rpy="0 0 0"/>
        <geometry>
          <mesh filename="package://centaur/meshes/centaur/${prefix}_link_1.stl"/>
        </geometry>
        <material name="green"/>
      </visual>
      <collision>
        <origin xyz="-0.002 0.007 0.018" rpy="0 0 0"/>
        <geometry>
          <cylinder length="0.05" radius="0.008"/>
        </geometry>
        <material name="yellow"/>
      </collision>
    </link>-->
  <!--    <gazebo reference="${prefix}_link_1">
      <mu1>1.1</mu1>
      <mu2>1.1</mu2>
      <kp>1000000.0</kp>
      <kd>10.0</kd>
      <maxVel>0.1</maxVel>
      <minDepth>0.00</minDepth>
      <maxContacts>1</maxContacts>

    </gazebo>-->
  <!-- end of link list -->
  <!-- joint list -->
  <!-- WARNING: UPPER LIMIT NOT CORRECT/IGNORED WHILE USING MIMIC JOINT TYPE -->
  <!--		
                <joint name="${prefix}_j1" type="revolute">
                        <parent link="${prefix}_link_0"/>
                        <child link="${prefix}_link_1"/>
                        <axis xyz="1 0 0"/>
                        <origin xyz="0 -0.00407 0.04983" rpy="0.4 0 0"/>
                        <limit lower="0" upper="0.8" effort="100" velocity="100"/>
                        <mimic joint="${prefix}_j0" multiplier="0.4" offset="0"/>
                </joint>
                -->
  <!--   
    <joint name="${prefix}_j1" type="fixed">
      <parent link="${prefix}_link_0"/>
      <child link="${prefix}_link_1"/>
      <axis xyz="1 0 0"/>
      <origin xyz="0 -0.00407 0.04983" rpy="0.4 0 0"/>
      <limit lower="0" upper="0.8" effort="100" velocity="100"/>
    </joint>
    -->
  <!-- end of joint list -->
  <!-- link list -->
  <link name="r_f0_link_0">
    <visual>
      <origin rpy="0 0 0" xyz="0 0 0"/>
      <geometry>
        <mesh filename="package://centaur/meshes/centaur/r_f0_link_0.stl"/>
      </geometry>
      <material name="green">
        <color rgba="0 1 0 1"/>
      </material>
    </visual>
    <visual>
      <origin rpy="0.4 0 0" xyz="0 -0.00407 0.04983"/>
      <geometry>
        <mesh filename="package://centaur/meshes/centaur/r_f0_link_1.stl"/>
      </geometry>
      <material name="green"/>
    </visual>
    <collision>
      <origin rpy="0 1.57079632679 0" xyz="0 0 0"/>
      <geometry>
        <cylinder length="0.02" radius="0.017"/>
      </geometry>
      <material name="yellow">
        <color rgba="0 1 1 1"/>
      </material>
    </collision>
    <collision>
      <origin rpy="0 0 0" xyz="0 0 0.02"/>
      <geometry>
        <cylinder length="0.04" radius="0.008"/>
      </geometry>
      <material name="yellow"/>
    </collision>
    <collision>
      <origin rpy="0 1.57079632679 0" xyz="0 -0.00407 0.042"/>
      <geometry>
        <cylinder length="0.02" radius="0.014"/>
      </geometry>
      <material name="yellow">
        <color rgba="0 1 1 1"/>
      </material>
    </collision>
    <collision>
      <!--<origin xyz="0 -0.00407 0.04983" rpy="0.4 0 0"/>-->
      <origin rpy="0.4 0 0" xyz="0.001 -0.00207 0.06783 "/>
      <geometry>
        <cylinder length="0.05" radius="0.008"/>
      </geometry>
      <material name="yellow"/>
    </collision>
    <!-- WARNING: INERTIA NOT CORRECT -->
    <inertial>
      <origin rpy="0 0 0" xyz="0.0002 0.92e-03 21.11e-03"/>
      <mass value="0.1"/>
      <inertia ixx="21.39e-06" ixy="-3.9e-07" ixz="7.1e-07" iyy="18.98e-06" iyz="-1.36e-06" izz="4.73e-06"/>
    </inertial>
  </link>
  <gazebo reference="r_f0_link_0">
    <mu1>1.1</mu1>
    <mu2>1.1</mu2>
    <kp>1000000.0</kp>
    <kd>10.0</kd>
    <maxVel>0.1</maxVel>
    <minDepth>0.00</minDepth>
    <maxContacts>1</maxContacts>
  </gazebo>
  <!--    <link name="${prefix}_link_1">
      <visual>
        <origin xyz="0 0 0" rpy="0 0 0"/>
        <geometry>
          <mesh filename="package://centaur/meshes/centaur/${prefix}_link_1.stl"/>
        </geometry>
        <material name="green"/>
      </visual>
      <collision>
        <origin xyz="-0.002 0.007 0.018" rpy="0 0 0"/>
        <geometry>
          <cylinder length="0.05" radius="0.008"/>
        </geometry>
        <material name="yellow"/>
      </collision>
    </link>-->
  <!--    <gazebo reference="${prefix}_link_1">
      <mu1>1.1</mu1>
      <mu2>1.1</mu2>
      <kp>1000000.0</kp>
      <kd>10.0</kd>
      <maxVel>0.1</maxVel>
      <minDepth>0.00</minDepth>
      <maxContacts>1</maxContacts>

    </gazebo>-->
  <!-- end of link list -->
  <!-- joint list -->
  <!-- WARNING: UPPER LIMIT NOT CORRECT/IGNORED WHILE USING MIMIC JOINT TYPE -->
  <!--		
                <joint name="${prefix}_j1" type="revolute">
                        <parent link="${prefix}_link_0"/>
                        <child link="${prefix}_link_1"/>
                        <axis xyz="1 0 0"/>
                        <origin xyz="0 -0.00407 0.04983" rpy="0.4 0 0"/>
                        <limit lower="0" upper="0.8" effort="100" velocity="100"/>
                        <mimic joint="${prefix}_j0" multiplier="0.4" offset="0"/>
                </joint>
                -->
  <!--   
    <joint name="${prefix}_j1" type="fixed">
      <parent link="${prefix}_link_0"/>
      <child link="${prefix}_link_1"/>
      <axis xyz="1 0 0"/>
      <origin xyz="0 -0.00407 0.04983" rpy="0.4 0 0"/>
      <limit lower="0" upper="0.8" effort="100" velocity="100"/>
    </joint>
    -->
  <!-- end of joint list -->
  <joint name="r_vt_hand_joint" type="fixed">
    <origin rpy="3.141592 0 1.570796" xyz="0 0 -0.16"/>
    <parent link="r_hand"/>
    <child link="r_palm"/>
  </joint>
  <!-- link list -->
  <link name="r_palm">
    <!--
      <collision name="collision_aaa">
        <geometry>
          <mesh filename="package://centaur/meshes/centaur/${prefix}_palm.stl"/>
        </geometry>
      </collision>
      <visual>
        <geometry>
          <mesh filename="package://centaur/meshes/centaur/${prefix}_palm.stl"/>
        </geometry>
        <material name="green">
          <color rgba="0 1 0 1"/>
        </material>
      </visual>
-->
    <visual>
      <origin rpy="0 0 0" xyz="0 0 0"/>
      <geometry>
        <mesh filename="package://centaur/meshes/centaur/r_palm.stl"/>
      </geometry>
      <material name="green">
        <color rgba="0 1 0 1"/>
      </material>
    </visual>
    <collision>
      <origin rpy="0 0 0" xyz="0 0 0"/>
      <geometry>
        <mesh filename="package://centaur/meshes/centaur/r_palm.stl"/>
      </geometry>
      <material name="yellow">
        <color rgba="0 1 1 1"/>
      </material>
    </collision>
    <!-- WARNING: INERTIA NOT CORRECT -->
    <inertial>
      <origin rpy="0 0 0" xyz="0.00344 6.49e-03 42.12e-03"/>
      <mass value="0.7"/>
      <inertia ixx="0.1e-04" ixy="0" ixz="0" iyy="0.07e-04" iyz="0" izz="0.1e-04"/>
    </inertial>
  </link>
  <gazebo reference="r_palm">
    <sensor name="r_HT_contact" type="contact">
      <plugin filename="libcontactHT.so" name="r_HT_plugin"/>
      <contact>
        <collision>r_hand_fixed_joint_lump__r_palm_collision_1</collision>
        <collision>l_hand_fixed_joint_lump__l_palm_collision_1</collision>
      </contact>
    </sensor>
    <!--
      <audio_source>
        <uri>file://media/audio/Hammering_normal.wav</uri>
        <pitch>2.0</pitch>
        <gain>1.0</gain>
        <loop>false</loop>
        <contact>
          <collision>r_hand_fixed_joint_lump__r_palm_collision_1</collision>
          <collision>l_hand_fixed_joint_lump__l_palm_collision_1</collision>
        </contact>
      </audio_source>
-->
  </gazebo>
  <gazebo reference="r_palm">
    <mu1>1.1</mu1>
    <mu2>1.1</mu2>
    <kp>1000000.0</kp>
    <kd>1.0</kd>
    <maxVel>0.1</maxVel>
    <minDepth>0.00</minDepth>
    <maxContacts>6</maxContacts>
    <!--<material>Gazebo/FlatBlack</material>-->
  </gazebo>
  <!-- end of link list -->
  <!-- joint list -->
  <joint name="r_f1_j0" type="revolute">
    <parent link="r_palm"/>
    <child link="r_f1_link_0"/>
    <axis xyz="1 0 0"/>
    <origin rpy="-1.315 0 0" xyz="0.036 0.0361 0.0596"/>
    <limit effort="10" lower="0" upper="2.685" velocity="10"/>
    <!--<dynamics damping="0.1"/>-->
  </joint>
  <joint name="r_f0_j0" type="revolute">
    <parent link="r_palm"/>
    <child link="r_f0_link_0"/>
    <axis xyz="1 0 0"/>
    <origin rpy="-1.315 0 0" xyz="-0.0355 0.0361 0.0596"/>
    <limit effort="10" lower="0" upper="2.685" velocity="10"/>
    <!--<dynamics damping="0.1"/>-->
  </joint>
  <!-- end of joint list -->
  <!--<gazebo>
        <plugin name="THOR_VT_HandPlugin" filename="libTHOR_VT_HandPlugin.so">
		<prefix>${prefix}</prefix>
        </plugin>

        <kp>1000000.0</kp>
    	<kd>100.0</kd>
   	<mu1>1.5</mu1>
    	<mu2>1.5</mu2>
    	<fdir1>1 0 0</fdir1>
    	<maxVel>1.0</maxVel>
        <minDepth>0.00</minDepth>
        <implicitSpringDamper>1</implicitSpringDamper>
	</gazebo>-->
  <!--Transmissions for gazebo ros control-->
  <transmission name="r_f0_j0_transmssion">
    <type>transmission_interface/SimpleTransmission</type>
    <joint name="r_f0_j0">
      <hardwareInterface>EffortJointInterface</hardwareInterface>
    </joint>
    <actuator name="r_f0_j0_motor">
      <hardwareInterface>EffortJointInterface</hardwareInterface>
      <mechanicalReduction>1</mechanicalReduction>
    </actuator>
  </transmission>
  <gazebo reference="r_f0_j0">
    <implicitSpringDamper>1</implicitSpringDamper>
  </gazebo>
  <transmission name="r_f1_j0_transmssion">
    <type>transmission_interface/SimpleTransmission</type>
    <joint name="r_f1_j0">
      <hardwareInterface>EffortJointInterface</hardwareInterface>
    </joint>
    <actuator name="r_f1_j0_motor">
      <hardwareInterface>EffortJointInterface</hardwareInterface>
      <mechanicalReduction>1</mechanicalReduction>
    </actuator>
  </transmission>
  <gazebo reference="r_f1_j0">
    <implicitSpringDamper>1</implicitSpringDamper>
  </gazebo>
  <!--gazebo>
    <plugin name="gazebo_ros_control" filename="libgazebo_ros_control.so">
      <robotNamespace>thor_mang</robotNamespace>
      <robotSimType>gazebo_ros_control/VT_Hand_HWSim</robotSimType>
    </plugin>
  </gazebo-->
  <gazebo>
    <plugin filename="libgazebo_ros_control.so" name="gazebo_ros_control">
      <robotNamespace>thor_mang</robotNamespace>
    </plugin>
  </gazebo>
  <!--</macro>-->
  <!--between ground and lower edge of socket-->
  <!--between upper edge of socket and center of ultrasound sensor-->
  <!--between rear edge of socket and middle ultrasound sensor-->
  <!--between rear edge of socket and left/rigth ultrasound sensor-->
  <!--between x-axis of socket and left/rigth ultrasound sensor-->
  <!--angel between reverse x-axis and left/rigth ultrasound sensor z-axis-->
  <!--<xacro:property name="laser0PitchServo_x_offset" value="0.07" />-->
  <!--between front edge of base and laser0 pitch axis-->
  <!--<xacro:property name="laser0PitchServo_z_offset" value="-0.03" />-->
  <!--between lower edge of base and laser0 pitch axis-->
  <!--<xacro:property name="laser0_x_offset" value="0.023" />-->
  <!--between laser0 pitch axis and laser0 center-->
  <!--between laser0 pitch axis and laserscan plane-->
  <!--<xacro:property name="top_size_x" value="0.185" />-->
  <!--between front edge of top and laser1 pitch axis-->
  <!--<xacro:property name="laser1RollServo_height" value="0.039" />-->
  <!--between lower edge of top and laser1 roll axis-->
  <!--between laser1 roll axis and laserscan plane-->
  <!-- between laser1 pitch axis and laser1 center-->
  <!--<xacro:property name="cameraYawServo_size_z" value="0.091" />-->
  <!--between upper edge of top and camera pitch axis-->
  <!--<xacro:property name="cameraYawServo_x_position" value="-0.027" />-->
  <!--between front edge of top and camera yaw axis-->
  <!--<xacro:property name="camera_size_y" value="0.02" />-->
  <!--<xacro:property name="camera_size_z" value="0.02" />-->
  <!--between intersection point of yaw and pitch axis and center of camera lense-->
  <!--<xacro:property name="camera_y_position" value="-0.049" />-->
  <!--  <xacro:property name="infrared_size_x" value="0.09" />
  <xacro:property name="infrared_radius" value="0.015" />
  <xacro:property name="infrared_x_position" value="0.03" />-->
  <!--between intersection point of yaw and pitch axis and center of infrared lense-->
  <!--<xacro:property name="infrared_y_position" value="0.04" />-->
  <!--5.8cm between front and servo axis-->
  <!--between intersection point of yaw and pitch axis and center of camera lense-->
  <!--   <xacro:property name="kinect_yaw_position" value="0" />/>-->
  <!--between base_link and laser1 roll axis-->
  <!--between upper edge of top and camera pitch axis-->
  <!--between front edge of top and camera yaw axis-->
  <joint name="laser1/x" type="revolute">
    <origin rpy="0 0 0" xyz="0.146 0 0.2"/>
    <parent link="base_link"/>
    <child link="laser1RollServo"/>
    <axis xyz="1 0 0"/>
    <limit effort="100" lower="-1.57079632679" upper="1.57079632679" velocity="100"/>
  </joint>
  <link name="laser1RollServo">
    <inertial>
      <mass value="0.1"/>
      <origin xyz="0 0 0"/>
      <inertia ixx="4.9e-05" ixy="0.0" ixz="0.0" iyy="4.9e-05" iyz="0.0" izz="4.9e-05"/>
    </inertial>
    <visual>
      <origin rpy="0 0 0" xyz="0.032 0.0 0.0"/>
      <geometry>
        <box size="0.064 0.03 0.04"/>
      </geometry>
      <material name="Blue"/>
    </visual>
    <collision>
      <origin rpy="0 0 0" xyz="0.032 0.0 0.0"/>
      <geometry>
        <box size="0.064 0.03 0.04"/>
      </geometry>
    </collision>
  </link>
  <joint name="laser1/y" type="revolute">
    <origin rpy="0 0 0" xyz="0.064 0 0"/>
    <parent link="laser1RollServo"/>
    <child link="laser1_link"/>
    <axis xyz="0 1 0"/>
    <limit effort="100" lower="-1.57079632679" upper="1.57079632679" velocity="100"/>
  </joint>
  <link name="laser1_link">
    <inertial>
      <mass value="0.1"/>
      <origin xyz="0 0 0"/>
      <inertia ixx="4.9e-05" ixy="0.0" ixz="0.0" iyy="4.9e-05" iyz="0.0" izz="4.9e-05"/>
    </inertial>
    <visual>
      <origin rpy="0 0 0" xyz="0.0 0.0 0.045"/>
      <geometry>
        <!--<box size="${laser1_size_x} ${laser1_size_y} ${laser1_size_z}" />-->
        <box size="0.05 0.05 0.01"/>
      </geometry>
      <material name="Grey"/>
    </visual>
    <collision>
      <origin rpy="0 0 0" xyz="0.0 0.0 0.045"/>
      <geometry>
        <!--<box size="${laser1_size_x} ${laser1_size_y} ${laser1_size_z}" />-->
        <box size="0.05 0.05 0.01"/>
      </geometry>
    </collision>
  </link>
  <joint name="laser1_joint" type="fixed">
    <origin rpy="0 0 0" xyz="0.03 0 0.085"/>
    <parent link="laser1_link"/>
    <child link="laser1_frame"/>
  </joint>
  <link name="laser1_frame">
    <inertial>
      <mass value="0.270"/>
      <origin rpy="0 0 0" xyz="0 0 0"/>
      <inertia ixx="2.632e-4" ixy="0" ixz="0" iyy="2.632e-4" iyz="0" izz="1.62e-4"/>
    </inertial>
    <visual>
      <origin rpy="0 0 0" xyz="0 0 0"/>
      <geometry>
        <mesh filename="package://centaur/meshes/centaur/hokuyo_utm_30lx.dae"/>
      </geometry>
    </visual>
    <collision>
      <origin rpy="0 0 0" xyz="0 0 -0.0115"/>
      <geometry>
        <box size="0.058 0.058 0.087"/>
        <!--<mesh filename="package://centaur/meshes/centaur/hokuyo_utm_30lx.stl"/>-->
      </geometry>
    </collision>
  </link>
  <gazebo reference="laser1_frame">
    <sensor name="laser1" type="ray">
      <always_on>true</always_on>
      <update_rate>40</update_rate>
      <pose>0 0 0 0 0 0</pose>
      <visualize>false</visualize>
      <ray>
        <scan>
          <horizontal>
            <samples>1081</samples>
            <resolution>1</resolution>
            <min_angle>2.35619449019</min_angle>
            <max_angle>-2.35619449019</max_angle>
          </horizontal>
        </scan>
        <range>
          <min>0.2</min>
          <max>30.0</max>
          <resolution>0.01</resolution>
        </range>
        <noise>
          <type>gaussian</type>
          <mean>0.0</mean>
          <stddev>0.004</stddev>
        </noise>
      </ray>
      <plugin filename="libgazebo_ros_laser.so" name="gazebo_ros_laser1_controller">
        <topicName>/laser1/scan_no_intensities_from_gazebo</topicName>
        <frameName>laser1_frame</frameName>
      </plugin>
    </sensor>
  </gazebo>
  <gazebo>
    <plugin filename="libhector_servo_plugin.so" name="laser1_servo_controller">
      <alwaysOn>true</alwaysOn>
      <controlRate>50.0</controlRate>
      <updateRate>0.0</updateRate>
      <firstServoName>laser1/x</firstServoName>
      <firstServoAxis>1 0 0</firstServoAxis>
      <secondServoName>laser1/y</secondServoName>
      <secondServoAxis>0 1 0</secondServoAxis>
      <torque>0.5</torque>
      <robotNamespace>/</robotNamespace>
      <topicName>laser1/command</topicName>
      <jointStateName>joint_states</jointStateName>
      <proportionalControllerGain>8.0</proportionalControllerGain>
      <derivativeControllerGain>0.0</derivativeControllerGain>
      <maxVelocity>0.0</maxVelocity>
    </plugin>
  </gazebo>
  <joint name="camera/z" type="revolute">
    <origin rpy="0 0 0" xyz="0.2 0 0.24"/>
    <parent link="base_link"/>
    <child link="cameraYawServo"/>
    <axis xyz="0 0 1"/>
    <limit effort="100" lower="-2.35619449019" upper="2.35619449019" velocity="100"/>
  </joint>
  <link name="cameraYawServo">
    <inertial>
      <mass value="0.1"/>
      <origin xyz="0 0 0"/>
      <inertia ixx="4.9e-05" ixy="0.0" ixz="0.0" iyy="4.9e-05" iyz="0.0" izz="4.9e-05"/>
    </inertial>
    <visual>
      <origin rpy="0 0 0" xyz="0.0 0.0 0.0425"/>
      <geometry>
        <box size="0.04 0.03 0.085"/>
      </geometry>
      <material name="Blue"/>
    </visual>
    <collision>
      <origin rpy="0 0 0" xyz="0.0 0.0 0.0425"/>
      <geometry>
        <box size="0.04 0.03 0.085"/>
      </geometry>
    </collision>
  </link>
  <joint name="camera/y" type="revolute">
    <origin rpy="0 0 0" xyz="0 0 0.085"/>
    <parent link="cameraYawServo"/>
    <child link="mounting_link"/>
    <axis xyz="0 1 0"/>
    <limit effort="100" lower="-1.57079632679" upper="1.57079632679" velocity="100"/>
  </joint>
  <link name="mounting_link">
    <inertial>
      <mass value="0.05"/>
      <origin xyz="0 0 0"/>
      <inertia ixx="2.45e-05" ixy="0.0" ixz="0.0" iyy="2.45e-05" iyz="0.0" izz="2.45e-05"/>
    </inertial>
  </link>
  <joint name="infrared_joint" type="fixed">
    <origin rpy="0 0 0" xyz="0.0505 0.046 -0.0025"/>
    <parent link="mounting_link"/>
    <child link="infrared_frame"/>
  </joint>
  <link name="infrared_frame">
    <inertial>
      <mass value="0.01"/>
      <origin xyz="0 0 0"/>
      <inertia ixx="4.9e-06" ixy="0.0" ixz="0.0" iyy="4.9e-06" iyz="0.0" izz="4.9e-06"/>
    </inertial>
    <visual>
      <origin rpy="0 0 0" xyz="0 0 0"/>
      <geometry>
        <mesh filename="package://centaur/meshes/centaur/thermaleye_camera_hector_v2.dae"/>
      </geometry>
    </visual>
    <collision>
      <origin rpy="0 0 0" xyz="0 0 0"/>
      <geometry>
        <mesh filename="package://centaur/meshes/centaur/thermaleye_camera_hector_v2.stl"/>
      </geometry>
    </collision>
  </link>
  <joint name="infrared_optical_joint" type="fixed">
    <origin rpy="-1.57079632679 0.0 -1.57079632679" xyz="0 0 0"/>
    <parent link="infrared_frame"/>
    <child link="infrared_optical_frame"/>
  </joint>
  <link name="infrared_optical_frame"/>
  <joint name="openni_joint" type="fixed">
    <origin rpy="0 0 0.0" xyz="0.055 0.0  0.055"/>
    <parent link="mounting_link"/>
    <child link="openni_link"/>
  </joint>
  <link name="openni_link">
    <inertial>
      <mass value="0.200"/>
      <origin rpy="0 0 0" xyz="0 0 0"/>
      <inertia ixx="5.8083e-4" ixy="0" ixz="0" iyy="3.0833e-5" iyz="0" izz="5.9083e-4"/>
    </inertial>
    <visual>
      <origin rpy="0 0 0" xyz="0 0 0"/>
      <geometry>
        <mesh filename="package://centaur/meshes/centaur/asus_camera_simple.dae"/>
      </geometry>
    </visual>
    <!--        
       <collision>
          <origin xyz="0 0 0" rpy="0 0 0" />
          <geometry>
            <box size="0.035 0.185 0.025"/>
          </geometry>
        </collision>
        -->
    <collision>
      <origin rpy="0 0 0" xyz="0 0 0"/>
      <geometry>
        <mesh filename="package://centaur/meshes/centaur/asus_camera_simple.dae"/>
      </geometry>
    </collision>
  </link>
  <joint name="openni_depth_joint" type="fixed">
    <origin rpy="0 0 0" xyz="0.0 0.049 0.0"/>
    <parent link="openni_link"/>
    <child link="openni_depth_frame"/>
  </joint>
  <link name="openni_depth_frame"/>
  <joint name="openni_depth_optical_joint" type="fixed">
    <origin rpy="-1.57079632679 0.0 -1.57079632679" xyz="0 0 0"/>
    <parent link="openni_depth_frame"/>
    <child link="openni_depth_optical_frame"/>
  </joint>
  <link name="openni_depth_optical_frame"/>
  <joint name="openni_rgb_joint" type="fixed">
    <origin rpy="0 0 0" xyz="0.0 0.022 0.0"/>
    <parent link="openni_link"/>
    <child link="openni_rgb_frame"/>
  </joint>
  <link name="openni_rgb_frame"/>
  <joint name="openni_rgb_optical_joint" type="fixed">
    <origin rpy="-1.57079632679 0.0 -1.57079632679" xyz="0 0 0"/>
    <parent link="openni_rgb_frame"/>
    <child link="openni_rgb_optical_frame"/>
  </joint>
  <link name="openni_rgb_optical_frame"/>
  <gazebo>
    <plugin filename="libhector_servo_plugin.so" name="camera_servo_controller">
      <alwaysOn>true</alwaysOn>
      <controlRate>50.0</controlRate>
      <updateRate>0.0</updateRate>
      <firstServoName>camera/z</firstServoName>
      <firstServoAxis>0 0 1</firstServoAxis>
      <secondServoName>camera/y</secondServoName>
      <secondServoAxis>0 1 0</secondServoAxis>
      <torque>0.5</torque>
      <robotNamespace>/</robotNamespace>
      <topicName>camera/command</topicName>
      <jointStateName>joint_states</jointStateName>
      <proportionalControllerGain>8.0</proportionalControllerGain>
      <derivativeControllerGain>0.0</derivativeControllerGain>
      <maxVelocity>2.0</maxVelocity>
    </plugin>
  </gazebo>
  <gazebo reference="openni_depth_frame">
    <sensor name="kinect_camera" type="depth">
      <update_rate>10</update_rate>
      <camera>
        <horizontal_fov>1.0471975512</horizontal_fov>
        <image>
          <format>R8G8B8</format>
          <width>320</width>
          <height>240</height>
        </image>
        <clip>
          <near>0.05</near>
          <far>3</far>
        </clip>
      </camera>
      <plugin filename="libgazebo_ros_openni_kinect.so" name="kinect_camera_controller">
        <alwaysOn>true</alwaysOn>
        <updateRate>10</updateRate>
        <imageTopicName>openni/rgb/image_color</imageTopicName>
        <cameraInfoTopicName>openni/camera_info</cameraInfoTopicName>
        <depthImageTopicName>openni/depth/image_raw</depthImageTopicName>
        <depthImageCameraInfoTopicName>openni/depth/camera_info</depthImageCameraInfoTopicName>
        <pointCloudTopicName>openni/depth/points</pointCloudTopicName>
        <frameName>openni_depth_optical_frame</frameName>
        <pointCloudCutoff>0.5</pointCloudCutoff>
        <distortionK1>0</distortionK1>
        <distortionK2>0</distortionK2>
        <distortionK3>0</distortionK3>
        <distortionT1>0</distortionT1>
        <distortionT2>0</distortionT2>
        <CxPrime>0</CxPrime>
        <Cx>0</Cx>
        <Cy>0</Cy>
        <focalLength>0</focalLength>
        <hackBaseline>0</hackBaseline>
      </plugin>
    </sensor>
  </gazebo>
  <gazebo reference="infrared_frame">
    <sensor name="thermal_camera_sensor" type="camera">
      <update_rate>10</update_rate>
      <camera>
        <horizontal_fov>1.57079632679</horizontal_fov>
        <image>
          <format>R8G8B8</format>
          <width>160</width>
          <height>120</height>
        </image>
        <clip>
          <near>0.01</near>
          <far>100</far>
        </clip>
      </camera>
      <plugin filename="libgazebo_ros_thermal_camera.so" name="thermal_camera_controller">
        <alwaysOn>true</alwaysOn>
        <updateRate>10</updateRate>
        <imageTopicName>/thermal/image</imageTopicName>
        <cameraInfoTopicName>/thermal/camera_info</cameraInfoTopicName>
        <frameName>infrared_optical_frame</frameName>
      </plugin>
    </sensor>
  </gazebo>
</robot>

