<?xml version="1.0"?>
<sdf version="1.5">
  <model name="fourlegs">
    <static>false</static>
    <self_collide>false</self_collide>
    <!--  ----------------------------  -->
    <link name="BODY">
      <pose>0 0 0.06 0 0 0</pose>
      <inertial>
        <mass>2</mass>
        <inertia>
          <ixx>0.00194</ixx>
          <ixy>0</ixy>
          <ixz>0</ixz>
          <iyy>0.00694</iyy>
          <iyz>0</iyz>
          <izz>0.00834</izz>
        </inertia>
      </inertial>
      <collision name="collision">
        <geometry>
          <box>
            <size>0.2 0.1 0.04</size>
          </box>
        </geometry>
        <surface>
          <friction>
            <ode>
              <mu>1</mu>
              <mu2>1</mu2>
              <slip1>0</slip1>
              <slip2>0</slip2>
            </ode>
          </friction>
        </surface>
      </collision>
      <visual name="visual">
        <geometry>
          <box>
            <size>0.2 0.1 0.04</size>
          </box>
        </geometry>
      </visual>
    </link>
    <!--  ----------------------------  -->
    <link name="NECK">
      <pose>0.1 0 0.11 0 0 0</pose>
      <inertial>
        <mass>0.2</mass>
        <inertia>
          <ixx>0.000034133</ixx>
          <ixy>0</ixy>
          <ixz>0</ixz>
          <iyy>0.000054613</iyy>
          <iyz>0</iyz>
          <izz>0.000034133</izz>
        </inertia>
      </inertial>
      <collision name="collision">
        <geometry>
          <box>
            <size>0.04 0.02 0.04</size>
          </box>
        </geometry>
        <surface>
          <friction>
            <ode>
              <mu>1</mu>
              <mu2>1</mu2>
              <slip1>0</slip1>
              <slip2>0</slip2>
            </ode>
          </friction>
        </surface>
      </collision>
      <visual name="visual">
        <geometry>
          <box>
            <size>0.04 0.02 0.04</size>
          </box>
        </geometry>
      </visual>
      <sensor type="camera" name="camera">
        <update_rate>20</update_rate>
        <visualize>false</visualize>
        <camera name="camera">
          <horizontal_fov>1.047</horizontal_fov>
          <image>
            <width>320</width>
            <height>240</height>
            <format>R8G8B8</format>
          </image>
          <clip>
            <near>0.1</near>
            <far>100</far>
          </clip>
          <!-- Noise is sampled independently per pixel on each frame.
               That pixel's noise value is added to each of its color
               channels, which at that point lie in the range [0,1]. -->
          <noise>
            <type>gaussian</type>
            <mean>0.0</mean>
            <stddev>0.007</stddev>
          </noise>
        </camera>
<!-- For gazebo_ros connection
        <plugin name="camera_controller" filename="libgazebo_ros_camera.so">
          <alwaysOn>true</alwaysOn>
          <updateRate>0.0</updateRate>
          <cameraName>camera/rgb</cameraName>
          <imageTopicName>image_raw</imageTopicName>
          <cameraInfoTopicName>NECK</cameraInfoTopicName>
          <frameName>camera_link</frameName>
          <hackBaseline>0.07</hackBaseline>
          <distortionK1>0.0</distortionK1>
          <distortionK2>0.0</distortionK2>
          <distortionK3>0.0</distortionK3>
          <distortionT1>0.0</distortionT1>
          <distortionT2>0.0</distortionT2>
        </plugin>
-->
      </sensor>
    </link>
    <!--  ----------------------------  -->
    <joint type="revolute" name="J_NECK">
      <pose>-0.02 0 -0.03 0 0 0</pose>
      <child>NECK</child>
      <parent>BODY</parent>
      <axis>
        <xyz>0 0 1</xyz>
        <limit>
          <lower>0</lower>
          <upper>0</upper>
        </limit>
      </axis>
    </joint>
    <!--  ----------------------------  -->
    <link name="FR0">
      <pose>0.13 -0.03 0.05 0 0 0</pose>
      <inertial>
        <mass>0.01</mass>
        <inertia>
          <ixx>0.000000175</ixx>
          <ixy>0</ixy>
          <ixz>0</ixz>
          <iyy>0.000000175</iyy>
          <iyz>0</iyz>
          <izz>0.000000175</izz>
        </inertia>
      </inertial>
      <collision name="collision">
        <geometry>
          <box>
            <size>0.01 0.01 0.01</size>
          </box>
        </geometry>
        <surface>
          <friction>
            <ode>
              <mu>1</mu>
              <mu2>1</mu2>
              <slip1>0</slip1>
              <slip2>0</slip2>
            </ode>
          </friction>
        </surface>
      </collision>
      <visual name="visual">
        <geometry>
          <box>
            <size>0.01 0.01 0.01</size>
          </box>
        </geometry>
      </visual>
    </link>
    <!--  ----------------------------  -->
    <joint type="revolute" name="J_FR_B20">
      <pose>0 0 0 0 0 0</pose>
      <child>FR0</child>
      <parent>BODY</parent>
      <axis>
        <xyz>-1 0 0</xyz>
      </axis>
    </joint>
    <!--  ----------------------------  -->
    <link name="FR1">
      <pose>0.13 -0.06 0.05 0 0 0</pose>
      <inertial>
        <mass>0.2</mass>
        <inertia>
          <ixx>0.000054613</ixx>
          <ixy>0</ixy>
          <ixz>0</ixz>
          <iyy>0.000034133</iyy>
          <iyz>0</iyz>
          <izz>0.000034133</izz>
        </inertia>
      </inertial>
      <collision name="collision">
        <geometry>
          <box>
            <size>0.02 0.04 0.04</size>
          </box>
        </geometry>
        <surface>
          <friction>
            <ode>
              <mu>1</mu>
              <mu2>1</mu2>
              <slip1>0</slip1>
              <slip2>0</slip2>
            </ode>
          </friction>
        </surface>
      </collision>
      <visual name="visual">
        <geometry>
          <box>
            <size>0.02 0.04 0.04</size>
          </box>
        </geometry>
      </visual>
    </link>
    <!--  ----------------------------  -->
    <joint type="revolute" name="J_FR_021">
      <pose>0 0 0 0 0 0</pose>
      <child>FR0</child>
      <parent>FR1</parent>
      <axis>
        <xyz>0 0 -1</xyz>
      </axis>
    </joint>
    <!--  ----------------------------  -->
    <link name="FR2">
      <pose>0.13 -0.1 0.02 0 0 0</pose>
      <inertial>
        <mass>0.2</mass>
        <inertia>
          <ixx>0.000034133</ixx>
          <ixy>0</ixy>
          <ixz>0</ixz>
          <iyy>0.000054613</iyy>
          <iyz>0</iyz>
          <izz>0.000034133</izz>
        </inertia>
      </inertial>
      <collision name="collision">
        <geometry>
          <box>
            <size>0.04 0.02 0.04</size>
          </box>
        </geometry>
        <surface>
          <friction>
            <ode>
              <mu>1</mu>
              <mu2>1</mu2>
              <slip1>0</slip1>
              <slip2>0</slip2>
            </ode>
          </friction>
        </surface>
      </collision>
      <visual name="visual">
        <geometry>
          <box>
            <size>0.04 0.02 0.04</size>
          </box>
        </geometry>
      </visual>
<!--
        <inertial>
          <pose>0 0 -0.02 0 0 0</pose>
          <mass>0.001</mass>
          <inertia>
            <ixx>1.67551608191e-4</ixx>
            <ixy>0</ixy>
            <ixz>0</ixz>
            <iyy>1.67551608191e-4</iyy>
            <iyz>0</iyz>
            <izz>1.67551608191e-4</izz>
          </inertia>
        </inertial>
-->
      <collision name="collision_sphere">
        <pose>0 0 -0.02 0 0 0</pose>
        <geometry>
          <sphere>
            <radius>0.01</radius>
          </sphere>
        </geometry>
        <surface>
          <friction>
            <ode>
              <mu>1</mu>
              <mu2>1</mu2>
              <slip1>0</slip1>
              <slip2>0</slip2>
            </ode>
          </friction>
        </surface>
      </collision>
      <visual name="visual_sphere">
        <pose>0 0 -0.02 0 0 0</pose>
        <geometry>
          <sphere>
            <radius>0.01</radius>
          </sphere>
        </geometry>
        <material>
          <ambient>0 0 0 1</ambient>
          <diffuse>0 0 0 1</diffuse>
          <specular>0.1 0.1 0.1 1</specular>
          <emissive>0 0 0 0</emissive>
        </material>
      </visual>
    </link>
    <!--  ----------------------------  -->
    <joint type="revolute" name="J_FR_122">
      <pose>0 0 0.03 0 0 0</pose>
      <child>FR2</child>
      <parent>FR1</parent>
      <axis>
        <xyz>1 0 0</xyz>
      </axis>
    </joint>
    <!--  ----------------------------  -->
    <link name="FL0">
      <pose>0.13 0.03 0.05 0 0 0</pose>
      <inertial>
        <mass>0.01</mass>
        <inertia>
          <ixx>0.000000175</ixx>
          <ixy>0</ixy>
          <ixz>0</ixz>
          <iyy>0.000000175</iyy>
          <iyz>0</iyz>
          <izz>0.000000175</izz>
        </inertia>
      </inertial>
      <collision name="collision">
        <geometry>
          <box>
            <size>0.01 0.01 0.01</size>
          </box>
        </geometry>
        <surface>
          <friction>
            <ode>
              <mu>1</mu>
              <mu2>1</mu2>
              <slip1>0</slip1>
              <slip2>0</slip2>
            </ode>
          </friction>
        </surface>
      </collision>
      <visual name="visual">
        <geometry>
          <box>
            <size>0.01 0.01 0.01</size>
          </box>
        </geometry>
      </visual>
    </link>
    <!--  ----------------------------  -->
    <joint type="revolute" name="J_FL_B20">
      <pose>0 0 0 0 0 0</pose>
      <child>FL0</child>
      <parent>BODY</parent>
      <axis>
        <xyz>1 0 0</xyz>
      </axis>
    </joint>
    <!--  ----------------------------  -->
    <link name="FL1">
      <pose>0.13 0.06 0.05 0 0 0</pose>
      <inertial>
        <mass>0.2</mass>
        <inertia>
          <ixx>0.000054613</ixx>
          <ixy>0</ixy>
          <ixz>0</ixz>
          <iyy>0.000034133</iyy>
          <iyz>0</iyz>
          <izz>0.000034133</izz>
        </inertia>
      </inertial>
      <collision name="collision">
        <geometry>
          <box>
            <size>0.02 0.04 0.04</size>
          </box>
        </geometry>
        <surface>
          <friction>
            <ode>
              <mu>1</mu>
              <mu2>1</mu2>
              <slip1>0</slip1>
              <slip2>0</slip2>
            </ode>
          </friction>
        </surface>
      </collision>
      <visual name="visual">
        <geometry>
          <box>
            <size>0.02 0.04 0.04</size>
          </box>
        </geometry>
      </visual>
    </link>
    <!--  ----------------------------  -->
    <joint type="revolute" name="J_FL_021">
      <pose>0 0 0 0 0 0</pose>
      <child>FL0</child>
      <parent>FL1</parent>
      <axis>
        <xyz>0 0 1</xyz>
      </axis>
    </joint>
    <!--  ----------------------------  -->
    <link name="FL2">
      <pose>0.13 0.1 0.02 0 0 0</pose>
      <inertial>
        <mass>0.2</mass>
        <inertia>
          <ixx>0.000034133</ixx>
          <ixy>0</ixy>
          <ixz>0</ixz>
          <iyy>0.000054613</iyy>
          <iyz>0</iyz>
          <izz>0.000034133</izz>
        </inertia>
      </inertial>
      <collision name="collision">
        <geometry>
          <box>
            <size>0.04 0.02 0.04</size>
          </box>
        </geometry>
        <surface>
          <friction>
            <ode>
              <mu>1</mu>
              <mu2>1</mu2>
              <slip1>0</slip1>
              <slip2>0</slip2>
            </ode>
          </friction>
        </surface>
      </collision>
      <visual name="visual">
        <geometry>
          <box>
            <size>0.04 0.02 0.04</size>
          </box>
        </geometry>
      </visual>
<!--
        <inertial>
          <pose>0 0 -0.02 0 0 0</pose>
          <mass>0.001</mass>
          <inertia>
            <ixx>1.67551608191e-4</ixx>
            <ixy>0</ixy>
            <ixz>0</ixz>
            <iyy>1.67551608191e-4</iyy>
            <iyz>0</iyz>
            <izz>1.67551608191e-4</izz>
          </inertia>
        </inertial>
-->
      <collision name="collision_sphere">
        <pose>0 0 -0.02 0 0 0</pose>
        <geometry>
          <sphere>
            <radius>0.01</radius>
          </sphere>
        </geometry>
        <surface>
          <friction>
            <ode>
              <mu>1</mu>
              <mu2>1</mu2>
              <slip1>0</slip1>
              <slip2>0</slip2>
            </ode>
          </friction>
        </surface>
      </collision>
      <visual name="visual_sphere">
        <pose>0 0 -0.02 0 0 0</pose>
        <geometry>
          <sphere>
            <radius>0.01</radius>
          </sphere>
        </geometry>
        <material>
          <ambient>0 0 0 1</ambient>
          <diffuse>0 0 0 1</diffuse>
          <specular>0.1 0.1 0.1 1</specular>
          <emissive>0 0 0 0</emissive>
        </material>
      </visual>
    </link>
    <!--  ----------------------------  -->
    <joint type="revolute" name="J_FL_122">
      <pose>0 0 0.03 0 0 0</pose>
      <child>FL2</child>
      <parent>FL1</parent>
      <axis>
        <xyz>-1 0 0</xyz>
      </axis>
    </joint>
    <!--  ----------------------------  -->
    <link name="RR0">
      <pose>-0.13 -0.03 0.05 0 0 0</pose>
      <inertial>
        <mass>0.01</mass>
        <inertia>
          <ixx>0.000000175</ixx>
          <ixy>0</ixy>
          <ixz>0</ixz>
          <iyy>0.000000175</iyy>
          <iyz>0</iyz>
          <izz>0.000000175</izz>
        </inertia>
      </inertial>
      <collision name="collision">
        <geometry>
          <box>
            <size>0.01 0.01 0.01</size>
          </box>
        </geometry>
        <surface>
          <friction>
            <ode>
              <mu>1</mu>
              <mu2>1</mu2>
              <slip1>0</slip1>
              <slip2>0</slip2>
            </ode>
          </friction>
        </surface>
      </collision>
      <visual name="visual">
        <geometry>
          <box>
            <size>0.01 0.01 0.01</size>
          </box>
        </geometry>
      </visual>
    </link>
    <!--  ----------------------------  -->
    <joint type="revolute" name="J_RR_B20">
      <pose>0 0 0 0 0 0</pose>
      <child>RR0</child>
      <parent>BODY</parent>
      <axis>
        <xyz>-1 0 0</xyz>
      </axis>
    </joint>
    <!--  ----------------------------  -->
    <link name="RR1">
      <pose>-0.13 -0.06 0.05 0 0 0</pose>
      <inertial>
        <mass>0.2</mass>
        <inertia>
          <ixx>0.000054613</ixx>
          <ixy>0</ixy>
          <ixz>0</ixz>
          <iyy>0.000034133</iyy>
          <iyz>0</iyz>
          <izz>0.000034133</izz>
        </inertia>
      </inertial>
      <collision name="collision">
        <geometry>
          <box>
            <size>0.02 0.04 0.04</size>
          </box>
        </geometry>
        <surface>
          <friction>
            <ode>
              <mu>1</mu>
              <mu2>1</mu2>
              <slip1>0</slip1>
              <slip2>0</slip2>
            </ode>
          </friction>
        </surface>
      </collision>
      <visual name="visual">
        <geometry>
          <box>
            <size>0.02 0.04 0.04</size>
          </box>
        </geometry>
      </visual>
    </link>
    <!--  ----------------------------  -->
    <joint type="revolute" name="J_RR_021">
      <pose>0 0 0 0 0 0</pose>
      <child>RR0</child>
      <parent>RR1</parent>
      <axis>
        <xyz>0 0 1</xyz>
      </axis>
    </joint>
    <!--  ----------------------------  -->
    <link name="RR2">
      <pose>-0.13 -0.1 0.02 0 0 0</pose>
      <inertial>
        <mass>0.2</mass>
        <inertia>
          <ixx>0.000034133</ixx>
          <ixy>0</ixy>
          <ixz>0</ixz>
          <iyy>0.000054613</iyy>
          <iyz>0</iyz>
          <izz>0.000034133</izz>
        </inertia>
      </inertial>
      <collision name="collision">
        <geometry>
          <box>
            <size>0.04 0.02 0.04</size>
          </box>
        </geometry>
        <surface>
          <friction>
            <ode>
              <mu>1</mu>
              <mu2>1</mu2>
              <slip1>0</slip1>
              <slip2>0</slip2>
            </ode>
          </friction>
        </surface>
      </collision>
      <visual name="visual">
        <geometry>
          <box>
            <size>0.04 0.02 0.04</size>
          </box>
        </geometry>
      </visual>
<!--
        <inertial>
          <pose>0 0 -0.02 0 0 0</pose>
          <mass>0.001</mass>
          <inertia>
            <ixx>1.67551608191e-4</ixx>
            <ixy>0</ixy>
            <ixz>0</ixz>
            <iyy>1.67551608191e-4</iyy>
            <iyz>0</iyz>
            <izz>1.67551608191e-4</izz>
          </inertia>
        </inertial>
-->
      <collision name="collision_sphere">
        <pose>0 0 -0.02 0 0 0</pose>
        <geometry>
          <sphere>
            <radius>0.01</radius>
          </sphere>
        </geometry>
        <surface>
          <friction>
            <ode>
              <mu>1</mu>
              <mu2>1</mu2>
              <slip1>0</slip1>
              <slip2>0</slip2>
            </ode>
          </friction>
        </surface>
      </collision>
      <visual name="visual_sphere">
        <pose>0 0 -0.02 0 0 0</pose>
        <geometry>
          <sphere>
            <radius>0.01</radius>
          </sphere>
        </geometry>
        <material>
          <ambient>0 0 0 1</ambient>
          <diffuse>0 0 0 1</diffuse>
          <specular>0.1 0.1 0.1 1</specular>
          <emissive>0 0 0 0</emissive>
        </material>
      </visual>
    </link>
    <!--  ----------------------------  -->
    <joint type="revolute" name="J_RR_122">
      <pose>0 0 0.03 0 0 0</pose>
      <child>RR2</child>
      <parent>RR1</parent>
      <axis>
        <xyz>1 0 0</xyz>
      </axis>
    </joint>
    <!--  ----------------------------  -->
    <link name="RL0">
      <pose>-0.13 0.03 0.05 0 0 0</pose>
      <inertial>
        <mass>0.01</mass>
        <inertia>
          <ixx>0.000000175</ixx>
          <ixy>0</ixy>
          <ixz>0</ixz>
          <iyy>0.000000175</iyy>
          <iyz>0</iyz>
          <izz>0.000000175</izz>
        </inertia>
      </inertial>
      <collision name="collision">
        <geometry>
          <box>
            <size>0.01 0.01 0.01</size>
          </box>
        </geometry>
        <surface>
          <friction>
            <ode>
              <mu>1</mu>
              <mu2>1</mu2>
              <slip1>0</slip1>
              <slip2>0</slip2>
            </ode>
          </friction>
        </surface>
      </collision>
      <visual name="visual">
        <geometry>
          <box>
            <size>0.01 0.01 0.01</size>
          </box>
        </geometry>
      </visual>
    </link>
    <!--  ----------------------------  -->
    <joint type="revolute" name="J_RL_B20">
      <pose>0 0 0 0 0 0</pose>
      <child>RL0</child>
      <parent>BODY</parent>
      <axis>
        <xyz>1 0 0</xyz>
      </axis>
    </joint>
    <!--  ----------------------------  -->
    <link name="RL1">
      <pose>-0.13 0.06 0.05 0 0 0</pose>
      <inertial>
        <mass>0.2</mass>
        <inertia>
          <ixx>0.000054613</ixx>
          <ixy>0</ixy>
          <ixz>0</ixz>
          <iyy>0.000034133</iyy>
          <iyz>0</iyz>
          <izz>0.000034133</izz>
        </inertia>
      </inertial>
      <collision name="collision">
        <geometry>
          <box>
            <size>0.02 0.04 0.04</size>
          </box>
        </geometry>
        <surface>
          <friction>
            <ode>
              <mu>1</mu>
              <mu2>1</mu2>
              <slip1>0</slip1>
              <slip2>0</slip2>
            </ode>
          </friction>
        </surface>
      </collision>
      <visual name="visual">
        <geometry>
          <box>
            <size>0.02 0.04 0.04</size>
          </box>
        </geometry>
      </visual>
    </link>
    <!--  ----------------------------  -->
    <joint type="revolute" name="J_RL_021">
      <pose>0 0 0 0 0 0</pose>
      <child>RL0</child>
      <parent>RL1</parent>
      <axis>
        <xyz>0 0 -1</xyz>
      </axis>
    </joint>
    <!--  ----------------------------  -->
    <link name="RL2">
      <pose>-0.13 0.1 0.02 0 0 0</pose>
      <inertial>
        <mass>0.2</mass>
        <inertia>
          <ixx>0.000034133</ixx>
          <ixy>0</ixy>
          <ixz>0</ixz>
          <iyy>0.000054613</iyy>
          <iyz>0</iyz>
          <izz>0.000034133</izz>
        </inertia>
      </inertial>
      <collision name="collision">
        <geometry>
          <box>
            <size>0.04 0.02 0.04</size>
          </box>
        </geometry>
        <surface>
          <friction>
            <ode>
              <mu>1</mu>
              <mu2>1</mu2>
              <slip1>0</slip1>
              <slip2>0</slip2>
            </ode>
          </friction>
        </surface>
      </collision>
      <visual name="visual">
        <geometry>
          <box>
            <size>0.04 0.02 0.04</size>
          </box>
        </geometry>
      </visual>
<!--
        <inertial>
          <pose>0 0 -0.02 0 0 0</pose>
          <mass>0.001</mass>
          <inertia>
            <ixx>1.67551608191e-4</ixx>
            <ixy>0</ixy>
            <ixz>0</ixz>
            <iyy>1.67551608191e-4</iyy>
            <iyz>0</iyz>
            <izz>1.67551608191e-4</izz>
          </inertia>
        </inertial>
-->
      <collision name="collision_sphere">
        <pose>0 0 -0.02 0 0 0</pose>
        <geometry>
          <sphere>
            <radius>0.01</radius>
          </sphere>
        </geometry>
        <surface>
          <friction>
            <ode>
              <mu>1</mu>
              <mu2>1</mu2>
              <slip1>0</slip1>
              <slip2>0</slip2>
            </ode>
          </friction>
        </surface>
      </collision>
      <visual name="visual_sphere">
        <pose>0 0 -0.02 0 0 0</pose>
        <geometry>
          <sphere>
            <radius>0.01</radius>
          </sphere>
        </geometry>
        <material>
          <ambient>0 0 0 1</ambient>
          <diffuse>0 0 0 1</diffuse>
          <specular>0.1 0.1 0.1 1</specular>
          <emissive>0 0 0 0</emissive>
        </material>
      </visual>
    </link>
    <!--  ----------------------------  -->
    <joint type="revolute" name="J_RL_122">
      <pose>0 0 0.03 0 0 0</pose>
      <child>RL2</child>
      <parent>RL1</parent>
      <axis>
        <xyz>-1 0 0</xyz>
      </axis>
    </joint>
    <!--  ----------------------------  -->
    <link name="front_right_wheel">
      <pose>0.13 -.125 0 -1.5707 0 0</pose>
      <inertial>
        <mass>0.1</mass>
        <inertia>
          <ixx>0.00015621</ixx>
          <ixy>0</ixy>
          <ixz>0</ixz>
          <iyy>0.00015621</iyy>
          <iyz>0</iyz>
          <izz>0.00028839</izz>
        </inertia>
      </inertial>
      <collision name="collision">
        <geometry>
          <cylinder>
            <radius>0.05</radius>
            <length>0.025</length>
          </cylinder>
        </geometry>
        <surface>
          <friction>
            <ode>
              <mu>1.0</mu>
              <mu2>1.0</mu2>
<!--              <slip1>0.0</slip1>
              <slip2>0.0</slip2> -->
            </ode>
          </friction>
        </surface>
      </collision>
      <visual name="visual">
        <geometry>
          <cylinder>
            <radius>0.05</radius>
            <length>0.025</length>
          </cylinder>
        </geometry>
        <material>
          <script>
            <uri>file://media/materials/scripts/gazebo.material</uri>
            <name>Gazebo/FlatBlack</name>
          </script>
        </material>
      </visual>
    </link>
    <!--  ----------------------------  -->
    <joint type="revolute" name="front_right_wheel_hinge">
      <pose>0 0 0.01 0 0 0</pose>
      <child>front_right_wheel</child>
      <parent>FR2</parent>
      <axis>
        <xyz>0 0 1</xyz>
      </axis>
<!--
     <sensor name="force_torque_front_right_wheel_hinge" type="force_torque">
        <update_rate>1</update_rate>
        <force_torque>
          <frame>child</frame>
          <measure_direction>child_to_parent</measure_direction>
        </force_torque>
      </sensor>
-->
    </joint>
    <!--  ----------------------------  -->
    <link name="front_left_wheel">
      <pose>0.13 .125 0 -1.5707 0 0</pose>
      <inertial>
        <mass>0.1</mass>
        <inertia>
          <ixx>0.00015621</ixx>
          <ixy>0</ixy>
          <ixz>0</ixz>
          <iyy>0.00015621</iyy>
          <iyz>0</iyz>
          <izz>0.00028839</izz>
        </inertia>
      </inertial>
      <collision name="collision">
        <geometry>
          <cylinder>
            <radius>0.05</radius>
            <length>0.025</length>
          </cylinder>
        </geometry>
        <surface>
          <friction>
            <ode>
              <mu>1.0</mu>
              <mu2>1.0</mu2>
<!--              <slip1>0.0</slip1>
              <slip2>0.0</slip2> -->
            </ode>
          </friction>
        </surface>
      </collision>
      <visual name="visual">
        <geometry>
          <cylinder>
            <radius>0.05</radius>
            <length>0.025</length>
          </cylinder>
        </geometry>
        <material>
          <script>
            <uri>file://media/materials/scripts/gazebo.material</uri>
            <name>Gazebo/FlatBlack</name>
          </script>
        </material>
      </visual>
    </link>
    <!--  ----------------------------  -->
    <joint type="revolute" name="front_left_wheel_hinge">
      <pose>0 0 0.01 0 0 0</pose>
      <child>front_left_wheel</child>
      <parent>FL2</parent>
      <axis>
        <xyz>0 0 1</xyz>
      </axis>
<!--
      <sensor name="force_torque_front_left_wheel_hinge" type="force_torque">
        <update_rate>1</update_rate>
        <force_torque>
          <frame>child</frame>
          <measure_direction>child_to_parent</measure_direction>
        </force_torque>
      </sensor>
-->
    </joint>
    <!--  ----------------------------  -->
    <link name="rear_right_wheel">
      <pose>-0.13 -.125 0 -1.5707 0 0</pose>
      <inertial>
        <mass>0.1</mass>
        <inertia>
          <ixx>0.00015621</ixx>
          <ixy>0</ixy>
          <ixz>0</ixz>
          <iyy>0.00015621</iyy>
          <iyz>0</iyz>
          <izz>0.00028839</izz>
        </inertia>
      </inertial>
      <collision name="collision">
        <geometry>
          <cylinder>
            <radius>0.05</radius>
            <length>0.025</length>
          </cylinder>
        </geometry>
        <surface>
          <friction>
            <ode>
              <mu>1.0</mu>
              <mu2>1.0</mu2>
<!--              <slip1>0.0</slip1>
              <slip2>0.0</slip2> -->
            </ode>
          </friction>
        </surface>
      </collision>
      <visual name="visual">
        <geometry>
          <cylinder>
            <radius>0.05</radius>
            <length>0.025</length>
          </cylinder>
        </geometry>
        <material>
          <script>
            <uri>file://media/materials/scripts/gazebo.material</uri>
            <name>Gazebo/FlatBlack</name>
          </script>
        </material>
      </visual>
    </link>
    <!--  ----------------------------  -->
    <joint type="revolute" name="rear_right_wheel_hinge">
      <pose>0 0 0.01 0 0 0</pose>
      <child>rear_right_wheel</child>
      <parent>RR2</parent>
      <axis>
        <xyz>0 0 1</xyz>
      </axis>
<!--
      <sensor name="force_torque_rear_right_wheel_hinge" type="force_torque">
        <update_rate>1</update_rate>
        <force_torque>
          <frame>child</frame>
          <measure_direction>child_to_parent</measure_direction>
        </force_torque>
      </sensor>
-->
    </joint>
    <!--  ----------------------------  -->
    <link name="rear_left_wheel">
      <pose>-0.13 .125 0 -1.5707 0 0</pose>
      <inertial>
        <mass>0.1</mass>
        <inertia>
          <ixx>0.00015621</ixx>
          <ixy>0</ixy>
          <ixz>0</ixz>
          <iyy>0.00015621</iyy>
          <iyz>0</iyz>
          <izz>0.00028839</izz>
        </inertia>
      </inertial>
      <collision name="collision">
        <geometry>
          <cylinder>
            <radius>0.05</radius>
            <length>0.025</length>
          </cylinder>
        </geometry>
        <surface>
          <friction>
            <ode>
              <mu>1.0</mu>
              <mu2>1.0</mu2>
<!--              <slip1>0.0</slip1>
              <slip2>0.0</slip2> -->
            </ode>
          </friction>
        </surface>
      </collision>
      <visual name="visual">
        <geometry>
          <cylinder>
            <radius>0.05</radius>
            <length>0.025</length>
          </cylinder>
        </geometry>
        <material>
          <script>
            <uri>file://media/materials/scripts/gazebo.material</uri>
            <name>Gazebo/FlatBlack</name>
          </script>
        </material>
      </visual>
    </link>
    <!--  ----------------------------  -->
    <joint type="revolute" name="rear_left_wheel_hinge">
      <pose>0 0 0.01 0 0 0</pose>
      <child>rear_left_wheel</child>
      <parent>RL2</parent>
      <axis>
        <xyz>0 0 1</xyz>
      </axis>
<!--
      <sensor name="force_torque_rear_left_wheel_hinge" type="force_torque">
        <update_rate>1</update_rate>
        <force_torque>
          <frame>child</frame>
          <measure_direction>child_to_parent</measure_direction>
        </force_torque>
      </sensor>
-->
    </joint>
    <!--  ----------------------------  -->
    <plugin filename="libQuadrupedMotion.so" name="QuadrupedMotion">
      <J_FR_B20>J_FR_B20</J_FR_B20>
      <J_FR_021>J_FR_021</J_FR_021>
      <J_FR_122>J_FR_122</J_FR_122>
      <J_FL_B20>J_FL_B20</J_FL_B20>
      <J_FL_021>J_FL_021</J_FL_021>
      <J_FL_122>J_FL_122</J_FL_122>
      <J_RR_B20>J_RR_B20</J_RR_B20>
      <J_RR_021>J_RR_021</J_RR_021>
      <J_RR_122>J_RR_122</J_RR_122>
      <J_RL_B20>J_RL_B20</J_RL_B20>
      <J_RL_021>J_RL_021</J_RL_021>
      <J_RL_122>J_RL_122</J_RL_122>
    </plugin>
    <!--  ----------------------------  -->
    <plugin name="SkidSteerPluginFourlegsWheeled" filename="libSkidSteerPluginFourlegsWheeled.so">
      <right_front>front_right_wheel_hinge</right_front>
      <right_rear>rear_right_wheel_hinge</right_rear>
      <left_front>front_left_wheel_hinge</left_front>
      <left_rear>rear_left_wheel_hinge</left_rear>
      <MaxForce>5.0</MaxForce>
    </plugin>
    <!--  ----------------------------  -->
  </model>
</sdf>
