<?xml version="1.0" ?>
<sdf version="1.5">
  <model name="spring">
    <pose>0 0 0  0 0 0</pose>
    <static>0</static>

    <link name="head1">
      <pose>0 0 0.005 0 0 0</pose>
      <visual name="visual">
        <geometry>
          <box> <size>0.01 0.01 0.01</size> </box>
        </geometry>
      </visual>
      <collision name="visual">
        <geometry>
          <box> <size>0.01 0.01 0.01</size> </box>
        </geometry>
      </collision>
    </link>

    <link name="head2">
      <pose> 0 0 0.095 0 0 0 </pose>
      <visual name="visual">
        <geometry>
          <box> <size>0.01 0.01 0.01</size> </box>
        </geometry>
      </visual>
      <collision name="visual">
        <geometry>
          <box> <size>0.01 0.01 0.01 </size> </box>
        </geometry>
      </collision>
    </link>

    <joint type="prismatic" name="spring">
      <child>head1</child>
      <parent>head2</parent>
      <axis>
        <limit>
          <lower>0.01</lower>
          <upper>0.09</upper>
        </limit>
        <xyz>0 0 1</xyz>
      </axis>
    </joint>

    <plugin filename="libSpring.so" name="Spring">
      <joint_name>spring</joint_name>
      <spring_constant>500</spring_constant>
    </plugin>

  </model>
</sdf>
