<?xml version="1.0" ?>
<robot name="robot">
  <joint name="camera_joint" type="fixed">
    <parent link="base_link"/>
    <child link="camera_link"/>
    <origin rpy="0    0   -1.57" xyz="0    0    0.22"/>
    <axis xyz="0  0  1"/>
    <limit effort="0.0" lower="0.0" upper="0.0" velocity="0.0"/>
  </joint>
  <joint name="hokuyo_joint" type="fixed">
    <parent link="base_link"/>
    <child link="hokuyo_link"/>
    <origin rpy="0    0   -1.57" xyz="0     0     0.135"/>
    <axis xyz="0  0  1"/>
    <limit effort="0.0" lower="0.0" upper="0.0" velocity="0.0"/>
  </joint>
  <joint name="right_rear" type="fixed">
    <parent link="base_link"/>
    <child link="right_rear_wheel"/>
    <origin rpy="3.14159  1.57079  3.14159" xyz="-0.05  0.15  0.05"/>
    <axis xyz="0  0  1"/>
    <limit effort="0" lower="0" upper="0" velocity="0"/>
  </joint>
  <joint name="right_front" type="fixed">
    <parent link="base_link"/>
    <child link="right_front_wheel"/>
    <origin rpy="3.14159  1.57079  3.14159" xyz="-0.05 -0.15  0.05"/>
    <axis xyz="0  0  1"/>
    <limit effort="0" lower="0" upper="0" velocity="0"/>
  </joint>
  <joint name="right_center1" type="fixed">
    <parent link="base_link"/>
    <child link="right_center_wheel_1"/>
    <origin rpy="3.14159  1.57079  3.14159" xyz="-0.05  0.05  0.05"/>
    <axis xyz="0  0  1"/>
    <limit effort="0" lower="0" upper="0" velocity="0"/>
  </joint>
  <joint name="right_center2" type="fixed">
    <parent link="base_link"/>
    <child link="right_center_wheel_2"/>
    <origin rpy="3.14159  1.57079  3.14159" xyz="-0.05   0     0.049"/>
    <axis xyz="0  0  1"/>
    <limit effort="0" lower="0" upper="0" velocity="0"/>
  </joint>
  <joint name="right_center3" type="fixed">
    <parent link="base_link"/>
    <child link="right_center_wheel_3"/>
    <origin rpy="3.14159  1.57079  3.14159" xyz="-0.05 -0.05  0.05"/>
    <axis xyz="0  0  1"/>
    <limit effort="0" lower="0" upper="0" velocity="0"/>
  </joint>
  <joint name="right_sub2" type="fixed">
    <parent link="base_link"/>
    <child link="right_sub_wheel_2"/>
    <origin rpy="3.14159  1.57079  3.14159" xyz="-0.15  0.1   0.05"/>
    <axis xyz="0  0  1"/>
    <limit effort="0" lower="0" upper="0" velocity="0"/>
  </joint>
  <joint name="right_sub3" type="fixed">
    <parent link="base_link"/>
    <child link="right_sub_wheel_3"/>
    <origin rpy="3.14159  1.57079  3.14159" xyz="-0.15 -0.1   0.05"/>
    <axis xyz="0  0  1"/>
    <limit effort="0" lower="0" upper="0" velocity="0"/>
  </joint>
  <joint name="left_rear" type="fixed">
    <parent link="base_link"/>
    <child link="left_rear_wheel"/>
    <origin rpy="3.14159  1.57079  3.14159" xyz="0.05  0.15  0.05"/>
    <axis xyz="0  0  1"/>
    <limit effort="0" lower="0" upper="0" velocity="0"/>
  </joint>
  <joint name="left_front" type="fixed">
    <parent link="base_link"/>
    <child link="left_front_wheel"/>
    <origin rpy="3.14159  1.57079  3.14159" xyz="0.05 -0.15  0.05"/>
    <axis xyz="0  0  1"/>
    <limit effort="0" lower="0" upper="0" velocity="0"/>
  </joint>
  <joint name="left_center1" type="fixed">
    <parent link="base_link"/>
    <child link="left_center_wheel_1"/>
    <origin rpy="3.14159  1.57079  3.14159" xyz="0.05  0.05  0.05"/>
    <axis xyz="0  0  1"/>
    <limit effort="0" lower="0" upper="0" velocity="0"/>
  </joint>
  <joint name="left_center2" type="fixed">
    <parent link="base_link"/>
    <child link="left_center_wheel_2"/>
    <origin rpy="3.14159  1.57079  3.14159" xyz="0.05   0     0.049"/>
    <axis xyz="0  0  1"/>
    <limit effort="0" lower="0" upper="0" velocity="0"/>
  </joint>
  <joint name="left_center3" type="fixed">
    <parent link="base_link"/>
    <child link="left_center_wheel_3"/>
    <origin rpy="3.14159  1.57079  3.14159" xyz="0.05 -0.05  0.05"/>
    <axis xyz="0  0  1"/>
    <limit effort="0" lower="0" upper="0" velocity="0"/>
  </joint>
  <joint name="left_sub2" type="fixed">
    <parent link="base_link"/>
    <child link="left_sub_wheel_2"/>
    <origin rpy="3.14159  1.57079  3.14159" xyz="0.05  0.1   0.05"/>
    <axis xyz="0  0  1"/>
    <limit effort="0" lower="0" upper="0" velocity="0"/>
  </joint>
  <joint name="left_sub3" type="fixed">
    <parent link="base_link"/>
    <child link="left_sub_wheel_3"/>
    <origin rpy="3.14159  1.57079  3.14159" xyz="0.05 -0.1   0.05"/>
    <axis xyz="0  0  1"/>
    <limit effort="0" lower="0" upper="0" velocity="0"/>
  </joint>
  <joint name="left_rear_arm_joint" type="revolute">
    <parent link="base_link"/>
    <child link="left_rear_arm"/>
    <origin rpy="0  0  0" xyz="0.151  0.15   0.051"/>
    <axis xyz="1  0  0"/>
    <limit effort="0.0" lower="-3.14" upper="3.14" velocity="1.0"/>
  </joint>
  <joint name="right_rear_arm_joint" type="revolute">
    <parent link="base_link"/>
    <child link="right_rear_arm"/>
    <origin rpy="0  0  0" xyz="-0.151  0.15   0.049"/>
    <axis xyz="1  0  0"/>
    <limit effort="0.0" lower="-3.14" upper="3.14" velocity="1.0"/>
  </joint>
  <joint name="left_front_arm_joint" type="revolute">
    <parent link="base_link"/>
    <child link="left_front_arm"/>
    <origin rpy="0  0  0" xyz="0.151 -0.15   0.051"/>
    <axis xyz="1  0  0"/>
    <limit effort="0.0" lower="-3.14" upper="3.14" velocity="1.0"/>
  </joint>
  <joint name="right_front_arm_joint" type="revolute">
    <parent link="base_link"/>
    <child link="right_front_arm"/>
    <origin rpy="0  0  0" xyz="-0.151 -0.15   0.049"/>
    <axis xyz="1  0  0"/>
    <limit effort="0.0" lower="-3.14" upper="3.14" velocity="1.0"/>
  </joint>
  <joint name="right_rear_arm_wheel_1" type="fixed">
    <parent link="right_rear_arm"/>
    <child link="right_rear_arm_wheel_1"/>
    <origin rpy="3.14159  1.57079  3.14159" xyz="0     0     0.001"/>
    <axis xyz="0  0  1"/>
    <limit effort="0" lower="0" upper="0" velocity="0"/>
  </joint>
  <joint name="right_rear_arm_wheel_2" type="fixed">
    <parent link="right_rear_arm"/>
    <child link="right_rear_arm_wheel_2"/>
    <origin rpy="3.14159  1.57079  3.14159" xyz="0     0.15   0.001"/>
    <axis xyz="0  0  1"/>
    <limit effort="0" lower="0" upper="0" velocity="0"/>
  </joint>
  <joint name="right_rear_arm_wheel_3" type="fixed">
    <parent link="right_rear_arm"/>
    <child link="right_rear_arm_wheel_3"/>
    <origin rpy="3.14159  1.57079  3.14159" xyz="0     0.075  0.001"/>
    <axis xyz="0  0  1"/>
    <limit effort="0" lower="0" upper="0" velocity="0"/>
  </joint>
  <joint name="right_front_arm_wheel_1" type="fixed">
    <parent link="right_front_arm"/>
    <child link="right_front_arm_wheel_1"/>
    <origin rpy="3.14159  1.57079  3.14159" xyz="0     0     0.001"/>
    <axis xyz="0  0  1"/>
    <limit effort="0" lower="0" upper="0" velocity="0"/>
  </joint>
  <joint name="right_front_arm_wheel_2" type="fixed">
    <parent link="right_front_arm"/>
    <child link="right_front_arm_wheel_2"/>
    <origin rpy="3.14159  1.57079  3.14159" xyz="0    -0.15   0.001"/>
    <axis xyz="0  0  1"/>
    <limit effort="0" lower="0" upper="0" velocity="0"/>
  </joint>
  <joint name="right_front_arm_wheel_3" type="fixed">
    <parent link="right_front_arm"/>
    <child link="right_front_arm_wheel_3"/>
    <origin rpy="3.14159  1.57079  3.14159" xyz="0    -0.075  0.001"/>
    <axis xyz="0  0  1"/>
    <limit effort="0" lower="0" upper="0" velocity="0"/>
  </joint>
  <joint name="left_rear_arm_wheel_1" type="fixed">
    <parent link="left_rear_arm"/>
    <child link="left_rear_arm_wheel_1"/>
    <origin rpy="3.14159  1.57079  3.14159" xyz="0     0    -0.001"/>
    <axis xyz="0  0  1"/>
    <limit effort="0" lower="0" upper="0" velocity="0"/>
  </joint>
  <joint name="left_rear_arm_wheel_2" type="fixed">
    <parent link="left_rear_arm"/>
    <child link="left_rear_arm_wheel_2"/>
    <origin rpy="3.14159  1.57079  3.14159" xyz="0     0.15  -0.001"/>
    <axis xyz="0  0  1"/>
    <limit effort="0" lower="0" upper="0" velocity="0"/>
  </joint>
  <joint name="left_rear_arm_wheel_3" type="fixed">
    <parent link="left_rear_arm"/>
    <child link="left_rear_arm_wheel_3"/>
    <origin rpy="3.14159  1.57079  3.14159" xyz="0     0.075 -0.001"/>
    <axis xyz="0  0  1"/>
    <limit effort="0" lower="0" upper="0" velocity="0"/>
  </joint>
  <joint name="left_front_arm_wheel_1" type="fixed">
    <parent link="left_front_arm"/>
    <child link="left_front_arm_wheel_1"/>
    <origin rpy="3.14159  1.57079  3.14159" xyz="0     0    -0.001"/>
    <axis xyz="0  0  1"/>
    <limit effort="0" lower="0" upper="0" velocity="0"/>
  </joint>
  <joint name="left_front_arm_wheel_2" type="fixed">
    <parent link="left_front_arm"/>
    <child link="left_front_arm_wheel_2"/>
    <origin rpy="3.14159  1.57079  3.14159" xyz="0    -0.15  -0.001"/>
    <axis xyz="0  0  1"/>
    <limit effort="0" lower="0" upper="0" velocity="0"/>
  </joint>
  <joint name="left_front_arm_wheel_3" type="fixed">
    <parent link="left_front_arm"/>
    <child link="left_front_arm_wheel_3"/>
    <origin rpy="3.14159  1.57079  3.14159" xyz="0    -0.075 -0.001"/>
    <axis xyz="0  0  1"/>
    <limit effort="0" lower="0" upper="0" velocity="0"/>
  </joint>
  <link name="base_link">
    <inertial>
      <mass value="20"/>
      <origin rpy="0  0  0" xyz="0    0    0.05"/>
      <inertia ixx="1.696e-01" ixy="0" ixz="0" iyy="2.176e-02" iyz="0" izz="1.7984e-01"/>
    </inertial>
    <collision name="collision">
      <origin rpy="0  0  0" xyz="0    0    0.05"/>
      <geometry>
        <box size=".1 .32 .06"/>
      </geometry>
    </collision>
    <visual name="visual">
      <origin rpy="0  0  0" xyz="0    0    0.05"/>
      <geometry>
        <box size=".1 .32 .06"/>
      </geometry>
    </visual>
    <visual name="crawler_visual_R">
      <origin rpy="0       0       1.57079" xyz="-0.08    -0.00075  0.05"/>
      <geometry>
        <mesh filename="package://crawler_robot_ros/meshes/crawler_robot_ros/crawler.dae" scale="1.0 1.0 1.0"/>
      </geometry>
    </visual>
    <visual name="crawler_visual_L">
      <origin rpy="0       0       1.57079" xyz="0.08    -0.00075  0.05"/>
      <geometry>
        <mesh filename="package://crawler_robot_ros/meshes/crawler_robot_ros/crawler.dae" scale="1.0 1.0 1.0"/>
      </geometry>
    </visual>
  </link>
  <link name="camera_link">
    <inertial>
      <mass value="0.1"/>
      <origin rpy="0  0  0" xyz="0  0  0"/>
      <inertia ixx="0.000166667" ixy="0" ixz="0" iyy="0.000166667" iyz="0" izz="0.000166667"/>
    </inertial>
    <collision name="collision-box">
      <origin rpy="0  0  0" xyz="-0.01  0    0"/>
      <geometry>
        <box size="0.08 0.1 0.1"/>
      </geometry>
    </collision>
    <collision name="collision-lens">
      <origin rpy="0    1.57  0" xyz="0.04  0    0"/>
      <geometry>
        <cylinder length="0.02" radius="0.03"/>
      </geometry>
    </collision>
    <visual name="visual-box">
      <origin rpy="0  0  0" xyz="-0.01  0    0"/>
      <geometry>
        <box size="0.08 0.1 0.1"/>
      </geometry>
    </visual>
    <visual name="visual-lens">
      <origin rpy="0    1.57  0" xyz="0.04  0    0"/>
      <geometry>
        <cylinder length="0.02" radius="0.03"/>
      </geometry>
    </visual>
  </link>
  <link name="hokuyo_link">
    <inertial>
      <mass value="0.1"/>
      <origin rpy="0  0  0" xyz="0  0  0"/>
      <inertia ixx="0.6205208333e-04" ixy="0" ixz="0" iyy="0.6205208333e-04" iyz="0" izz="4.1927083333e-05"/>
    </inertial>
    <collision name="collision-base">
      <origin rpy="0  0  0" xyz="0      0     -0.0145"/>
      <geometry>
        <box size="0.05 0.05 0.041"/>
      </geometry>
    </collision>
    <collision name="collision-top">
      <origin rpy="0  0  0" xyz="0      0      0.0205"/>
      <geometry>
        <cylinder length="0.029" radius="0.021"/>
      </geometry>
    </collision>
    <visual name="visual-base">
      <origin rpy="0  0  0" xyz="0      0     -0.0145"/>
      <geometry>
        <box size="0.05 0.05 0.041"/>
      </geometry>
    </visual>
    <visual name="visual-top">
      <origin rpy="0  0  0" xyz="0      0      0.0205"/>
      <geometry>
        <cylinder length="0.029" radius="0.021"/>
      </geometry>
    </visual>
  </link>
  <link name="right_rear_wheel">
    <inertial>
      <mass value="1.0"/>
      <origin rpy="0  0  0" xyz="0    0   -0.05"/>
      <inertia ixx="1.3744467859e-03" ixy="0" ixz="0" iyy="1.3744467859e-03" iyz="0" izz="11.780972451e-04"/>
    </inertial>
    <collision name="collision">
      <origin rpy="0  0  0" xyz="0    0   -0.05"/>
      <geometry>
        <cylinder length=".1" radius=".05"/>
      </geometry>
    </collision>
    <visual name="visual">
      <origin rpy="0  0  0" xyz="0    0   -0.05"/>
      <geometry>
        <cylinder length=".1" radius=".05"/>
      </geometry>
    </visual>
  </link>
  <link name="right_front_wheel">
    <inertial>
      <mass value="1.0"/>
      <origin rpy="0  0  0" xyz="0    0   -0.05"/>
      <inertia ixx="1.3744467859e-03" ixy="0" ixz="0" iyy="1.3744467859e-03" iyz="0" izz="11.780972451e-04"/>
    </inertial>
    <collision name="collision">
      <origin rpy="0  0  0" xyz="0    0   -0.05"/>
      <geometry>
        <cylinder length=".1" radius=".05"/>
      </geometry>
    </collision>
    <visual name="visual">
      <origin rpy="0  0  0" xyz="0    0   -0.05"/>
      <geometry>
        <cylinder length=".1" radius=".05"/>
      </geometry>
    </visual>
  </link>
  <link name="right_center_wheel_1">
    <inertial>
      <mass value="1.0"/>
      <origin rpy="0  0  0" xyz="0    0   -0.05"/>
      <inertia ixx="7.5267323992e-04" ixy="0" ixz="0" iyy="7.5267323992e-04" iyz="0" izz="11.2900985988e-04"/>
    </inertial>
    <collision name="collision">
      <origin rpy="0  0  0" xyz="0    0   -0.05"/>
      <geometry>
        <cylinder length=".05" radius=".05"/>
      </geometry>
    </collision>
  </link>
  <link name="right_center_wheel_2">
    <inertial>
      <mass value="1.0"/>
      <origin rpy="0  0  0" xyz="0    0   -0.05"/>
      <inertia ixx="7.5267323992e-04" ixy="0" ixz="0" iyy="7.5267323992e-04" iyz="0" izz="11.2900985988e-04"/>
    </inertial>
    <collision name="collision">
      <origin rpy="0  0  0" xyz="0    0   -0.05"/>
      <geometry>
        <cylinder length=".05" radius=".05"/>
      </geometry>
    </collision>
  </link>
  <link name="right_center_wheel_3">
    <inertial>
      <mass value="1.0"/>
      <origin rpy="0  0  0" xyz="0    0   -0.05"/>
      <inertia ixx="7.5267323992e-04" ixy="0" ixz="0" iyy="7.5267323992e-04" iyz="0" izz="11.2900985988e-04"/>
    </inertial>
    <collision name="collision">
      <origin rpy="0  0  0" xyz="0    0   -0.05"/>
      <geometry>
        <cylinder length=".05" radius=".05"/>
      </geometry>
    </collision>
  </link>
  <link name="right_sub_wheel_2">
    <inertial>
      <mass value="1.0"/>
      <origin rpy="0  0  0" xyz="0    0    0.05"/>
      <inertia ixx="1.3744467859e-03" ixy="0" ixz="0" iyy="1.3744467859e-03" iyz="0" izz="11.780972451e-04"/>
    </inertial>
    <collision name="collision">
      <origin rpy="0  0  0" xyz="0    0    0.05"/>
      <geometry>
        <cylinder length=".1" radius=".05"/>
      </geometry>
    </collision>
  </link>
  <link name="right_sub_wheel_3">
    <inertial>
      <mass value="1.0"/>
      <origin rpy="0  0  0" xyz="0    0    0.05"/>
      <inertia ixx="1.3744467859e-03" ixy="0" ixz="0" iyy="1.3744467859e-03" iyz="0" izz="11.780972451e-04"/>
    </inertial>
    <collision name="collision">
      <origin rpy="0  0  0" xyz="0    0    0.05"/>
      <geometry>
        <cylinder length=".1" radius=".05"/>
      </geometry>
    </collision>
  </link>
  <link name="left_rear_wheel">
    <inertial>
      <mass value="1.0"/>
      <origin rpy="0  0  0" xyz="0    0    0.05"/>
      <inertia ixx="1.3744467859e-03" ixy="0" ixz="0" iyy="1.3744467859e-03" iyz="0" izz="11.780972451e-04"/>
    </inertial>
    <collision name="collision">
      <origin rpy="0  0  0" xyz="0    0    0.05"/>
      <geometry>
        <cylinder length=".1" radius=".05"/>
      </geometry>
    </collision>
    <visual name="visual">
      <origin rpy="0  0  0" xyz="0    0    0.05"/>
      <geometry>
        <cylinder length=".1" radius=".05"/>
      </geometry>
    </visual>
  </link>
  <link name="left_front_wheel">
    <inertial>
      <mass value="1.0"/>
      <origin rpy="0  0  0" xyz="0    0    0.05"/>
      <inertia ixx="1.3744467859e-03" ixy="0" ixz="0" iyy="1.3744467859e-03" iyz="0" izz="11.780972451e-04"/>
    </inertial>
    <collision name="collision">
      <origin rpy="0  0  0" xyz="0    0    0.05"/>
      <geometry>
        <cylinder length=".1" radius=".05"/>
      </geometry>
    </collision>
    <visual name="visual">
      <origin rpy="0  0  0" xyz="0    0    0.05"/>
      <geometry>
        <cylinder length=".1" radius=".05"/>
      </geometry>
    </visual>
  </link>
  <link name="left_center_wheel_1">
    <inertial>
      <mass value="1.0"/>
      <origin rpy="0  0  0" xyz="0    0    0.05"/>
      <inertia ixx="7.5267323992e-04" ixy="0" ixz="0" iyy="7.5267323992e-04" iyz="0" izz="11.2900985988e-04"/>
    </inertial>
    <collision name="collision">
      <origin rpy="0  0  0" xyz="0    0    0.05"/>
      <geometry>
        <cylinder length=".05" radius=".05"/>
      </geometry>
    </collision>
  </link>
  <link name="left_center_wheel_2">
    <inertial>
      <mass value="1.0"/>
      <origin rpy="0  0  0" xyz="0    0    0.05"/>
      <inertia ixx="7.5267323992e-04" ixy="0" ixz="0" iyy="7.5267323992e-04" iyz="0" izz="11.2900985988e-04"/>
    </inertial>
    <collision name="collision">
      <origin rpy="0  0  0" xyz="0    0    0.05"/>
      <geometry>
        <cylinder length=".05" radius=".05"/>
      </geometry>
    </collision>
  </link>
  <link name="left_center_wheel_3">
    <inertial>
      <mass value="1.0"/>
      <origin rpy="0  0  0" xyz="0    0    0.05"/>
      <inertia ixx="7.5267323992e-04" ixy="0" ixz="0" iyy="7.5267323992e-04" iyz="0" izz="11.2900985988e-04"/>
    </inertial>
    <collision name="collision">
      <origin rpy="0  0  0" xyz="0    0    0.05"/>
      <geometry>
        <cylinder length=".05" radius=".05"/>
      </geometry>
    </collision>
  </link>
  <link name="left_sub_wheel_2">
    <inertial>
      <mass value="1.0"/>
      <origin rpy="0  0  0" xyz="0    0    0.05"/>
      <inertia ixx="1.3744467859e-03" ixy="0" ixz="0" iyy="1.3744467859e-03" iyz="0" izz="11.780972451e-04"/>
    </inertial>
    <collision name="collision">
      <origin rpy="0  0  0" xyz="0    0    0.05"/>
      <geometry>
        <cylinder length=".1" radius=".05"/>
      </geometry>
    </collision>
  </link>
  <link name="left_sub_wheel_3">
    <inertial>
      <mass value="1.0"/>
      <origin rpy="0  0  0" xyz="0    0    0.05"/>
      <inertia ixx="1.3744467859e-03" ixy="0" ixz="0" iyy="1.3744467859e-03" iyz="0" izz="11.780972451e-04"/>
    </inertial>
    <collision name="collision">
      <origin rpy="0  0  0" xyz="0    0    0.05"/>
      <geometry>
        <cylinder length=".1" radius=".05"/>
      </geometry>
    </collision>
  </link>
  <link name="right_rear_arm">
    <inertial>
      <mass value="1.0"/>
      <origin rpy="1.57  0    1.57" xyz="-0.015  0.075  0.001"/>
      <inertia ixx="6.8125e-4" ixy="0" ixz="0" iyy="3.96253e-3" iyz="0" izz="4.53125e-3"/>
    </inertial>
    <visual name="visual">
      <origin rpy="0  0  0" xyz="0     0.075  0.001"/>
      <geometry>
        <box size=".002 .16 .05"/>
      </geometry>
    </visual>
    <visual name="crawler_visual">
      <origin rpy="0    0    1.57" xyz="-0.015  0.075 -0.049"/>
      <geometry>
        <mesh filename="package://crawler_robot_ros/meshes/crawler_robot_ros/arm_crawler_2.dae" scale="1.0 1.0 1.0"/>
      </geometry>
    </visual>
  </link>
  <link name="right_rear_arm_wheel_1">
    <inertial>
      <mass value="1.0"/>
      <origin rpy="0  0  0" xyz="0     0    -0.015"/>
      <inertia ixx="6.2674773439e-04" ixy="0" ixz="0" iyy="6.2674773439e-04" iyz="0" izz="11.1919238284e-04"/>
    </inertial>
    <collision name="collision">
      <origin rpy="0  0  0" xyz="0     0    -0.015"/>
      <geometry>
        <cylinder length=".03" radius=".05"/>
      </geometry>
    </collision>
    <visual name="visual">
      <origin rpy="0  0  0" xyz="0     0    -0.015"/>
      <geometry>
        <cylinder length=".03" radius=".05"/>
      </geometry>
    </visual>
  </link>
  <link name="right_rear_arm_wheel_2">
    <inertial>
      <mass value="1.0"/>
      <origin rpy="0  0  0" xyz="0     0    -0.015"/>
      <inertia ixx="6.2674773439e-04" ixy="0" ixz="0" iyy="6.2674773439e-04" iyz="0" izz="11.1919238284e-04"/>
    </inertial>
    <collision name="collision">
      <origin rpy="0  0  0" xyz="0     0    -0.015"/>
      <geometry>
        <cylinder length=".03" radius=".05"/>
      </geometry>
    </collision>
    <visual name="visual">
      <origin rpy="0  0  0" xyz="0     0    -0.015"/>
      <geometry>
        <cylinder length=".03" radius=".05"/>
      </geometry>
    </visual>
  </link>
  <link name="right_rear_arm_wheel_3">
    <inertial>
      <mass value="1.0"/>
      <origin rpy="0  0  0" xyz="0     0    -0.015"/>
      <inertia ixx="6.2674773439e-04" ixy="0" ixz="0" iyy="6.2674773439e-04" iyz="0" izz="11.1919238284e-04"/>
    </inertial>
    <collision name="collision">
      <origin rpy="0  0  0" xyz="0     0    -0.015"/>
      <geometry>
        <cylinder length=".03" radius=".05"/>
      </geometry>
    </collision>
  </link>
  <link name="left_rear_arm">
    <inertial>
      <mass value="1.0"/>
      <origin rpy="1.57  0    1.57" xyz="0.015  0.075 -0.001"/>
      <inertia ixx="6.8125e-4" ixy="0" ixz="0" iyy="3.96253e-3" iyz="0" izz="4.53125e-3"/>
    </inertial>
    <visual name="visual">
      <origin rpy="0  0  0" xyz="0     0.075 -0.001"/>
      <geometry>
        <box size=".002 .16 .05"/>
      </geometry>
    </visual>
    <visual name="crawler_visual">
      <origin rpy="0    0    1.57" xyz="0.015  0.075 -0.051"/>
      <geometry>
        <mesh filename="package://crawler_robot_ros/meshes/crawler_robot_ros/arm_crawler_2.dae" scale="1.0 1.0 1.0"/>
      </geometry>
    </visual>
  </link>
  <link name="left_rear_arm_wheel_1">
    <inertial>
      <mass value="1.0"/>
      <origin rpy="0  0  0" xyz="0     0     0.015"/>
      <inertia ixx="6.2674773439e-04" ixy="0" ixz="0" iyy="6.2674773439e-04" iyz="0" izz="11.1919238284e-04"/>
    </inertial>
    <collision name="collision">
      <origin rpy="0  0  0" xyz="0     0     0.015"/>
      <geometry>
        <cylinder length=".03" radius=".05"/>
      </geometry>
    </collision>
    <visual name="visual">
      <origin rpy="0  0  0" xyz="0     0     0.015"/>
      <geometry>
        <cylinder length=".03" radius=".05"/>
      </geometry>
    </visual>
  </link>
  <link name="left_rear_arm_wheel_2">
    <inertial>
      <mass value="1.0"/>
      <origin rpy="0  0  0" xyz="0     0     0.015"/>
      <inertia ixx="6.2674773439e-04" ixy="0" ixz="0" iyy="6.2674773439e-04" iyz="0" izz="11.1919238284e-04"/>
    </inertial>
    <collision name="collision">
      <origin rpy="0  0  0" xyz="0     0     0.015"/>
      <geometry>
        <cylinder length=".03" radius=".05"/>
      </geometry>
    </collision>
    <visual name="visual">
      <origin rpy="0  0  0" xyz="0     0     0.015"/>
      <geometry>
        <cylinder length=".03" radius=".05"/>
      </geometry>
    </visual>
  </link>
  <link name="left_rear_arm_wheel_3">
    <inertial>
      <mass value="1.0"/>
      <origin rpy="0  0  0" xyz="0     0     0.015"/>
      <inertia ixx="6.2674773439e-04" ixy="0" ixz="0" iyy="6.2674773439e-04" iyz="0" izz="11.1919238284e-04"/>
    </inertial>
    <collision name="collision">
      <origin rpy="0  0  0" xyz="0     0     0.015"/>
      <geometry>
        <cylinder length=".03" radius=".05"/>
      </geometry>
    </collision>
  </link>
  <link name="right_front_arm">
    <inertial>
      <mass value="1.0"/>
      <origin rpy="1.57  0    1.57" xyz="-0.015 -0.075  0.001"/>
      <inertia ixx="6.8125e-4" ixy="0" ixz="0" iyy="3.96253e-3" iyz="0" izz="4.53125e-3"/>
    </inertial>
    <visual name="visual">
      <origin rpy="0  0  0" xyz="0    -0.075  0.001"/>
      <geometry>
        <box size=".002 .16 .05"/>
      </geometry>
    </visual>
    <visual name="crawler_visual">
      <origin rpy="0    0    1.57" xyz="-0.015 -0.075 -0.049"/>
      <geometry>
        <mesh filename="package://crawler_robot_ros/meshes/crawler_robot_ros/arm_crawler_2.dae" scale="1.0 1.0 1.0"/>
      </geometry>
    </visual>
  </link>
  <link name="right_front_arm_wheel_1">
    <inertial>
      <mass value="1.0"/>
      <origin rpy="0  0  0" xyz="0     0    -0.015"/>
      <inertia ixx="6.2674773439e-04" ixy="0" ixz="0" iyy="6.2674773439e-04" iyz="0" izz="11.1919238284e-04"/>
    </inertial>
    <collision name="collision">
      <origin rpy="0  0  0" xyz="0     0    -0.015"/>
      <geometry>
        <cylinder length=".03" radius=".05"/>
      </geometry>
    </collision>
    <visual name="visual">
      <origin rpy="0  0  0" xyz="0     0    -0.015"/>
      <geometry>
        <cylinder length=".03" radius=".05"/>
      </geometry>
    </visual>
  </link>
  <link name="right_front_arm_wheel_2">
    <inertial>
      <mass value="1.0"/>
      <origin rpy="0  0  0" xyz="0     0    -0.015"/>
      <inertia ixx="6.2674773439e-04" ixy="0" ixz="0" iyy="6.2674773439e-04" iyz="0" izz="11.1919238284e-04"/>
    </inertial>
    <collision name="collision">
      <origin rpy="0  0  0" xyz="0     0    -0.015"/>
      <geometry>
        <cylinder length=".03" radius=".05"/>
      </geometry>
    </collision>
    <visual name="visual">
      <origin rpy="0  0  0" xyz="0     0    -0.015"/>
      <geometry>
        <cylinder length=".03" radius=".05"/>
      </geometry>
    </visual>
  </link>
  <link name="right_front_arm_wheel_3">
    <inertial>
      <mass value="1.0"/>
      <origin rpy="0  0  0" xyz="0     0    -0.015"/>
      <inertia ixx="6.2674773439e-04" ixy="0" ixz="0" iyy="6.2674773439e-04" iyz="0" izz="11.1919238284e-04"/>
    </inertial>
    <collision name="collision">
      <origin rpy="0  0  0" xyz="0     0    -0.015"/>
      <geometry>
        <cylinder length=".03" radius=".05"/>
      </geometry>
    </collision>
  </link>
  <link name="left_front_arm">
    <inertial>
      <mass value="1.0"/>
      <origin rpy="1.57  0    1.57" xyz="0.015 -0.075 -0.001"/>
      <inertia ixx="6.8125e-4" ixy="0" ixz="0" iyy="3.96253e-3" iyz="0" izz="4.53125e-3"/>
    </inertial>
    <visual name="visual">
      <origin rpy="0  0  0" xyz="0    -0.075 -0.001"/>
      <geometry>
        <box size=".002 .16 .05"/>
      </geometry>
    </visual>
    <visual name="crawler_visual">
      <origin rpy="0    0    1.57" xyz="0.015 -0.075 -0.051"/>
      <geometry>
        <mesh filename="package://crawler_robot_ros/meshes/crawler_robot_ros/arm_crawler_2.dae" scale="1.0 1.0 1.0"/>
      </geometry>
    </visual>
  </link>
  <link name="left_front_arm_wheel_1">
    <inertial>
      <mass value="1.0"/>
      <origin rpy="0  0  0" xyz="0     0     0.015"/>
      <inertia ixx="6.2674773439e-04" ixy="0" ixz="0" iyy="6.2674773439e-04" iyz="0" izz="11.1919238284e-04"/>
    </inertial>
    <collision name="collision">
      <origin rpy="0  0  0" xyz="0     0     0.015"/>
      <geometry>
        <cylinder length=".03" radius=".05"/>
      </geometry>
    </collision>
    <visual name="visual">
      <origin rpy="0  0  0" xyz="0     0     0.015"/>
      <geometry>
        <cylinder length=".03" radius=".05"/>
      </geometry>
    </visual>
  </link>
  <link name="left_front_arm_wheel_2">
    <inertial>
      <mass value="1.0"/>
      <origin rpy="0  0  0" xyz="0     0     0.015"/>
      <inertia ixx="6.2674773439e-04" ixy="0" ixz="0" iyy="6.2674773439e-04" iyz="0" izz="11.1919238284e-04"/>
    </inertial>
    <collision name="collision">
      <origin rpy="0  0  0" xyz="0     0     0.015"/>
      <geometry>
        <cylinder length=".03" radius=".05"/>
      </geometry>
    </collision>
    <visual name="visual">
      <origin rpy="0  0  0" xyz="0     0     0.015"/>
      <geometry>
        <cylinder length=".03" radius=".05"/>
      </geometry>
    </visual>
  </link>
  <link name="left_front_arm_wheel_3">
    <inertial>
      <mass value="1.0"/>
      <origin rpy="0  0  0" xyz="0     0     0.015"/>
      <inertia ixx="6.2674773439e-04" ixy="0" ixz="0" iyy="6.2674773439e-04" iyz="0" izz="11.1919238284e-04"/>
    </inertial>
    <collision name="collision">
      <origin rpy="0  0  0" xyz="0     0     0.015"/>
      <geometry>
        <cylinder length=".03" radius=".05"/>
      </geometry>
    </collision>
  </link>
  <!-- TRANSMISSION for gazebo_ros_control -->
  <transmission name="right_front_arm_joint_transmssion">
    <type>transmission_interface/SimpleTransmission</type>
    <joint name="right_front_arm_joint">
      <hardwareInterface>hardware_interface/EffortJointInterface</hardwareInterface>
      <mechanicalReduction>1</mechanicalReduction>
    </joint>
    <actuator name="right_front_arm_joint_motor">
      <hardwareInterface>hardware_interface/EffortJointInterface</hardwareInterface>
      <mechanicalReduction>1</mechanicalReduction>
    </actuator>
  </transmission>
  <transmission name="right_rear_arm_joint_transmssion">
    <type>transmission_interface/SimpleTransmission</type>
    <joint name="right_rear_arm_joint">
      <hardwareInterface>hardware_interface/EffortJointInterface</hardwareInterface>
      <mechanicalReduction>1</mechanicalReduction>
    </joint>
    <actuator name="right_rear_arm_joint_motor">
      <hardwareInterface>hardware_interface/EffortJointInterface</hardwareInterface>
      <mechanicalReduction>1</mechanicalReduction>
    </actuator>
  </transmission>
  <transmission name="left_front_arm_joint_transmssion">
    <type>transmission_interface/SimpleTransmission</type>
    <joint name="left_front_arm_joint">
      <hardwareInterface>hardware_interface/EffortJointInterface</hardwareInterface>
      <mechanicalReduction>1</mechanicalReduction>
    </joint>
    <actuator name="left_front_arm_joint_motor">
      <hardwareInterface>hardware_interface/EffortJointInterface</hardwareInterface>
      <mechanicalReduction>1</mechanicalReduction>
    </actuator>
  </transmission>
  <transmission name="left_rear_arm_joint_transmssion">
    <type>transmission_interface/SimpleTransmission</type>
    <joint name="left_rear_arm_joint">
      <hardwareInterface>hardware_interface/EffortJointInterface</hardwareInterface>
      <mechanicalReduction>1</mechanicalReduction>
    </joint>
    <actuator name="left_rear_arm_joint_motor">
      <hardwareInterface>hardware_interface/EffortJointInterface</hardwareInterface>
      <mechanicalReduction>1</mechanicalReduction>
    </actuator>
  </transmission>
</robot>
