<?xml version="1.0" ?>
<sdf version="1.5">
  <model name="robot">
    <link name="base_link">
      <pose>0 0 0.16 0 0 0</pose>
      <inertial>
        <mass>5.67</mass>
        <inertia>
          <ixx>0.07</ixx>
          <iyy>0.08</iyy>
          <izz>0.10</izz>
          <ixy>0</ixy>
          <ixz>0</ixz>
          <iyz>0</iyz>
        </inertia>
      </inertial>
      <collision name="collision">
        <geometry>
          <box>
            <size>0.445 0.277 0.17</size>
          </box>
        </geometry>
      </collision>
      <collision name="castor_collision">
        <pose>-0.200 0 -0.12 0 0 0</pose>
        <geometry>
          <sphere>
            <radius>0.04</radius>
          </sphere>
        </geometry>
        <surface>
          <friction>
            <ode>
              <mu>0</mu>
              <mu2>0</mu2>
<!--              <slip1>1.0</slip1>
              <slip2>1.0</slip2> -->
            </ode>
          </friction>
        </surface>
      </collision>
      <visual name="visual">
        <pose>0 0 0.04 0 0 0</pose>
        <geometry>
          <mesh>
            <uri>model://pioneer2dx_ros/meshes/chassis.dae</uri>
          </mesh>
        </geometry>
      </visual>
      <visual name="castor_visual">
        <pose>-0.200 0 -0.12 0 0 0</pose>
        <geometry>
          <sphere>
            <radius>0.04</radius>
          </sphere>
        </geometry>
        <material>
          <script>
            <uri>file://media/materials/scripts/gazebo.material</uri>
            <name>Gazebo/FlatBlack</name>
          </script>
        </material>
      </visual>
    </link>
    <link name="right_wheel">
      <pose>0.1 -.17 0.11 0 1.5707 1.5707</pose>
      <inertial>
        <mass>1.5</mass>
        <inertia>
          <ixx>0.0051</ixx>
          <iyy>0.0051</iyy>
          <izz>0.0090</izz>
          <ixy>0</ixy>
          <ixz>0</ixz>
          <iyz>0</iyz>
        </inertia>
      </inertial>
      <collision name="collision">
        <geometry>
          <cylinder>
            <radius>0.11</radius>
            <length>0.05</length>
          </cylinder>
        </geometry>
        <surface>
          <friction>
            <ode>
              <mu>1.0</mu>
              <mu2>1.0</mu2>
<!--              <slip1>0.0</slip1>
              <slip2>0.0</slip2> -->
            </ode>
          </friction>
        </surface>
      </collision>
      <visual name="visual">
        <geometry>
          <cylinder>
            <radius>0.11</radius>
            <length>0.05</length>
          </cylinder>
        </geometry>
        <material>
          <script>
            <uri>file://media/materials/scripts/gazebo.material</uri>
            <name>Gazebo/FlatBlack</name>
          </script>
        </material>
      </visual>
    </link>
    <link name="left_wheel">
      <pose>0.1 .17 0.11 0 1.5707 1.5707</pose>
      <inertial>
        <mass>1.5</mass>
        <inertia>
          <ixx>0.0051</ixx>
          <iyy>0.0051</iyy>
          <izz>0.0090</izz>
          <ixy>0</ixy>
          <ixz>0</ixz>
          <iyz>0</iyz>
        </inertia>
      </inertial>
      <collision name="collision">
        <geometry>
          <cylinder>
            <radius>0.11</radius>
            <length>0.05</length>
          </cylinder>
        </geometry>
        <surface>
          <friction>
            <ode>
              <mu>1.0</mu>
              <mu2>1.0</mu2>
<!--              <slip1>0.0</slip1>
              <slip2>0.0</slip2> -->
            </ode>
          </friction>
        </surface>
      </collision>
      <visual name="visual">
        <geometry>
          <cylinder>
            <radius>0.11</radius>
            <length>0.05</length>
          </cylinder>
        </geometry>
        <material>
          <script>
            <uri>file://media/materials/scripts/gazebo.material</uri>
            <name>Gazebo/FlatBlack</name>
          </script>
        </material>
      </visual>
    </link>
    <joint type="revolute" name="left_wheel_hinge">
      <pose>0 0 -0.03 0 0 0</pose>
      <child>left_wheel</child>
      <parent>base_link</parent>
      <axis>
        <xyz>0 1 0</xyz>
        <use_parent_model_frame>true</use_parent_model_frame>
      </axis>
    </joint>
    <joint type="revolute" name="right_wheel_hinge">
      <pose>0 0 0.03 0 0 0</pose>
      <child>right_wheel</child>
      <parent>base_link</parent>
      <axis>
        <xyz>0 1 0</xyz>
        <use_parent_model_frame>true</use_parent_model_frame>
      </axis>
    </joint>

<!-- Camera (hight is 100mm) -->
<!-- Including model causes a trouble of RobotNameSpace in sdf version 1.5.
    <include>
      <name>camera</name>
      <pose>0.1 0 0.383 0 0 0</pose>
      <pose>0.1 0 0.22 0 0 0</pose> <= sample memo>
      <uri>model://camera_ros</uri>
    </include>

    <joint name="camera_joint" type="revolute">
      <parent>base_link</parent>
      <child>camera::camera_link</child>
      <pose>0 0 0 0 0 0</pose>
      <axis>
        <xyz>0 0 1</xyz>
        <limit>
          <lower>0</lower>
          <upper>0</upper>
        </limit>
      </axis>
    </joint>
-->
    <link name="camera_link">
      <pose>0.1 0 0.383 0 0 0</pose>
      <audio_sink /> <!-- Camera and microphone should be combined -->
      <inertial>
        <mass>0.1</mass>
        <inertia>
          <ixx>0.000166667</ixx>
          <iyy>0.000166667</iyy>
          <izz>0.000166667</izz>
        </inertia>
      </inertial>
      <collision name="collision-box">
        <pose>-0.01 0 0 0 0 0</pose>
        <geometry>
          <box>
            <size>0.08 0.1 0.1</size>
          </box>
        </geometry>
      </collision>
      <collision name="collision-lens">
        <pose>0.04 0 0 0 1.57 0</pose>
        <geometry>
          <cylinder>
            <radius>0.03</radius>
            <length>0.02</length>
          </cylinder>
        </geometry>
      </collision>
      <visual name="visual-box">
        <pose>-0.01 0 0 0 0 0</pose>
        <geometry>
          <box>
            <size>0.08 0.1 0.1</size>
          </box>
        </geometry>
        <material>
          <ambient>0.3 0.3 0.3 1</ambient>
          <diffuse>0.7 0.7 0.7 1</diffuse>
          <specular>0.1 0.1 0.1 1</specular>
          <emissive>0 0 0 0</emissive>
        </material>
      </visual>
      <visual name="visual-lens">
        <pose>0.04 0 0 0 1.57 0</pose>
        <geometry>
          <cylinder>
            <radius>0.03</radius>
            <length>0.02</length>
          </cylinder>
        </geometry>
        <material>
          <ambient>0 0 0 1</ambient>
          <diffuse>0 0 0 1</diffuse>
          <specular>0.1 0.1 0.1 1</specular>
          <emissive>0 0 0 0</emissive>
        </material>
      </visual>
<!-- RGB CAMERA --> 
      <sensor type="camera" name="camera">
        <update_rate>20</update_rate>
        <visualize>false</visualize>
        <camera name="camera">
          <horizontal_fov>1.047</horizontal_fov>
          <image>
            <width>320</width>
            <height>240</height>
            <format>R8G8B8</format>
          </image>
          <clip>
            <near>0.1</near>
            <far>100</far>
          </clip>
          <!-- Noise is sampled independently per pixel on each frame.
               That pixel's noise value is added to each of its color
               channels, which at that point lie in the range [0,1]. -->
          <noise>
            <type>gaussian</type>
            <mean>0.0</mean>
            <stddev>0.007</stddev>
          </noise>
        </camera>
        <plugin name="camera_controller" filename="libgazebo_ros_camera.so">
          <alwaysOn>true</alwaysOn>
          <updateRate>0.0</updateRate>
          <cameraName>camera/rgb</cameraName>
          <imageTopicName>image_raw</imageTopicName>
          <cameraInfoTopicName>camera_info</cameraInfoTopicName>
          <frameName>camera_link</frameName>
          <hackBaseline>0.07</hackBaseline>
          <distortionK1>0.0</distortionK1>
          <distortionK2>0.0</distortionK2>
          <distortionK3>0.0</distortionK3>
          <distortionT1>0.0</distortionT1>
          <distortionT2>0.0</distortionT2>
        </plugin>
      </sensor>
<!-- THERMAL CAMERA --> 
      <sensor type="camera" name="thermal_camera_sensor">
        <update_rate>10</update_rate>
        <camera name="camera_ros_thermal">
          <horizontal_fov>1.047</horizontal_fov>
          <image>
            <width>160</width>
            <height>120</height>
            <format>R8G8B8</format>
          </image>
          <clip>
            <near>0.1</near>
            <far>100</far>
          </clip>
<!--
          <noise>
            <type>gaussian</type>
            <mean>0.0</mean>
            <stddev>0.007</stddev>
          </noise>
-->
        </camera>
        <plugin name="thermal_camera_controller" 
                filename="libgazebo_ros_thermal_camera_pink.so">
          <alwaysOn>true</alwaysOn>
          <updateRate>10</updateRate>
          <imageTopicName>camera/thermal/image_raw</imageTopicName>
          <cameraInfoTopicName>camera/thermal/camera_info</cameraInfoTopicName>
          <frameName>camera_link</frameName>
<!-- Before ROS-Melodic, below was accepted by gazebo_ros_spawn
          <interface:camera name="thermal_camera_iface" />
-->
        </plugin>
      </sensor> 
    </link>
    <joint name="camera_joint" type="revolute">
      <parent>base_link</parent>
      <child>camera_link</child>
      <pose>0 0 0 0 0 0</pose>
      <axis>
        <xyz>0 0 1</xyz>
        <limit>
          <lower>0</lower>
          <upper>0</upper>
        </limit>
      </axis>
    </joint>
        
<!-- Hokuyo (hight is 70mm) -->
<!-- Including model causes a trouble of RobotNameSpace in sdf version 1.5.
    <include>
      <name>hokuyo</name>
      <pose>0.1 0 0.298 0 0 0</pose>
      <pose>0.1 0 0.135 0 0 0</pose> <= sample memo 
      <uri>model://hokuyo_ros</uri>
    </include>

    <joint name="hokuyo_joint" type="revolute">
      <parent>base_link</parent>
      <child>hokuyo::hokuyo_link</child>
      <pose>0 0 0 0 0 0</pose>
      <axis>
        <xyz>0 0 1</xyz>
        <limit>
          <lower>0</lower>
          <upper>0</upper>
        </limit>
      </axis>
    </joint>
-->
    <link name="hokuyo_link">
      <pose>0.1 0 0.298 0 0 0</pose>
      <inertial>
        <mass>0.1</mass>
        <inertia>
          <ixx>0.6205208333e-04</ixx>
          <iyy>0.6205208333e-04</iyy>
          <izz>4.1927083333e-05</izz>
        </inertia>
      </inertial>
      <visual name="visual-base">
        <pose>0 0 -0.0145 0 0 0</pose>
        <geometry>
          <box>
            <size>0.05 0.05 0.041</size>
          </box>
        </geometry>
        <material>
          <ambient>0.3 0.3 0.3 1</ambient>
          <diffuse>0.7 0.7 0.7 1</diffuse>
          <specular>0.1 0.1 0.1 1</specular>
          <emissive>0 0 0 0</emissive>
        </material>
      </visual>
      <visual name="visual-top">
        <pose>0 0 0.0205 0 0 0</pose>
        <geometry>
          <cylinder>
            <radius>0.021</radius>
            <length>0.029</length>
          </cylinder>
        </geometry>
        <material>
          <ambient>0 0 0 1</ambient>
          <diffuse>0 0 0 1</diffuse>
          <specular>0.1 0.1 0.1 1</specular>
          <emissive>0 0 0 0</emissive>
        </material>
      </visual>
      <visual name="visual-top-back">
        <pose>-0.02 0 0.019 0 0 0</pose>
        <geometry>
          <box>
            <size>0.01 0.01 0.025</size>
          </box>
        </geometry>
        <material>
          <ambient>0.1 0.1 0.1 1</ambient>
          <diffuse>0.3 0.3 0.3 1</diffuse>
          <specular>0.1 0.1 0.1 1</specular>
          <emissive>0 0 0 0</emissive>
        </material>
      </visual>
      <collision name="collision-base">
        <pose>0 0 -0.0145 0 0 0</pose>
        <geometry>
          <box>
            <size>0.05 0.05 0.041</size>
          </box>
        </geometry>
      </collision>
      <collision name="collision-top">
        <pose>0 0 0.0205 0 0 0</pose>
        <geometry>
          <cylinder>
            <radius>0.021</radius>
            <length>0.029</length>
          </cylinder>
        </geometry>
      </collision>
      <sensor type="ray" name="lms200">
        <always_on>true</always_on>
        <update_rate>30</update_rate>
        <pose>0 0 0.01815 0 0 0</pose> <!-- From URG04LX Spec -->
        <visualize>false</visualize>
        <ray>
          <scan>
            <horizontal>
              <samples>1040</samples>      <!-- 1040!!! -->
              <resolution>1</resolution>
              <min_angle>-2.268928</min_angle> <!-- 90deg: -1.570796 -->
              <max_angle>2.268928</max_angle>  <!-- 90deg: 1.570796  -->
            </horizontal>
          </scan>
          <range>
<!--            <min>0.20</min>  From URG04LX Spec -->
            <min>0.15</min>
            <max>5.6</max> <!-- From URG04LX Spec -->
            <resolution>0.001</resolution> <!-- From URG04LX Spec -->
          </range>
        </ray>
        <plugin name="gazebo_ros_hokuyo_controller" filename="libgazebo_ros_laser.so">
          <topicName>scan</topicName>
          <gaussianNoise>0.005</gaussianNoise>
          <alwaysOn>true</alwaysOn>
          <updateRate>30</updateRate>
          <frameName>hokuyo_link</frameName>
        </plugin>
      </sensor>
    </link>
    <joint name="hokuyo_joint" type="revolute">
      <parent>base_link</parent>
      <child>hokuyo_link</child>
      <pose>0 0 0 0 0 0</pose>
      <axis>
        <xyz>0 0 1</xyz>
        <limit>
          <lower>0</lower>
          <upper>0</upper>
        </limit>
      </axis>
    </joint>

    <plugin name="differential_drive_controller" filename="libgazebo_ros_diff_drive.so">
      <alwaysOn>true</alwaysOn>
      <updateRate>100.0</updateRate>
      <leftJoint>left_wheel_hinge</leftJoint>
      <rightJoint>right_wheel_hinge</rightJoint>
      <wheelSeparation>0.4</wheelSeparation>
      <wheelDiameter>0.215</wheelDiameter>
<!-- Following 2lines were came from gazebosim gazebo_ros topic page.
      <wheelSeparation>0.5380</wheelSeparation>
      <wheelDiameter>0.2410</wheelDiameter>
-->
      <robotBaseFrame>base_link</robotBaseFrame>
      <torque>200</torque>
      <commandTopic>cmd_vel</commandTopic>
      <odometryTopic>odom</odometryTopic>
      <odometryFrame>odom</odometryFrame>
      <broadcastTF>true</broadcastTF>

      <legacyMode>0</legacyMode>

    </plugin>

    <!-- Original libDiffDrivePlugin for sample
    <plugin filename="libDiffDrivePlugin_rc2016.so" name="diff_drive">
      <left_joint>left_wheel_hinge</left_joint>
      <right_joint>right_wheel_hinge</right_joint>
      <torque>5</torque>
    </plugin>
    -->

    <plugin name="gazebo_ros_control" filename="libgazebo_ros_control.so">
<!--      <robotParam>robot/robot_description</robotParam> -->
      <robotSimType>gazebo_ros_control/DefaultRobotHWSim</robotSimType>
    </plugin>

  </model>
</sdf>
