<?xml version='1.0'?>
<sdf version='1.5'>
  <model name="robot1">
    <static>false</static>
    <self_collide>0</self_collide>
<!--__________________body_____________________-->
    <link name='base_link'>
      <pose>0 0 .05 0 0 0</pose>
      <inertial>
        <mass>20</mass>
        <inertia>
          <ixx>1.696e-01</ixx>
          <iyy>2.176e-02</iyy>
          <izz>1.7984e-01</izz>
        </inertia>
      </inertial>

      <collision name='collision'>
        <geometry>
          <box>
            <size>.1 .32 .06</size>
          </box>
        </geometry>
      </collision>

      <visual name='visual'>
        <geometry>
          <box>
            <size>.1 .32 .06</size>
          </box>
        </geometry>
      </visual>
<!--__________________crawler_____________________-->
      <visual name="crawler_visual_R">
        <pose>-0.08 -0.00075 0 0 0 1.570796327</pose>
        <geometry>
          <mesh>
            <uri>model://crawler_robot_ros1/dae/crawler.dae</uri>
          </mesh>
        </geometry>
      </visual>
      <visual name="crawler_visual_L">
        <pose>0.08 -0.00075 0 0 0 1.570796327</pose>
        <geometry>
          <mesh>
            <uri>model://crawler_robot_ros1/dae/crawler.dae</uri>
          </mesh>
        </geometry>
      </visual>
<!-- IMU Sensor -->
      <sensor name="imu_sensor" type="imu">
        <pose>0 0 0 0 0 0</pose>
        <always_on>1</always_on>
        <update_rate>100</update_rate>
<!--  NOW update rate is set 10 tempolarity
        <update_rate>10</update_rate>
-->
        <imu>
<!--  NOW comment noise parameters out tempolary
          <noise>
            <type>gaussian</type>
            <rate>
              <mean>0</mean>
              <stddev>0.0002</stddev>
              <bias_mean>7.5e-06</bias_mean>
              <bias_stddev>8e-07</bias_stddev>
            </rate>
            <accel>
              <mean>0</mean>
              <stddev>0.017</stddev>
              <bias_mean>0.1</bias_mean>
              <bias_stddev>0.001</bias_stddev>
            </accel>
          </noise>
-->
        </imu>
      </sensor>
<!-- GPS sensor copied from gazebo-5.0.1/test/worlds/gps_test.world -->
      <sensor name="gps" type="gps">
        <pose>0 0 0 0 0 0</pose>
        <update_rate>10.0</update_rate>
        <always_on>true</always_on>
        <gps>
          <position_sensing>
            <horizontal>
              <noise type="gaussian_quantized">
                <mean>0</mean>
                <stddev>1</stddev>
                <bias_mean>3</bias_mean>
                <bias_stddev>1</bias_stddev>
                <precision>0.5</precision>
              </noise>
            </horizontal>
            <vertical>
              <noise type="gaussian_quantized">
                <mean>0</mean>
                <stddev>1</stddev>
                <bias_mean>3</bias_mean>
                <bias_stddev>1</bias_stddev>
                <precision>1.0</precision>
              </noise>
            </vertical>
          </position_sensing>
          <velocity_sensing>
            <horizontal>
              <noise type="gaussian_quantized">
                <mean>0</mean>
                <stddev>0.1</stddev>
                <bias_mean>0.1</bias_mean>
                <bias_stddev>0.1</bias_stddev>
                <precision>0.1</precision>
              </noise>
            </horizontal>
            <vertical>
              <noise type="gaussian_quantized">
                <mean>0</mean>
                <stddev>0.2</stddev>
                <bias_mean>0.2</bias_mean>
                <bias_stddev>0.2</bias_stddev>
                <precision>0.2</precision>
              </noise>
            </vertical>
          </velocity_sensing>
        </gps>
      </sensor>
    </link>
    
<!-- Camera (hight is 100mm) -->
    <include>
      <name>camera</name>
      <pose>0 0 0.22 0 0 -1.57</pose>
      <uri>model://camera_ros1</uri>
    </include>

    <joint name="camera_joint" type="revolute">
      <parent>base_link</parent>
      <child>camera::camera_link</child>
      <pose>0 0 0 0 0 0</pose>
      <axis>
        <xyz>0 0 1</xyz>
        <limit>
          <lower>0</lower>
          <upper>0</upper>
        </limit>
      </axis>
    </joint>
    
<!-- Hokuyo (hight is 70mm) -->
    <include>
      <name>hokuyo</name>
      <pose>0 0 0.135 0 0 -1.57</pose>
      <uri>model://hokuyo_ros1</uri>
    </include>

    <joint name="hokuyo_joint" type="revolute">
      <parent>base_link</parent>
      <child>hokuyo::hokuyo_link</child>
      <pose>0 0 0 0 0 0</pose>
      <axis>
        <xyz>0 0 1</xyz>
        <limit>
          <lower>0</lower>
          <upper>0</upper>
        </limit>
      </axis>
    </joint>
    
<!--__________________right_crawler___________________-->
    <link name="right_rear_wheel"> 
      <pose>-0.1 0.15 0.05 0 1.570796327 0</pose>
      <inertial>
        <mass>1.0</mass>
        <inertia>
          <ixx>1.3744467859e-03</ixx>
          <ixy>0</ixy>
          <ixz>0</ixz>
          <iyy>1.3744467859e-03</iyy>
          <iyz>0</iyz>
          <izz>11.780972451e-04</izz>
        </inertia>
      </inertial>
      <collision name="collision">
        <geometry>
          <cylinder>
            <radius>.05</radius>
            <length>.1</length>
          </cylinder>
        </geometry>
        <surface>
          <friction>
            <ode>
              <mu>.8</mu>
              <mu2>.8</mu2>
            </ode>
          </friction>
        </surface>
      </collision>
      <visual name="visual">
        <geometry>
          <cylinder>
            <radius>.05</radius>
            <length>.1</length>
          </cylinder>
        </geometry>
      </visual>
    </link>

    <link name="right_front_wheel">
    <pose>-0.1 -0.15 0.05 0 1.570796327 0</pose>
      <inertial>
        <mass>1.0</mass>
        <inertia>
          <ixx>1.3744467859e-03</ixx>
          <ixy>0</ixy>
          <ixz>0</ixz>
          <iyy>1.3744467859e-03</iyy>
          <iyz>0</iyz>
          <izz>11.780972451e-04</izz>
        </inertia>
      </inertial>
      <collision name="collision">
        <geometry>
          <cylinder>
            <radius>.05</radius>
            <length>.1</length>
          </cylinder>
        </geometry>
        <surface>
          <friction>
            <ode>
              <mu>.8</mu>
              <mu2>.8</mu2>
            </ode>
          </friction>
        </surface>
      </collision>
      <visual name="visual">
        <geometry>
          <cylinder>
            <radius>.05</radius>
            <length>.1</length>
          </cylinder>
        </geometry>
      </visual>
    </link>

    <link name="right_center_wheel_1">
      <pose>-0.1 0.05 0.05 0 1.570796327 0</pose>
      <inertial>
        <mass>1.0</mass>
        <inertia>
          <ixx>7.5267323992e-04</ixx>
          <ixy>0</ixy>
          <ixz>0</ixz>
          <iyy>7.5267323992e-04</iyy>
          <iyz>0</iyz>
          <izz>11.2900985988e-04</izz>
        </inertia>
      </inertial>
      <collision name="collision">
        <laser_retro>0</laser_retro>
        <geometry>
          <cylinder>
            <radius>.05</radius>
            <length>.05</length>
          </cylinder>
        </geometry>
        <surface>
          <friction>
            <ode>
              <mu>.8</mu>
              <mu2>.8</mu2>
            </ode>
          </friction>
        </surface>
      </collision>
<!--
      <visual name="visual">
        <laser_retro>0</laser_retro>
        <geometry>
          <cylinder>
            <radius>.05</radius>
            <length>.05</length>
          </cylinder>
        </geometry>
      </visual>
-->
    </link>

    <link name="right_center_wheel_2">
      <pose>-0.1 -0.0 0.049 0 1.570796327 0</pose>
      <inertial>
        <mass>1.0</mass>
        <inertia>
          <ixx>7.5267323992e-04</ixx>
          <ixy>0</ixy>
          <ixz>0</ixz>
          <iyy>7.5267323992e-04</iyy>
          <iyz>0</iyz>
          <izz>11.2900985988e-04</izz>
        </inertia>
      </inertial>
      <collision name="collision">
        <laser_retro>0</laser_retro>
        <geometry>
          <cylinder>
            <radius>.05</radius>
            <length>.05</length>
          </cylinder>
        </geometry>
        <surface>
          <friction>
            <ode>
              <mu>.8</mu>
              <mu2>.8</mu2>
            </ode>
          </friction>
        </surface>
      </collision>
<!--
      <visual name="visual">
        <laser_retro>0</laser_retro>
        <geometry>
          <cylinder>
            <radius>.05</radius>
            <length>.05</length>
          </cylinder>
        </geometry>
      </visual>
-->
    </link>

    <link name="right_center_wheel_3">
      <pose>-0.1 -0.05 0.05 0 1.570796327 0</pose>
      <inertial>
        <mass>1.0</mass>
        <inertia>
          <ixx>7.5267323992e-04</ixx>
          <ixy>0</ixy>
          <ixz>0</ixz>
          <iyy>7.5267323992e-04</iyy>
          <iyz>0</iyz>
          <izz>11.2900985988e-04</izz>
        </inertia>
      </inertial>
      <collision name="collision">
        <laser_retro>0</laser_retro>
        <geometry>
          <cylinder>
            <radius>.05</radius>
            <length>.05</length>
          </cylinder>
        </geometry>
        <surface>
          <friction>
            <ode>
              <mu>.8</mu>
              <mu2>.8</mu2>
            </ode>
          </friction>
        </surface>
      </collision>
<!--
      <visual name="visual">
        <laser_retro>0</laser_retro>
        <geometry>
          <cylinder>
            <radius>.05</radius>
            <length>.05</length>
          </cylinder>
        </geometry>
      </visual>
-->
    </link>

    <link name="right_sub_wheel_2">
      <pose>-0.1 0.1 0.05 0 1.570796327 0</pose>
      <inertial>
        <mass>1.0</mass>
        <inertia>
          <ixx>1.3744467859e-03</ixx>
          <ixy>0</ixy>
          <ixz>0</ixz>
          <iyy>1.3744467859e-03</iyy>
          <iyz>0</iyz>
          <izz>11.780972451e-04</izz>
        </inertia>
      </inertial>
      <collision name="collision">
        <laser_retro>0</laser_retro>
        <geometry>
          <cylinder>
            <radius>.05</radius>
            <length>.1</length>
          </cylinder>
        </geometry>
        <surface>
          <friction>
            <ode>
              <mu>.8</mu>
              <mu2>.8</mu2>
            </ode>
          </friction>
        </surface>
      </collision>
<!--
      <visual name="visual">
        <laser_retro>0</laser_retro>
        <geometry>
          <cylinder>
            <radius>.05</radius>
            <length>.1</length>
          </cylinder>
        </geometry>
      </visual>
-->
      <self_collide>0</self_collide>
    </link>

    <link name="right_sub_wheel_3">
      <pose>-0.1 -0.1 0.05 0 1.570796327 0</pose>
      <inertial>
        <mass>1.0</mass>
        <inertia>
          <ixx>1.3744467859e-03</ixx>
          <ixy>0</ixy>
          <ixz>0</ixz>
          <iyy>1.3744467859e-03</iyy>
          <iyz>0</iyz>
          <izz>11.780972451e-04</izz>
        </inertia>
      </inertial>
      <collision name="collision">
        <laser_retro>0</laser_retro>
        <geometry>
          <cylinder>
            <radius>.05</radius>
            <length>.1</length>
          </cylinder>
        </geometry>
        <surface>
          <friction>
            <ode>
              <mu>.8</mu>
              <mu2>.8</mu2>
            </ode>
          </friction>
        </surface>
      </collision>
<!--
      <visual name="visual">
        <laser_retro>0</laser_retro>
        <geometry>
          <cylinder>
            <radius>.05</radius>
            <length>.1</length>
          </cylinder>
        </geometry>
      </visual>
-->
      <self_collide>0</self_collide>
    </link>
<!--__________________/right_crawler___________________-->

<!--__________________left_crawler___________________-->
    <link name="left_rear_wheel">
      <pose>0.1 0.15 0.05 0 1.570796327 0</pose>
      <inertial>
        <mass>1.0</mass>
        <inertia>
          <ixx>1.3744467859e-03</ixx>
          <ixy>0</ixy>
          <ixz>0</ixz>
          <iyy>1.3744467859e-03</iyy>
          <iyz>0</iyz>
          <izz>11.780972451e-04</izz>
        </inertia>
      </inertial>
      <collision name="collision">
        <geometry>
          <cylinder>
            <radius>.05</radius>
            <length>.1</length>
          </cylinder>
        </geometry>
        <surface>
          <friction>
            <ode>
              <mu>.8</mu>
              <mu2>.8</mu2>
            </ode>
          </friction>
        </surface>
      </collision>
      <visual name="visual">
        <geometry>
          <cylinder>
            <radius>.05</radius>
            <length>.1</length>
          </cylinder>
        </geometry>
      </visual>
    </link>

    <link name="left_front_wheel">
      <pose>0.1 -0.15 0.05 0 1.570796327 0</pose>
      <inertial>
        <mass>1.0</mass>
        <inertia>
          <ixx>1.3744467859e-03</ixx>
          <ixy>0</ixy>
          <ixz>0</ixz>
          <iyy>1.3744467859e-03</iyy>
          <iyz>0</iyz>
          <izz>11.780972451e-04</izz>
        </inertia>
      </inertial>
      <collision name="collision">
        <geometry>
          <cylinder>
            <radius>.05</radius>
            <length>.1</length>
          </cylinder>
        </geometry>
        <surface>
          <friction>
            <ode>
              <mu>.8</mu>
              <mu2>.8</mu2>
            </ode>
          </friction>
        </surface>
      </collision>
      <visual name="visual">
        <geometry>
          <cylinder>
            <radius>.05</radius>
            <length>.1</length>
          </cylinder>
        </geometry>
      </visual>
    </link>

    <link name="left_center_wheel_1">
      <pose>0.1 0.05 0.05 0 1.570796327 0</pose>
      <inertial>
        <mass>1.0</mass>
        <inertia>
          <ixx>7.5267323992e-04</ixx>
          <ixy>0</ixy>
          <ixz>0</ixz>
          <iyy>7.5267323992e-04</iyy>
          <iyz>0</iyz>
          <izz>11.2900985988e-04</izz>
        </inertia>
      </inertial>
      <collision name="collision">
        <laser_retro>0</laser_retro>
        <geometry>
          <cylinder>
            <radius>.05</radius>
            <length>.05</length>
          </cylinder>
        </geometry>
        <surface>
          <friction>
            <ode>
              <mu>.8</mu>
              <mu2>.8</mu2>
            </ode>
          </friction>
        </surface>
      </collision>
<!--
      <visual name="visual">
        <laser_retro>0</laser_retro>
        <geometry>
          <cylinder>
            <radius>.05</radius>
            <length>.05</length>
          </cylinder>
        </geometry>
      </visual>
-->
    </link>

    <link name="left_center_wheel_2">
      <pose>0.1 -0.0 0.049 0 1.570796327 0</pose>
      <inertial>
        <mass>1.0</mass>
        <inertia>
          <ixx>7.5267323992e-04</ixx>
          <ixy>0</ixy>
          <ixz>0</ixz>
          <iyy>7.5267323992e-04</iyy>
          <iyz>0</iyz>
          <izz>11.2900985988e-04</izz>
        </inertia>
      </inertial>
      <collision name="collision">
        <laser_retro>0</laser_retro>
        <geometry>
          <cylinder>
            <radius>.05</radius>
            <length>.05</length>
          </cylinder>
        </geometry>
        <surface>
          <friction>
            <ode>
              <mu>.8</mu>
              <mu2>.8</mu2>
            </ode>
          </friction>
        </surface>
      </collision>
<!--
      <visual name="visual">
        <laser_retro>0</laser_retro>
        <geometry>
          <cylinder>
            <radius>.05</radius>
            <length>.05</length>
          </cylinder>
        </geometry>
      </visual>
-->
    </link>

    <link name="left_center_wheel_3">
      <pose>0.1 -0.05 0.05 0 1.570796327 0</pose>
      <inertial>
        <mass>1.0</mass>
        <inertia>
          <ixx>7.5267323992e-04</ixx>
          <ixy>0</ixy>
          <ixz>0</ixz>
          <iyy>7.5267323992e-04</iyy>
          <iyz>0</iyz>
          <izz>11.2900985988e-04</izz>
        </inertia>
      </inertial>
      <collision name="collision">
        <laser_retro>0</laser_retro>
        <geometry>
          <cylinder>
            <radius>.05</radius>
            <length>.05</length>
          </cylinder>
        </geometry>
        <surface>
          <friction>
            <ode>
              <mu>.8</mu>
              <mu2>.8</mu2>
            </ode>
          </friction>
        </surface>
      </collision>
<!--
      <visual name="visual">
        <laser_retro>0</laser_retro>
        <geometry>
          <cylinder>
            <radius>.05</radius>
            <length>.05</length>
          </cylinder>
        </geometry>
      </visual>
-->
    </link>

    <link name="left_sub_wheel_2">
      <pose>0.1 0.1 0.05 0 1.570796327 0</pose>
      <inertial>
        <mass>1.0</mass>
        <inertia>
          <ixx>1.3744467859e-03</ixx>
          <ixy>0</ixy>
          <ixz>0</ixz>
          <iyy>1.3744467859e-03</iyy>
          <iyz>0</iyz>
          <izz>11.780972451e-04</izz>
        </inertia>
      </inertial>
      <collision name="collision">
        <laser_retro>0</laser_retro>
        <geometry>
          <cylinder>
            <radius>.05</radius>
            <length>.1</length>
          </cylinder>
        </geometry>
        <surface>
          <friction>
            <ode>
              <mu>.8</mu>
              <mu2>.8</mu2>
            </ode>
          </friction>
        </surface>
      </collision>
<!--
      <visual name="visual">
        <laser_retro>0</laser_retro>
        <geometry>
          <cylinder>
            <radius>.05</radius>
            <length>.1</length>
          </cylinder>
        </geometry>
      </visual>
-->
    </link>

    <link name="left_sub_wheel_3">
      <pose>0.1 -0.1 0.05 0 1.570796327 0</pose>
      <inertial>
        <mass>1.0</mass>
        <inertia>
          <ixx>1.3744467859e-03</ixx>
          <ixy>0</ixy>
          <ixz>0</ixz>
          <iyy>1.3744467859e-03</iyy>
          <iyz>0</iyz>
          <izz>11.780972451e-04</izz>
        </inertia>
      </inertial>
      <collision name="collision">
        <laser_retro>0</laser_retro>
        <geometry>
          <cylinder>
            <radius>.05</radius>
            <length>.1</length>
          </cylinder>
        </geometry>
        <surface>
          <friction>
            <ode>
              <mu>.8</mu>
              <mu2>.8</mu2>
            </ode>
          </friction>
        </surface>
      </collision>
<!--
      <visual name="visual">
        <laser_retro>0</laser_retro>
        <geometry>
          <cylinder>
            <radius>.05</radius>
            <length>.1</length>
          </cylinder>
        </geometry>
      </visual>
-->
    </link>
<!--__________________/left_crawler___________________-->

<!--__________________right_rear_arm__________________-->

    <link name="right_rear_arm">
      <pose>-0.151 0.225 0.05 0 0 0</pose>
      <inertial>
        <pose>-0.015 0 0 1.57 0 1.57</pose>
        <mass>1.0</mass>
        <inertia>
          <ixx>6.8125e-4</ixx>
          <ixy>0</ixy>
          <ixz>0</ixz>
          <iyy>3.96253e-3</iyy>
          <iyz>0</iyz>
          <izz>4.53125e-3</izz>
        </inertia>
      </inertial>
<!--
      <collision name="collision">
        <geometry>
          <box>
            <size>.002 .16 .05</size>
          </box>
        </geometry>
      </collision>
-->
      <visual name="visual">
        <geometry>
          <box>
            <size>.002 .16 .05</size>
          </box>
        </geometry>
        <material>
          <ambient>0.7 0.7 0.7 1</ambient>
          <diffuse>0.3 0.3 0.3 1</diffuse>
          <specular>0.1 0.1 0.1 1</specular>
          <emissive>0 0 0 0</emissive>
        </material>
      </visual>
      <visual name="crawler_visual">
        <pose>-0.015 0 -0.05 0 0 1.57</pose>
        <geometry>
          <mesh>
            <uri>model://crawler_robot_ros1/dae/arm_crawler_2.dae</uri>
          </mesh>
        </geometry>
      </visual>
    </link>

    <link name="right_rear_arm_wheel_1">
      <pose>-0.166 0.15 0.05 0 1.570796327 0</pose>
      <inertial>
        <mass>1.0</mass>
        <inertia>
          <ixx>6.2674773439e-04</ixx>
          <ixy>0</ixy>
          <ixz>0</ixz>
          <iyy>6.2674773439e-04</iyy>
          <iyz>0</iyz>
          <izz>11.1919238284e-04</izz>
        </inertia>
      </inertial>
      <collision name="collision">
        <geometry>
          <cylinder>
            <radius>.05</radius>
            <length>.03</length>
          </cylinder>
        </geometry>
        <surface>
          <friction>
            <ode>
              <mu>.8</mu>
              <mu2>.8</mu2>
            </ode>
          </friction>
        </surface>
      </collision>
      <visual name="visual">
        <geometry>
          <cylinder>
            <radius>.05</radius>
            <length>.03</length>
          </cylinder>
        </geometry>
      </visual>
      <self_collide>0</self_collide>
    </link>

    <link name="right_rear_arm_wheel_2">
      <pose>-0.166 0.3 0.05 0 1.570796327 0</pose>
      <inertial>
        <mass>1.0</mass>
        <inertia>
          <ixx>6.2674773439e-04</ixx>
          <ixy>0</ixy>
          <ixz>0</ixz>
          <iyy>6.2674773439e-04</iyy>
          <iyz>0</iyz>
          <izz>11.1919238284e-04</izz>
        </inertia>
      </inertial>
      <collision name="collision">
        <geometry>
          <cylinder>
            <radius>.05</radius>
            <length>.03</length>
          </cylinder>
        </geometry>
        <surface>
          <friction>
            <ode>
              <mu>.8</mu>
              <mu2>.8</mu2>
            </ode>
          </friction>
        </surface>
      </collision>
      <visual name="visual">
        <geometry>
          <cylinder>
            <radius>.05</radius>
            <length>.03</length>
          </cylinder>
        </geometry>
      </visual>
      <self_collide>0</self_collide>
    </link>

    <link name="right_rear_arm_wheel_3">
      <pose>-0.166 0.225 0.05 0 1.570796327 0</pose>
      <inertial>
        <mass>1.0</mass>
        <inertia>
          <ixx>6.2674773439e-04</ixx>
          <ixy>0</ixy>
          <ixz>0</ixz>
          <iyy>6.2674773439e-04</iyy>
          <iyz>0</iyz>
          <izz>11.1919238284e-04</izz>
        </inertia>
      </inertial>
      <collision name="collision">
        <laser_retro>0</laser_retro>
        <geometry>
          <cylinder>
            <radius>.05</radius>
            <length>.03</length>
          </cylinder>
        </geometry>
        <surface>
          <friction>
            <ode>
              <mu>.8</mu>
              <mu2>.8</mu2>
            </ode>
          </friction>
        </surface>
      </collision>
<!--
      <visual name="visual">
        <laser_retro>0</laser_retro>
        <geometry>
          <cylinder>
            <radius>.05</radius>
            <length>.03</length>
          </cylinder>
        </geometry>
      </visual>
-->
      <self_collide>0</self_collide>
    </link>
<!--__________________/right_rear_arm__________________-->

<!--__________________left_rear_arm__________________-->
    <link name="left_rear_arm">
      <pose>0.151 0.225 0.05 0 0 0</pose>
      <inertial>
        <pose>0.015 0 0 1.57 0 1.57</pose>
        <mass>1.0</mass>
        <inertia>
          <ixx>6.8125e-4</ixx>
          <ixy>0</ixy>
          <ixz>0</ixz>
          <iyy>3.96253e-3</iyy>
          <iyz>0</iyz>
          <izz>4.53125e-3</izz>
        </inertia>
      </inertial>
<!--
      <collision name="collision">
        <geometry>
          <box>
            <size>.002 .16 .05</size>
          </box>
        </geometry>
      </collision>
-->
      <visual name="visual">
        <geometry>
          <box>
            <size>.002 .16 .05</size>
          </box>
        </geometry>
        <material>
          <ambient>0.7 0.7 0.7 1</ambient>
          <diffuse>0.3 0.3 0.3 1</diffuse>
          <specular>0.1 0.1 0.1 1</specular>
          <emissive>0 0 0 0</emissive>
        </material>
      </visual>
      <visual name="crawler_visual">
        <pose>0.015 0 -0.05 0 0 1.57</pose>
        <geometry>
          <mesh>
            <uri>model://crawler_robot_ros1/dae/arm_crawler_2.dae</uri>
          </mesh>
        </geometry>
      </visual>
    </link>

    <link name="left_rear_arm_wheel_1">
      <pose>0.166 0.15 0.05 0 1.570796327 0</pose>
      <inertial>
        <mass>1.0</mass>
        <inertia>
          <ixx>6.2674773439e-04</ixx>
          <ixy>0</ixy>
          <ixz>0</ixz>
          <iyy>6.2674773439e-04</iyy>
          <iyz>0</iyz>
          <izz>11.1919238284e-04</izz>
        </inertia>
      </inertial>
      <collision name="collision">
        <geometry>
          <cylinder>
            <radius>.05</radius>
            <length>.03</length>
          </cylinder>
        </geometry>
        <surface>
          <friction>
            <ode>
              <mu>.8</mu>
              <mu2>.8</mu2>
            </ode>
          </friction>
        </surface>
      </collision>
      <visual name="visual">
        <geometry>
          <cylinder>
            <radius>.05</radius>
            <length>.03</length>
          </cylinder>
        </geometry>
      </visual>
      <self_collide>0</self_collide>
    </link>

    <link name="left_rear_arm_wheel_2">
      <pose>0.166 0.3 0.05 0 1.570796327 0</pose>
      <inertial>
        <mass>1.0</mass>
        <inertia>
          <ixx>6.2674773439e-04</ixx>
          <ixy>0</ixy>
          <ixz>0</ixz>
          <iyy>6.2674773439e-04</iyy>
          <iyz>0</iyz>
          <izz>11.1919238284e-04</izz>
        </inertia>
      </inertial>
      <collision name="collision">
        <geometry>
          <cylinder>
            <radius>.05</radius>
            <length>.03</length>
          </cylinder>
        </geometry>
        <surface>
          <friction>
            <ode>
              <mu>.8</mu>
              <mu2>.8</mu2>
            </ode>
          </friction>
        </surface>
      </collision>
      <visual name="visual">
        <geometry>
          <cylinder>
            <radius>.05</radius>
            <length>.03</length>
          </cylinder>
        </geometry>
      </visual>
      <self_collide>0</self_collide>
    </link>

    <link name="left_rear_arm_wheel_3">
      <pose>0.166 0.225 0.05 0 1.570796327 0</pose>
      <inertial>
        <mass>1.0</mass>
        <inertia>
          <ixx>6.2674773439e-04</ixx>
          <ixy>0</ixy>
          <ixz>0</ixz>
          <iyy>6.2674773439e-04</iyy>
          <iyz>0</iyz>
          <izz>11.1919238284e-04</izz>
        </inertia>
      </inertial>
      <collision name="collision">
        <laser_retro>0</laser_retro>
        <geometry>
          <cylinder>
            <radius>.05</radius>
            <length>.03</length>
          </cylinder>
        </geometry>
        <surface>
          <friction>
            <ode>
              <mu>.8</mu>
              <mu2>.8</mu2>
            </ode>
          </friction>
        </surface>
      </collision>
<!--
      <visual name="visual">
        <laser_retro>0</laser_retro>
        <geometry>
          <cylinder>
            <radius>.05</radius>
            <length>.03</length>
          </cylinder>
        </geometry>
      </visual>
-->
      <self_collide>0</self_collide>
    </link>
<!--__________________/left_rear_arm__________________-->

<!--__________________right_front_arm__________________-->
    <link name="right_front_arm">
      <pose>-0.151 -0.225 0.05 0 0 0</pose>
      <inertial>
        <pose>-0.015 0 0 1.57 0 1.57</pose>
        <mass>1.0</mass>
        <inertia>
          <ixx>6.8125e-4</ixx>
          <ixy>0</ixy>
          <ixz>0</ixz>
          <iyy>3.96253e-3</iyy>
          <iyz>0</iyz>
          <izz>4.53125e-3</izz>
        </inertia>
      </inertial>
<!--
      <collision name="collision">
        <geometry>
          <box>
            <size>.002 .16 .05</size>
          </box>
        </geometry>
      </collision>
-->
      <visual name="visual">
        <geometry>
          <box>
            <size>.002 .16 .05</size>
          </box>
        </geometry>
        <material>
          <ambient>0.7 0.7 0.7 1</ambient>
          <diffuse>0.3 0.3 0.3 1</diffuse>
          <specular>0.1 0.1 0.1 1</specular>
          <emissive>0 0 0 0</emissive>
        </material>
      </visual>
      <visual name="crawler_visual">
        <pose>-0.015 0 -0.05 0 0 1.57</pose>
        <geometry>
          <mesh>
            <uri>model://crawler_robot_ros1/dae/arm_crawler_2.dae</uri>
          </mesh>
        </geometry>
      </visual>
    </link>

    <link name="right_front_arm_wheel_1">
      <pose>-0.166 -0.15 0.05 0 1.570796327 0</pose>
      <inertial>
        <mass>1.0</mass>
        <inertia>
          <ixx>6.2674773439e-04</ixx>
          <ixy>0</ixy>
          <ixz>0</ixz>
          <iyy>6.2674773439e-04</iyy>
          <iyz>0</iyz>
          <izz>11.1919238284e-04</izz>
        </inertia>
      </inertial>
      <collision name="collision">
        <geometry>
          <cylinder>
            <radius>.05</radius>
            <length>.03</length>
          </cylinder>
        </geometry>
        <surface>
          <friction>
            <ode>
              <mu>.8</mu>
              <mu2>.8</mu2>
            </ode>
          </friction>
        </surface>
      </collision>
      <visual name="visual">
        <geometry>
          <cylinder>
            <radius>.05</radius>
            <length>.03</length>
          </cylinder>
        </geometry>
      </visual>
      <self_collide>0</self_collide>
    </link>

    <link name="right_front_arm_wheel_2">
      <pose>-0.166 -0.3 0.05 0 1.570796327 0</pose>
      <inertial>
        <mass>1.0</mass>
        <inertia>
          <ixx>6.2674773439e-04</ixx>
          <ixy>0</ixy>
          <ixz>0</ixz>
          <iyy>6.2674773439e-04</iyy>
          <iyz>0</iyz>
          <izz>11.1919238284e-04</izz>
        </inertia>
      </inertial>
      <collision name="collision">
        <geometry>
          <cylinder>
            <radius>.05</radius>
            <length>.03</length>
          </cylinder>
        </geometry>
        <surface>
          <friction>
            <ode>
              <mu>.8</mu>
              <mu2>.8</mu2>
            </ode>
          </friction>
        </surface>
      </collision>
      <visual name="visual">
        <geometry>
          <cylinder>
            <radius>.05</radius>
            <length>.03</length>
          </cylinder>
        </geometry>
      </visual>
      <self_collide>0</self_collide>
    </link>

    <link name="right_front_arm_wheel_3">
      <pose>-0.166 -0.225 0.05 0 1.570796327 0</pose>
      <inertial>
        <mass>1.0</mass>
        <inertia>
          <ixx>6.2674773439e-04</ixx>
          <ixy>0</ixy>
          <ixz>0</ixz>
          <iyy>6.2674773439e-04</iyy>
          <iyz>0</iyz>
          <izz>11.1919238284e-04</izz>
        </inertia>
      </inertial>
      <collision name="collision">
        <laser_retro>0</laser_retro>
        <geometry>
          <cylinder>
            <radius>.05</radius>
            <length>.03</length>
          </cylinder>
        </geometry>
        <surface>
          <friction>
            <ode>
              <mu>.8</mu>
              <mu2>.8</mu2>
            </ode>
          </friction>
        </surface>
      </collision>
<!--
      <visual name="visual">
        <laser_retro>0</laser_retro>
        <geometry>
          <cylinder>
            <radius>.05</radius>
            <length>.03</length>
          </cylinder>
        </geometry>
      </visual>
-->
      <self_collide>0</self_collide>
    </link>
<!--__________________/right_front_arm__________________-->

<!--__________________left_front_arm__________________-->
    <link name="left_front_arm">
      <pose>0.151 -0.225 0.05 0 0 0</pose>
      <inertial>
        <pose>0.015 0 0 1.57 0 1.57</pose>
        <mass>1.0</mass>
        <inertia>
          <ixx>6.8125e-4</ixx>
          <ixy>0</ixy>
          <ixz>0</ixz>
          <iyy>3.96253e-3</iyy>
          <iyz>0</iyz>
          <izz>4.53125e-3</izz>
        </inertia>
      </inertial>
<!--
      <collision name="collision">
        <geometry>
          <box>
            <size>.002 .16 .05</size>
          </box>
        </geometry>
      </collision>
-->
      <visual name="visual">
        <geometry>
          <box>
            <size>.002 .16 .05</size>
          </box>
        </geometry>
        <material>
          <ambient>0.7 0.7 0.7 1</ambient>
          <diffuse>0.3 0.3 0.3 1</diffuse>
          <specular>0.1 0.1 0.1 1</specular>
          <emissive>0 0 0 0</emissive>
        </material>
      </visual>
      <visual name="crawler_visual">
        <pose>0.015 0 -0.05 0 0 1.57</pose>
        <geometry>
          <mesh>
            <uri>model://crawler_robot_ros1/dae/arm_crawler_2.dae</uri>
          </mesh>
        </geometry>
      </visual>
    </link>

    <link name="left_front_arm_wheel_1">
      <pose>0.166 -0.15 0.05 0 1.570796327 0</pose>
      <inertial>
        <mass>1.0</mass>
        <inertia>
          <ixx>6.2674773439e-04</ixx>
          <ixy>0</ixy>
          <ixz>0</ixz>
          <iyy>6.2674773439e-04</iyy>
          <iyz>0</iyz>
          <izz>11.1919238284e-04</izz>
        </inertia>
      </inertial>
      <collision name="collision">
        <geometry>
          <cylinder>
            <radius>.05</radius>
            <length>.03</length>
          </cylinder>
        </geometry>
        <surface>
          <friction>
            <ode>
              <mu>.8</mu>
              <mu2>.8</mu2>
            </ode>
          </friction>
        </surface>
      </collision>
      <visual name="visual">
        <geometry>
          <cylinder>
            <radius>.05</radius>
            <length>.03</length>
          </cylinder>
        </geometry>
      </visual>
      <self_collide>0</self_collide>
    </link>

    <link name="left_front_arm_wheel_2">
      <pose>0.166 -0.3 0.05 0 1.570796327 0</pose>
      <inertial>
        <mass>1.0</mass>
        <inertia>
          <ixx>6.2674773439e-04</ixx>
          <ixy>0</ixy>
          <ixz>0</ixz>
          <iyy>6.2674773439e-04</iyy>
          <iyz>0</iyz>
          <izz>11.1919238284e-04</izz>
        </inertia>
      </inertial>
      <collision name="collision">
        <geometry>
          <cylinder>
            <radius>.05</radius>
            <length>.03</length>
          </cylinder>
        </geometry>
        <surface>
          <friction>
            <ode>
              <mu>.8</mu>
              <mu2>.8</mu2>
            </ode>
          </friction>
        </surface>
      </collision>
      <visual name="visual">
        <geometry>
          <cylinder>
            <radius>.05</radius>
            <length>.03</length>
          </cylinder>
        </geometry>
      </visual>
      <self_collide>0</self_collide>
    </link>

    <link name="left_front_arm_wheel_3">
      <pose>0.166 -0.225 0.05 0 1.570796327 0</pose>
      <inertial>
        <mass>1.0</mass>
        <inertia>
          <ixx>6.2674773439e-04</ixx>
          <ixy>0</ixy>
          <ixz>0</ixz>
          <iyy>6.2674773439e-04</iyy>
          <iyz>0</iyz>
          <izz>11.1919238284e-04</izz>
        </inertia>
      </inertial>
      <collision name="collision">
        <laser_retro>0</laser_retro>
        <geometry>
          <cylinder>
            <radius>.05</radius>
            <length>.03</length>
          </cylinder>
        </geometry>
        <surface>
          <friction>
            <ode>
              <mu>.8</mu>
              <mu2>.8</mu2>
            </ode>
          </friction>
        </surface>
      </collision>
<!--
      <visual name="visual">
        <laser_retro>0</laser_retro>
        <geometry>
          <cylinder>
            <radius>.05</radius>
            <length>.03</length>
          </cylinder>
        </geometry>
      </visual>
-->
      <self_collide>0</self_collide>
    </link>
<!--__________________/left_front_arm__________________-->


<!--__________________joint___________________-->
    <joint type="revolute" name="right_rear">
      <pose>0 0 0.05 0 0 0</pose>
      <child>right_rear_wheel</child>
      <parent>base_link</parent>
      <axis>
        <xyz>0 0 1</xyz>
      </axis>
    </joint>

    <joint type="revolute" name="right_front">
      <pose>0 0 0.05 0 0 0</pose>
      <child>right_front_wheel</child>
      <parent>base_link</parent>
      <axis>
        <xyz>0 0 1</xyz>
      </axis>
    </joint>


    <joint type="revolute" name="right_center1">
      <pose>0 0 0.05 0 0 0</pose>
      <child>right_center_wheel_1</child>
      <parent>base_link</parent>
      <axis>
        <xyz>0 0 1</xyz>
      </axis>
    </joint>

    <joint type="revolute" name="right_center2">
      <pose>0 0 0.05 0 0 0</pose>
      <child>right_center_wheel_2</child>
      <parent>base_link</parent>
      <axis>
        <xyz>0 0 1</xyz>
      </axis>
    </joint>

    <joint type="revolute" name="right_center3">
      <pose>0 0 0.05 0 0 0</pose>
      <child>right_center_wheel_3</child>
      <parent>base_link</parent>
      <axis>
        <xyz>0 0 1</xyz>
      </axis>
    </joint>

<!--
    <joint type="revolute" name="right_sub1">
      <pose>0 0 -0.05 0 0 0</pose>
      <child>right_sub_wheel_1</child>
      <parent>base_link</parent>
      <axis>
        <xyz>0 0 1</xyz>
      </axis>
    </joint>
-->

    <joint type="revolute" name="right_sub2">
      <pose>0 0 -0.05 0 0 0</pose>
      <child>right_sub_wheel_2</child>
      <parent>base_link</parent>
      <axis>
        <xyz>0 0 1</xyz>
      </axis>
    </joint>

    <joint type="revolute" name="right_sub3">
      <pose>0 0 -0.05 0 0 0</pose>
      <child>right_sub_wheel_3</child>
      <parent>base_link</parent>
      <axis>
        <xyz>0 0 1</xyz>
      </axis>
    </joint>

    <joint type="revolute" name="left_rear">
      <pose>0 0 -0.05 0 0 0</pose>
      <child>left_rear_wheel</child>
      <parent>base_link</parent>
      <axis>
        <xyz>0 0 1</xyz>
      </axis>
    </joint>

    <joint type="revolute" name="left_front">
      <pose>0 0 -0.05 0 0 0</pose>
      <child>left_front_wheel</child>
      <parent>base_link</parent>
      <axis>
        <xyz>0 0 1</xyz>
      </axis>
    </joint>



    <joint type="revolute" name="left_center1">
      <pose>0 0 -0.05 0 0 0</pose>
      <child>left_center_wheel_1</child>
      <parent>base_link</parent>
      <axis>
        <xyz>0 0 1</xyz>
      </axis>
    </joint>

    <joint type="revolute" name="left_center2">
      <pose>0 0 -0.05 0 0 0</pose>
      <child>left_center_wheel_2</child>
      <parent>base_link</parent>
      <axis>
        <xyz>0 0 1</xyz>
      </axis>
    </joint>

    <joint type="revolute" name="left_center3">
      <pose>0 0 -0.05 0 0 0</pose>
      <child>left_center_wheel_3</child>
      <parent>base_link</parent>
      <axis>
        <xyz>0 0 1</xyz>
      </axis>
    </joint>

<!--
    <joint type="revolute" name="left_sub1">
      <pose>0 0 -0.05 0 0 0</pose>
      <child>left_sub_wheel_1</child>
      <parent>base_link</parent>
      <axis>
        <xyz>0 0 1</xyz>
      </axis>
    </joint>
-->

    <joint type="revolute" name="left_sub2">
      <pose>0 0 -0.05 0 0 0</pose>
      <child>left_sub_wheel_2</child>
      <parent>base_link</parent>
      <axis>
        <xyz>0 0 1</xyz>
      </axis>
    </joint>

    <joint type="revolute" name="left_sub3">
      <pose>0 0 -0.05 0 0 0</pose>
      <child>left_sub_wheel_3</child>
      <parent>base_link</parent>
      <axis>
        <xyz>0 0 1</xyz>
      </axis>
    </joint>



    <joint type="revolute" name="left_rear_arm_joint">
      <pose>0 -0.075 0.001 0 0 0</pose>
      <child>left_rear_arm</child>
      <parent>base_link</parent>
      <axis>
        <xyz>1 0 0</xyz>
        <dynamics>
          <damping>.5</damping>
        </dynamics>
        <limit>
          <velocity>1</velocity>
        </limit>
      </axis>
    </joint>

    <joint type="revolute" name="right_rear_arm_joint">
      <pose>0 -0.075 -0.001 0 0 0</pose>
      <child>right_rear_arm</child>
      <parent>base_link</parent>
      <axis>
        <xyz>1 0 0</xyz>
        <dynamics>
          <damping>.5</damping>
        </dynamics>
        <limit>
          <velocity>1</velocity>
        </limit>
      </axis>
    </joint>

    <joint type="revolute" name="left_front_arm_joint">
      <pose>0 0.075 0.001 0 0 0</pose>
      <child>left_front_arm</child>
      <parent>base_link</parent>
      <axis>
        <xyz>1 0 0</xyz>
        <dynamics>
          <damping>.5</damping>
        </dynamics>
        <limit>
          <velocity>1</velocity>
        </limit>
      </axis>
    </joint>

    <joint type="revolute" name="right_front_arm_joint">
      <pose>0 0.075 -0.001 0 0 0</pose>
      <child>right_front_arm</child>
      <parent>base_link</parent>
      <axis>
        <xyz>1 0 0</xyz>
        <dynamics>
          <damping>.5</damping>
        </dynamics>
        <limit>
          <velocity>1</velocity>
        </limit>
      </axis>
    </joint>



    <joint type="revolute" name="right_rear_arm_wheel_1">
      <pose>0 0 0.015 0 0 0</pose>
      <child>right_rear_arm_wheel_1</child>
      <parent>right_rear_arm</parent>
      <axis>
        <xyz>0 0 1</xyz>
      </axis>
    </joint>

    <joint type="revolute" name="right_rear_arm_wheel_2">
      <pose>0 0 0.015 0 0 0</pose>
      <child>right_rear_arm_wheel_2</child>
      <parent>right_rear_arm</parent>
      <axis>
        <xyz>0 0 1</xyz>
      </axis>
    </joint>

    <joint type="revolute" name="right_rear_arm_wheel_3">
      <pose>0 0 0.015 0 0 0</pose>
      <child>right_rear_arm_wheel_3</child>
      <parent>right_rear_arm</parent>
      <axis>
        <xyz>0 0 1</xyz>
      </axis>
    </joint>



    <joint type="revolute" name="right_front_arm_wheel_1">
      <pose>0 0 0.015 0 0 0</pose>
      <child>right_front_arm_wheel_1</child>
      <parent>right_front_arm</parent>
      <axis>
        <xyz>0 0 1</xyz>
      </axis>
    </joint>

    <joint type="revolute" name="right_front_arm_wheel_2">
      <pose>0 0 0.015 0 0 0</pose>
      <child>right_front_arm_wheel_2</child>
      <parent>right_front_arm</parent>
      <axis>
        <xyz>0 0 1</xyz>
      </axis>
    </joint>

    <joint type="revolute" name="right_front_arm_wheel_3">
      <pose>0 0 0.015 0 0 0</pose>
      <child>right_front_arm_wheel_3</child>
      <parent>right_front_arm</parent>
      <axis>
        <xyz>0 0 1</xyz>
      </axis>
    </joint>



    <joint type="revolute" name="left_rear_arm_wheel_1">
      <pose>0 0 -0.015 0 0 0</pose>
      <child>left_rear_arm_wheel_1</child>
      <parent>left_rear_arm</parent>
      <axis>
        <xyz>0 0 1</xyz>
      </axis>
    </joint>

    <joint type="revolute" name="left_rear_arm_wheel_2">
      <pose>0 0 -0.015 0 0 0</pose>
      <child>left_rear_arm_wheel_2</child>
      <parent>left_rear_arm</parent>
      <axis>
        <xyz>0 0 1</xyz>
      </axis>
    </joint>

    <joint type="revolute" name="left_rear_arm_wheel_3">
      <pose>0 0 -0.015 0 0 0</pose>
      <child>left_rear_arm_wheel_3</child>
      <parent>left_rear_arm</parent>
      <axis>
        <xyz>0 0 1</xyz>
      </axis>
    </joint>



    <joint type="revolute" name="left_front_arm_wheel_1">
      <pose>0 0 -0.015 0 0 0</pose>
      <child>left_front_arm_wheel_1</child>
      <parent>left_front_arm</parent>
      <axis>
        <xyz>0 0 1</xyz>
      </axis>
    </joint>

    <joint type="revolute" name="left_front_arm_wheel_2">
      <pose>0 0 -0.015 0 0 0</pose>
      <child>left_front_arm_wheel_2</child>
      <parent>left_front_arm</parent>
      <axis>
        <xyz>0 0 1</xyz>
      </axis>
    </joint>

    <joint type="revolute" name="left_front_arm_wheel_3">
      <pose>0 0 -0.015 0 0 0</pose>
      <child>left_front_arm_wheel_3</child>
      <parent>left_front_arm</parent>
      <axis>
        <xyz>0 0 1</xyz>
      </axis>
    </joint>

<!--__________________/joint___________________-->

    <plugin name="crawler_flipper" filename="libcrawler_flipper_ros.so">
      <robotNamespace>robot1</robotNamespace>
      <right_front_arm>right_front_arm_joint</right_front_arm>
      <right_rear_arm>right_rear_arm_joint</right_rear_arm>
      <left_front_arm>left_front_arm_joint</left_front_arm>
      <left_rear_arm>left_rear_arm_joint</left_rear_arm>
      <right_front>right_front</right_front>
      <right_rear>right_rear</right_rear>
      <left_front>left_front</left_front>
      <left_rear>left_rear</left_rear>
      <right_center1>right_center1</right_center1>
      <right_center2>right_center2</right_center2>
      <right_center3>right_center3</right_center3>
      <left_center1>left_center1</left_center1>
      <left_center2>left_center2</left_center2>
      <left_center3>left_center3</left_center3>
      <right_front_arm_wheel_1>right_front_arm_wheel_1</right_front_arm_wheel_1>
      <right_front_arm_wheel_2>right_front_arm_wheel_2</right_front_arm_wheel_2>
      <right_front_arm_wheel_3>right_front_arm_wheel_3</right_front_arm_wheel_3>
      <left_front_arm_wheel_1>left_front_arm_wheel_1</left_front_arm_wheel_1>
      <left_front_arm_wheel_2>left_front_arm_wheel_2</left_front_arm_wheel_2>
      <left_front_arm_wheel_3>left_front_arm_wheel_3</left_front_arm_wheel_3>
      <right_rear_arm_wheel_1>right_rear_arm_wheel_1</right_rear_arm_wheel_1>
      <right_rear_arm_wheel_2>right_rear_arm_wheel_2</right_rear_arm_wheel_2>
      <right_rear_arm_wheel_3>right_rear_arm_wheel_3</right_rear_arm_wheel_3>
      <left_rear_arm_wheel_1>left_rear_arm_wheel_1</left_rear_arm_wheel_1>
      <left_rear_arm_wheel_2>left_rear_arm_wheel_2</left_rear_arm_wheel_2>
      <left_rear_arm_wheel_3>left_rear_arm_wheel_3</left_rear_arm_wheel_3>
      <right_sub2>right_sub2</right_sub2>
      <right_sub3>right_sub3</right_sub3>
      <left_sub2>left_sub2</left_sub2>
      <left_sub3>left_sub3</left_sub3>
      <gain>0.1</gain>
      <broadcastTF>true</broadcastTF>
    </plugin>

    <plugin name="gazebo_ros_control" filename="libgazebo_ros_control.so">
      <robotNamespace>robot1</robotNamespace>
<!--      <robotParam>robot/robot_description</robotParam> -->
      <robotSimType>gazebo_ros_control/DefaultRobotHWSim</robotSimType>
    </plugin>

  </model>
</sdf>
